[2025-07-30T07:41:45.538+0000] {local_task_job_runner.py:120} INFO - ::group::Pre task execution logs
[2025-07-30T07:41:45.610+0000] {taskinstance.py:2076} INFO - Dependencies all met for dep_context=non-requeueable deps ti=<TaskInstance: ml_pipeline_dag.stream_data_task manual__2025-07-30T07:41:39.266546+00:00 [queued]>
[2025-07-30T07:41:45.622+0000] {taskinstance.py:2076} INFO - Dependencies all met for dep_context=requeueable deps ti=<TaskInstance: ml_pipeline_dag.stream_data_task manual__2025-07-30T07:41:39.266546+00:00 [queued]>
[2025-07-30T07:41:45.623+0000] {taskinstance.py:2306} INFO - Starting attempt 1 of 1
[2025-07-30T07:41:45.644+0000] {taskinstance.py:2330} INFO - Executing <Task(PythonOperator): stream_data_task> on 2025-07-30 07:41:39.266546+00:00
[2025-07-30T07:41:45.658+0000] {warnings.py:110} WARNING - /home/***/.local/lib/python3.12/site-packages/***/task/task_runner/standard_task_runner.py:61: DeprecationWarning: This process (pid=263) is multi-threaded, use of fork() may lead to deadlocks in the child.
  pid = os.fork()

[2025-07-30T07:41:45.661+0000] {standard_task_runner.py:63} INFO - Started process 272 to run task
[2025-07-30T07:41:45.661+0000] {standard_task_runner.py:90} INFO - Running: ['***', 'tasks', 'run', 'ml_pipeline_dag', 'stream_data_task', 'manual__2025-07-30T07:41:39.266546+00:00', '--job-id', '10', '--raw', '--subdir', 'DAGS_FOLDER/ml_pipeline_dag.py', '--cfg-path', '/tmp/tmpufr7lpk9']
[2025-07-30T07:41:45.666+0000] {standard_task_runner.py:91} INFO - Job 10: Subtask stream_data_task
[2025-07-30T07:41:46.010+0000] {task_command.py:426} INFO - Running <TaskInstance: ml_pipeline_dag.stream_data_task manual__2025-07-30T07:41:39.266546+00:00 [running]> on host 627f9701fc6c
[2025-07-30T07:41:46.302+0000] {taskinstance.py:2648} INFO - Exporting env vars: AIRFLOW_CTX_DAG_OWNER='***' AIRFLOW_CTX_DAG_ID='ml_pipeline_dag' AIRFLOW_CTX_TASK_ID='stream_data_task' AIRFLOW_CTX_EXECUTION_DATE='2025-07-30T07:41:39.266546+00:00' AIRFLOW_CTX_TRY_NUMBER='1' AIRFLOW_CTX_DAG_RUN_ID='manual__2025-07-30T07:41:39.266546+00:00'
[2025-07-30T07:41:46.304+0000] {taskinstance.py:430} INFO - ::endgroup::
[2025-07-30T07:41:46.325+0000] {taskinstance.py:441} INFO - ::group::Post task execution logs
[2025-07-30T07:41:46.326+0000] {taskinstance.py:2905} ERROR - Task failed with exception
Traceback (most recent call last):
  File "/home/airflow/.local/lib/python3.12/site-packages/redis/connection.py", line 276, in connect
    sock = self.retry.call_with_retry(
           ^^^^^^^^^^^^^^^^^^^^^^^^^^^
  File "/home/airflow/.local/lib/python3.12/site-packages/redis/retry.py", line 46, in call_with_retry
    return do()
           ^^^^
  File "/home/airflow/.local/lib/python3.12/site-packages/redis/connection.py", line 277, in <lambda>
    lambda: self._connect(), lambda error: self.disconnect(error)
            ^^^^^^^^^^^^^^^
  File "/home/airflow/.local/lib/python3.12/site-packages/redis/connection.py", line 639, in _connect
    raise err
  File "/home/airflow/.local/lib/python3.12/site-packages/redis/connection.py", line 627, in _connect
    sock.connect(socket_address)
ConnectionRefusedError: [Errno 111] Connection refused

During handling of the above exception, another exception occurred:

Traceback (most recent call last):
  File "/home/airflow/.local/lib/python3.12/site-packages/airflow/models/taskinstance.py", line 465, in _execute_task
    result = _execute_callable(context=context, **execute_callable_kwargs)
             ^^^^^^^^^^^^^^^^^^^^^^^^^^^^^^^^^^^^^^^^^^^^^^^^^^^^^^^^^^^^^
  File "/home/airflow/.local/lib/python3.12/site-packages/airflow/models/taskinstance.py", line 432, in _execute_callable
    return execute_callable(context=context, **execute_callable_kwargs)
           ^^^^^^^^^^^^^^^^^^^^^^^^^^^^^^^^^^^^^^^^^^^^^^^^^^^^^^^^^^^^
  File "/home/airflow/.local/lib/python3.12/site-packages/airflow/models/baseoperator.py", line 400, in wrapper
    return func(self, *args, **kwargs)
           ^^^^^^^^^^^^^^^^^^^^^^^^^^^
  File "/home/airflow/.local/lib/python3.12/site-packages/airflow/operators/python.py", line 235, in execute
    return_value = self.execute_callable()
                   ^^^^^^^^^^^^^^^^^^^^^^^
  File "/home/airflow/.local/lib/python3.12/site-packages/airflow/operators/python.py", line 252, in execute_callable
    return self.python_callable(*self.op_args, **self.op_kwargs)
           ^^^^^^^^^^^^^^^^^^^^^^^^^^^^^^^^^^^^^^^^^^^^^^^^^^^^^
  File "/opt/airflow/dags/ml_pipeline_dag.py", line 17, in stream_data_with_drift
    r.lpush('data_queue', message)
  File "/home/airflow/.local/lib/python3.12/site-packages/redis/commands/core.py", line 2735, in lpush
    return self.execute_command("LPUSH", name, *values)
           ^^^^^^^^^^^^^^^^^^^^^^^^^^^^^^^^^^^^^^^^^^^^
  File "/home/airflow/.local/lib/python3.12/site-packages/redis/client.py", line 542, in execute_command
    conn = self.connection or pool.get_connection(command_name, **options)
                              ^^^^^^^^^^^^^^^^^^^^^^^^^^^^^^^^^^^^^^^^^^^^
  File "/home/airflow/.local/lib/python3.12/site-packages/redis/connection.py", line 1109, in get_connection
    connection.connect()
  File "/home/airflow/.local/lib/python3.12/site-packages/redis/connection.py", line 282, in connect
    raise ConnectionError(self._error_message(e))
redis.exceptions.ConnectionError: Error 111 connecting to localhost:6379. Connection refused.
[2025-07-30T07:41:46.364+0000] {taskinstance.py:1206} INFO - Marking task as FAILED. dag_id=ml_pipeline_dag, task_id=stream_data_task, run_id=manual__2025-07-30T07:41:39.266546+00:00, execution_date=20250730T074139, start_date=20250730T074145, end_date=20250730T074146
[2025-07-30T07:41:46.392+0000] {standard_task_runner.py:110} ERROR - Failed to execute job 10 for task stream_data_task (Error 111 connecting to localhost:6379. Connection refused.; 272)
[2025-07-30T07:41:46.458+0000] {local_task_job_runner.py:240} INFO - Task exited with return code 1
[2025-07-30T07:41:46.494+0000] {taskinstance.py:3498} INFO - 0 downstream tasks scheduled from follow-on schedule check
[2025-07-30T07:41:46.500+0000] {local_task_job_runner.py:222} INFO - ::endgroup::
