[2025-08-05T20:43:36.930+0000] {local_task_job_runner.py:120} INFO - ::group::Pre task execution logs
[2025-08-05T20:43:37.289+0000] {taskinstance.py:2076} INFO - Dependencies all met for dep_context=non-requeueable deps ti=<TaskInstance: ml_pipeline_dvc.train_dvc manual__2025-08-05T20:37:28.487618+00:00 [queued]>
[2025-08-05T20:43:37.363+0000] {taskinstance.py:2076} INFO - Dependencies all met for dep_context=requeueable deps ti=<TaskInstance: ml_pipeline_dvc.train_dvc manual__2025-08-05T20:37:28.487618+00:00 [queued]>
[2025-08-05T20:43:37.366+0000] {taskinstance.py:2306} INFO - Starting attempt 2 of 2
[2025-08-05T20:43:37.491+0000] {taskinstance.py:2330} INFO - Executing <Task(BashOperator): train_dvc> on 2025-08-05 20:37:28.487618+00:00
[2025-08-05T20:43:37.532+0000] {warnings.py:110} WARNING - /home/***/.local/lib/python3.12/site-packages/***/task/task_runner/standard_task_runner.py:61: DeprecationWarning: This process (pid=3214) is multi-threaded, use of fork() may lead to deadlocks in the child.
  pid = os.fork()

[2025-08-05T20:43:37.545+0000] {standard_task_runner.py:63} INFO - Started process 3215 to run task
[2025-08-05T20:43:37.546+0000] {standard_task_runner.py:90} INFO - Running: ['***', 'tasks', 'run', 'ml_pipeline_dvc', 'train_dvc', 'manual__2025-08-05T20:37:28.487618+00:00', '--job-id', '46', '--raw', '--subdir', 'DAGS_FOLDER/ml_pipeline_dag_2.py', '--cfg-path', '/tmp/tmpp4yoas61']
[2025-08-05T20:43:37.556+0000] {standard_task_runner.py:91} INFO - Job 46: Subtask train_dvc
[2025-08-05T20:43:38.246+0000] {task_command.py:426} INFO - Running <TaskInstance: ml_pipeline_dvc.train_dvc manual__2025-08-05T20:37:28.487618+00:00 [running]> on host cb274dbeb17b
[2025-08-05T20:43:39.304+0000] {taskinstance.py:2648} INFO - Exporting env vars: AIRFLOW_CTX_DAG_OWNER='yas' AIRFLOW_CTX_DAG_ID='ml_pipeline_dvc' AIRFLOW_CTX_TASK_ID='train_dvc' AIRFLOW_CTX_EXECUTION_DATE='2025-08-05T20:37:28.487618+00:00' AIRFLOW_CTX_TRY_NUMBER='2' AIRFLOW_CTX_DAG_RUN_ID='manual__2025-08-05T20:37:28.487618+00:00'
[2025-08-05T20:43:39.311+0000] {taskinstance.py:430} INFO - ::endgroup::
[2025-08-05T20:43:39.540+0000] {subprocess.py:63} INFO - Tmp dir root location: /tmp
[2025-08-05T20:43:39.554+0000] {subprocess.py:75} INFO - Running command: ['/usr/bin/bash', '-c', 'cd /opt/***/ml_pipeline && dvc repro train']
[2025-08-05T20:43:39.641+0000] {subprocess.py:86} INFO - Output:
[2025-08-05T20:43:54.224+0000] {subprocess.py:93} INFO - Running stage 'preprocess':
[2025-08-05T20:43:54.233+0000] {subprocess.py:93} INFO - > python preprocessing/preprocess_task.py
[2025-08-05T20:44:18.248+0000] {subprocess.py:93} INFO - {"asctime": "2025-08-05 20:44:18,229", "levelname": "INFO", "message": "\u2705 Saved pipeline: artifacts/preprocess/pipeline_v20250801_144307.pkl"}
[2025-08-05T20:44:18.291+0000] {subprocess.py:93} INFO - {"asctime": "2025-08-05 20:44:18,247", "levelname": "INFO", "message": "\ud83d\udcc4 Saved metadata: artifacts/preprocess/preprocess_metadata_v20250801_144307.json"}
[2025-08-05T20:44:18.323+0000] {subprocess.py:93} INFO - {"asctime": "2025-08-05 20:44:18,250", "levelname": "INFO", "message": "\ud83d\udce6 Updated version_meta.json"}
[2025-08-05T20:44:24.567+0000] {subprocess.py:93} INFO - Updating lock file 'dvc.lock'
[2025-08-05T20:44:24.736+0000] {subprocess.py:93} INFO - 
[2025-08-05T20:44:26.226+0000] {subprocess.py:93} INFO - Running stage 'train':
[2025-08-05T20:44:26.234+0000] {subprocess.py:93} INFO - > python train/train_task.py
[2025-08-05T20:45:18.405+0000] {subprocess.py:93} INFO - INFO:__main__:Outlier detector saved to artifacts/models/outlier_detector_v20250801_144307.pkl
[2025-08-05T20:45:19.111+0000] {subprocess.py:93} INFO - /home/***/.local/lib/python3.12/site-packages/sklearn/metrics/_ranking.py:1201: UndefinedMetricWarning: No positive samples in y_true, true positive value should be meaningless
[2025-08-05T20:45:19.131+0000] {subprocess.py:93} INFO -   warnings.warn(
[2025-08-05T20:45:19.376+0000] {subprocess.py:93} INFO - INFO:__main__:ðŸ“„ Training metadata saved to artifacts/train/train_metadata_v20250801_144307.json
[2025-08-05T20:45:19.385+0000] {subprocess.py:93} INFO - INFO:__main__:ðŸ“¦ Updated version_meta.json
[2025-08-05T20:45:21.436+0000] {subprocess.py:93} INFO - INFO:__main__:ðŸ“„ Registering the model FraudDetectionModel
[2025-08-05T20:45:21.444+0000] {subprocess.py:93} INFO - Traceback (most recent call last):
[2025-08-05T20:45:21.472+0000] {subprocess.py:93} INFO -   File "/opt/***/ml_pipeline/train/train_task.py", line 219, in <module>
[2025-08-05T20:45:21.499+0000] {subprocess.py:93} INFO -     main()
[2025-08-05T20:45:21.533+0000] {subprocess.py:93} INFO -   File "/opt/***/ml_pipeline/train/train_task.py", line 213, in main
[2025-08-05T20:45:21.573+0000] {subprocess.py:93} INFO -     register_model_with_mlflow(model, metrics)
[2025-08-05T20:45:21.590+0000] {subprocess.py:93} INFO -   File "/opt/***/ml_pipeline/train/train_task.py", line 126, in register_model_with_mlflow
[2025-08-05T20:45:21.594+0000] {subprocess.py:93} INFO -     X = np.array([[0, 1], [1, 1], [2, 0]])
[2025-08-05T20:45:21.632+0000] {subprocess.py:93} INFO -         ^^
[2025-08-05T20:45:21.644+0000] {subprocess.py:93} INFO - NameError: name 'np' is not defined
[2025-08-05T20:45:27.320+0000] {subprocess.py:93} INFO - ERROR: failed to reproduce 'train': Unable to acquire lock. Most likely another DVC process is running or was terminated abruptly. Check the page <https://dvc.org/doc/user-guide/troubleshooting#lock-issue> for other possible reasons and to learn how to resolve this.
[2025-08-05T20:45:29.552+0000] {subprocess.py:97} INFO - Command exited with return code 255
[2025-08-05T20:45:29.560+0000] {taskinstance.py:441} INFO - ::group::Post task execution logs
[2025-08-05T20:45:29.657+0000] {taskinstance.py:2905} ERROR - Task failed with exception
Traceback (most recent call last):
  File "/home/airflow/.local/lib/python3.12/site-packages/airflow/models/taskinstance.py", line 465, in _execute_task
    result = _execute_callable(context=context, **execute_callable_kwargs)
             ^^^^^^^^^^^^^^^^^^^^^^^^^^^^^^^^^^^^^^^^^^^^^^^^^^^^^^^^^^^^^
  File "/home/airflow/.local/lib/python3.12/site-packages/airflow/models/taskinstance.py", line 432, in _execute_callable
    return execute_callable(context=context, **execute_callable_kwargs)
           ^^^^^^^^^^^^^^^^^^^^^^^^^^^^^^^^^^^^^^^^^^^^^^^^^^^^^^^^^^^^
  File "/home/airflow/.local/lib/python3.12/site-packages/airflow/models/baseoperator.py", line 400, in wrapper
    return func(self, *args, **kwargs)
           ^^^^^^^^^^^^^^^^^^^^^^^^^^^
  File "/home/airflow/.local/lib/python3.12/site-packages/airflow/operators/bash.py", line 243, in execute
    raise AirflowException(
airflow.exceptions.AirflowException: Bash command failed. The command returned a non-zero exit code 255.
[2025-08-05T20:45:29.728+0000] {taskinstance.py:1206} INFO - Marking task as FAILED. dag_id=ml_pipeline_dvc, task_id=train_dvc, run_id=manual__2025-08-05T20:37:28.487618+00:00, execution_date=20250805T203728, start_date=20250805T204337, end_date=20250805T204529
[2025-08-05T20:45:29.899+0000] {standard_task_runner.py:110} ERROR - Failed to execute job 46 for task train_dvc (Bash command failed. The command returned a non-zero exit code 255.; 3215)
[2025-08-05T20:45:29.978+0000] {local_task_job_runner.py:240} INFO - Task exited with return code 1
[2025-08-05T20:45:30.174+0000] {taskinstance.py:3498} INFO - 0 downstream tasks scheduled from follow-on schedule check
[2025-08-05T20:45:30.191+0000] {local_task_job_runner.py:222} INFO - ::endgroup::
