[2025-08-12T16:14:14.489+0000] {local_task_job_runner.py:120} INFO - ::group::Pre task execution logs
[2025-08-12T16:14:14.608+0000] {taskinstance.py:2076} INFO - Dependencies all met for dep_context=non-requeueable deps ti=<TaskInstance: ml_pipeline_dvc.setup_dvc_remote manual__2025-08-12T16:14:11.570540+00:00 [queued]>
[2025-08-12T16:14:14.668+0000] {taskinstance.py:2076} INFO - Dependencies all met for dep_context=requeueable deps ti=<TaskInstance: ml_pipeline_dvc.setup_dvc_remote manual__2025-08-12T16:14:11.570540+00:00 [queued]>
[2025-08-12T16:14:14.670+0000] {taskinstance.py:2306} INFO - Starting attempt 1 of 2
[2025-08-12T16:14:14.733+0000] {taskinstance.py:2330} INFO - Executing <Task(BashOperator): setup_dvc_remote> on 2025-08-12 16:14:11.570540+00:00
[2025-08-12T16:14:14.755+0000] {warnings.py:110} WARNING - /home/***/.local/lib/python3.12/site-packages/***/task/task_runner/standard_task_runner.py:61: DeprecationWarning: This process (pid=3696) is multi-threaded, use of fork() may lead to deadlocks in the child.
  pid = os.fork()

[2025-08-12T16:14:14.756+0000] {standard_task_runner.py:90} INFO - Running: ['***', 'tasks', 'run', 'ml_pipeline_dvc', 'setup_dvc_remote', 'manual__2025-08-12T16:14:11.570540+00:00', '--job-id', '107', '--raw', '--subdir', 'DAGS_FOLDER/train_pipeline_dag.py', '--cfg-path', '/tmp/tmp9cl41n4d']
[2025-08-12T16:14:14.761+0000] {standard_task_runner.py:63} INFO - Started process 3697 to run task
[2025-08-12T16:14:14.762+0000] {standard_task_runner.py:91} INFO - Job 107: Subtask setup_dvc_remote
[2025-08-12T16:14:14.876+0000] {task_command.py:426} INFO - Running <TaskInstance: ml_pipeline_dvc.setup_dvc_remote manual__2025-08-12T16:14:11.570540+00:00 [running]> on host 563139bd1525
[2025-08-12T16:14:15.034+0000] {taskinstance.py:2648} INFO - Exporting env vars: AIRFLOW_CTX_DAG_OWNER='yas' AIRFLOW_CTX_DAG_ID='ml_pipeline_dvc' AIRFLOW_CTX_TASK_ID='setup_dvc_remote' AIRFLOW_CTX_EXECUTION_DATE='2025-08-12T16:14:11.570540+00:00' AIRFLOW_CTX_TRY_NUMBER='1' AIRFLOW_CTX_DAG_RUN_ID='manual__2025-08-12T16:14:11.570540+00:00'
[2025-08-12T16:14:15.036+0000] {taskinstance.py:430} INFO - ::endgroup::
[2025-08-12T16:14:15.065+0000] {subprocess.py:63} INFO - Tmp dir root location: /tmp
[2025-08-12T16:14:15.067+0000] {subprocess.py:75} INFO - Running command: ['/usr/bin/bash', '-c', '\n        dvc remote add -f minio s3://mlflow-artifacts\n        dvc remote modify minio endpointurl http://minio:9000\n        dvc remote modify minio access_key_id minioadmin\n        dvc remote modify minio secret_access_key minioadmin\n        dvc remote modify minio use_ssl false\n        dvc remote default minio\n        ']
[2025-08-12T16:14:15.083+0000] {subprocess.py:86} INFO - Output:
[2025-08-12T16:14:16.923+0000] {subprocess.py:93} INFO - ERROR: configuration error - config file error: Not inside a DVC repo
[2025-08-12T16:14:18.360+0000] {subprocess.py:93} INFO - ERROR: configuration error - config file error: Not inside a DVC repo
[2025-08-12T16:14:20.504+0000] {subprocess.py:93} INFO - ERROR: configuration error - config file error: Not inside a DVC repo
[2025-08-12T16:14:22.025+0000] {subprocess.py:93} INFO - ERROR: configuration error - config file error: Not inside a DVC repo
[2025-08-12T16:14:23.522+0000] {subprocess.py:93} INFO - ERROR: configuration error - config file error: Not inside a DVC repo
[2025-08-12T16:14:24.860+0000] {subprocess.py:93} INFO - ERROR: configuration error - config file error: Not inside a DVC repo
[2025-08-12T16:14:25.122+0000] {subprocess.py:97} INFO - Command exited with return code 251
[2025-08-12T16:14:25.124+0000] {taskinstance.py:441} INFO - ::group::Post task execution logs
[2025-08-12T16:14:25.139+0000] {taskinstance.py:2905} ERROR - Task failed with exception
Traceback (most recent call last):
  File "/home/airflow/.local/lib/python3.12/site-packages/airflow/models/taskinstance.py", line 465, in _execute_task
    result = _execute_callable(context=context, **execute_callable_kwargs)
             ^^^^^^^^^^^^^^^^^^^^^^^^^^^^^^^^^^^^^^^^^^^^^^^^^^^^^^^^^^^^^
  File "/home/airflow/.local/lib/python3.12/site-packages/airflow/models/taskinstance.py", line 432, in _execute_callable
    return execute_callable(context=context, **execute_callable_kwargs)
           ^^^^^^^^^^^^^^^^^^^^^^^^^^^^^^^^^^^^^^^^^^^^^^^^^^^^^^^^^^^^
  File "/home/airflow/.local/lib/python3.12/site-packages/airflow/models/baseoperator.py", line 400, in wrapper
    return func(self, *args, **kwargs)
           ^^^^^^^^^^^^^^^^^^^^^^^^^^^
  File "/home/airflow/.local/lib/python3.12/site-packages/airflow/operators/bash.py", line 243, in execute
    raise AirflowException(
airflow.exceptions.AirflowException: Bash command failed. The command returned a non-zero exit code 251.
[2025-08-12T16:14:25.149+0000] {taskinstance.py:1206} INFO - Marking task as UP_FOR_RETRY. dag_id=ml_pipeline_dvc, task_id=setup_dvc_remote, run_id=manual__2025-08-12T16:14:11.570540+00:00, execution_date=20250812T161411, start_date=20250812T161414, end_date=20250812T161425
[2025-08-12T16:14:25.169+0000] {standard_task_runner.py:110} ERROR - Failed to execute job 107 for task setup_dvc_remote (Bash command failed. The command returned a non-zero exit code 251.; 3697)
[2025-08-12T16:14:25.206+0000] {local_task_job_runner.py:240} INFO - Task exited with return code 1
[2025-08-12T16:14:25.238+0000] {taskinstance.py:3498} INFO - 0 downstream tasks scheduled from follow-on schedule check
[2025-08-12T16:14:25.240+0000] {local_task_job_runner.py:222} INFO - ::endgroup::
