[2025-08-12T20:09:35.834+0000] {local_task_job_runner.py:120} INFO - ::group::Pre task execution logs
[2025-08-12T20:09:35.959+0000] {taskinstance.py:2076} INFO - Dependencies all met for dep_context=non-requeueable deps ti=<TaskInstance: ml_pipeline_dvc.setup_dvc_remote manual__2025-08-12T20:09:33.481107+00:00 [queued]>
[2025-08-12T20:09:35.992+0000] {taskinstance.py:2076} INFO - Dependencies all met for dep_context=requeueable deps ti=<TaskInstance: ml_pipeline_dvc.setup_dvc_remote manual__2025-08-12T20:09:33.481107+00:00 [queued]>
[2025-08-12T20:09:35.993+0000] {taskinstance.py:2306} INFO - Starting attempt 1 of 2
[2025-08-12T20:09:36.036+0000] {taskinstance.py:2330} INFO - Executing <Task(BashOperator): setup_dvc_remote> on 2025-08-12 20:09:33.481107+00:00
[2025-08-12T20:09:36.059+0000] {warnings.py:110} WARNING - /home/***/.local/lib/python3.12/site-packages/***/task/task_runner/standard_task_runner.py:61: DeprecationWarning: This process (pid=1221) is multi-threaded, use of fork() may lead to deadlocks in the child.
  pid = os.fork()

[2025-08-12T20:09:36.066+0000] {standard_task_runner.py:90} INFO - Running: ['***', 'tasks', 'run', 'ml_pipeline_dvc', 'setup_dvc_remote', 'manual__2025-08-12T20:09:33.481107+00:00', '--job-id', '157', '--raw', '--subdir', 'DAGS_FOLDER/train_pipeline_dag.py', '--cfg-path', '/tmp/tmpnygx5npq']
[2025-08-12T20:09:36.072+0000] {standard_task_runner.py:63} INFO - Started process 1222 to run task
[2025-08-12T20:09:36.073+0000] {standard_task_runner.py:91} INFO - Job 157: Subtask setup_dvc_remote
[2025-08-12T20:09:36.336+0000] {task_command.py:426} INFO - Running <TaskInstance: ml_pipeline_dvc.setup_dvc_remote manual__2025-08-12T20:09:33.481107+00:00 [running]> on host 0802dd1186ed
[2025-08-12T20:09:36.704+0000] {taskinstance.py:2648} INFO - Exporting env vars: AIRFLOW_CTX_DAG_OWNER='yas' AIRFLOW_CTX_DAG_ID='ml_pipeline_dvc' AIRFLOW_CTX_TASK_ID='setup_dvc_remote' AIRFLOW_CTX_EXECUTION_DATE='2025-08-12T20:09:33.481107+00:00' AIRFLOW_CTX_TRY_NUMBER='1' AIRFLOW_CTX_DAG_RUN_ID='manual__2025-08-12T20:09:33.481107+00:00'
[2025-08-12T20:09:36.711+0000] {taskinstance.py:430} INFO - ::endgroup::
[2025-08-12T20:09:36.757+0000] {subprocess.py:63} INFO - Tmp dir root location: /tmp
[2025-08-12T20:09:36.763+0000] {subprocess.py:75} INFO - Running command: ['/usr/bin/bash', '-c', '\n        cd /opt/***/ml_pipeline\n        aws --endpoint-url http://minio:9000 s3 ls s3://mlflow-artifacts\n        dvc remote remove minio || true\n        dvc remote add -d minio s3://mlflow-artifacts\n        dvc remote modify minio endpointurl http://minio:9000\n        dvc remote modify minio access_key_id minioadmin\n        dvc remote modify minio secret_access_key minioadmin\n        dvc remote modify minio use_ssl false\n        export AWS_ACCESS_KEY_ID=minioadmin\n        export AWS_SECRET_ACCESS_KEY=minioadmin\n        export AWS_ENDPOINT_URL=http://minio:9000\n        dvc push --verbose\n        echo "=== DVC CONFIG AFTER SETUP ==="\n        cat .dvc/config\n        dvc repro preprocess -v\n        ']
[2025-08-12T20:09:36.792+0000] {subprocess.py:86} INFO - Output:
[2025-08-12T20:09:39.277+0000] {subprocess.py:93} INFO -                            PRE data/
[2025-08-12T20:09:39.278+0000] {subprocess.py:93} INFO -                            PRE metadata/
[2025-08-12T20:09:39.279+0000] {subprocess.py:93} INFO -                            PRE preprocess/
[2025-08-12T20:09:40.807+0000] {subprocess.py:93} INFO - ERROR: configuration error - config file error: expected 'url' for dictionary value @ data['remote']['minio']
[2025-08-12T20:09:42.744+0000] {subprocess.py:93} INFO - Setting 'minio' as a default remote.
[2025-08-12T20:09:50.428+0000] {subprocess.py:93} INFO - 2025-08-12 20:09:50,428 DEBUG: v3.61.0 (pip), CPython 3.12.3 on Linux-6.6.31-linuxkit-x86_64-with-glibc2.36
[2025-08-12T20:09:50.430+0000] {subprocess.py:93} INFO - 2025-08-12 20:09:50,428 DEBUG: command: /home/***/.local/bin/dvc push --verbose
[2025-08-12T20:09:51.385+0000] {subprocess.py:93} INFO - 2025-08-12 20:09:51,384 DEBUG: Lockfile 'dvc.lock' needs to be updated.
[2025-08-12T20:09:52.527+0000] {subprocess.py:93} INFO - Everything is up to date.
[2025-08-12T20:09:52.531+0000] {subprocess.py:93} INFO - 2025-08-12 20:09:52,530 DEBUG: Analytics is enabled.
[2025-08-12T20:09:52.587+0000] {subprocess.py:93} INFO - 2025-08-12 20:09:52,587 DEBUG: Trying to spawn ['daemon', 'analytics', '/tmp/tmp2i7lxslj', '-v']
[2025-08-12T20:09:52.595+0000] {subprocess.py:93} INFO - 2025-08-12 20:09:52,594 DEBUG: Spawned ['daemon', 'analytics', '/tmp/tmp2i7lxslj', '-v'] with pid 1350
[2025-08-12T20:09:52.769+0000] {subprocess.py:93} INFO - === DVC CONFIG AFTER SETUP ===
[2025-08-12T20:09:52.774+0000] {subprocess.py:93} INFO - [core]
[2025-08-12T20:09:52.774+0000] {subprocess.py:93} INFO -     remote = minio
[2025-08-12T20:09:52.775+0000] {subprocess.py:93} INFO - ['remote "minio"']
[2025-08-12T20:09:52.776+0000] {subprocess.py:93} INFO -     url = s3://mlflow-artifacts
[2025-08-12T20:09:52.776+0000] {subprocess.py:93} INFO -     endpointurl = http://minio:9000
[2025-08-12T20:09:52.777+0000] {subprocess.py:93} INFO -     access_key_id = minioadmin
[2025-08-12T20:09:52.778+0000] {subprocess.py:93} INFO -     secret_access_key = minioadmin
[2025-08-12T20:09:52.779+0000] {subprocess.py:93} INFO -     use_ssl = false
[2025-08-12T20:09:53.413+0000] {subprocess.py:93} INFO - 2025-08-12 20:09:53,413 DEBUG: v3.61.0 (pip), CPython 3.12.3 on Linux-6.6.31-linuxkit-x86_64-with-glibc2.36
[2025-08-12T20:09:53.414+0000] {subprocess.py:93} INFO - 2025-08-12 20:09:53,413 DEBUG: command: /home/***/.local/bin/dvc repro preprocess -v
[2025-08-12T20:09:54.154+0000] {subprocess.py:93} INFO - 2025-08-12 20:09:54,154 DEBUG: Assuming 'preprocess' to be a stage inside 'dvc.yaml'
[2025-08-12T20:09:54.299+0000] {subprocess.py:93} INFO - 2025-08-12 20:09:54,299 DEBUG: Lockfile 'dvc.lock' needs to be updated.
[2025-08-12T20:09:56.365+0000] {subprocess.py:93} INFO - 2025-08-12 20:09:56,365 DEBUG: Dependency 's3://mlflow-artifacts/metadata/version_meta.json' of stage: 'preprocess' changed because it is 'modified'.
[2025-08-12T20:09:56.369+0000] {subprocess.py:93} INFO - 2025-08-12 20:09:56,369 DEBUG: stage: 'preprocess' changed.
[2025-08-12T20:09:56.405+0000] {subprocess.py:93} INFO - 2025-08-12 20:09:56,405 DEBUG: Dependency 's3://mlflow-artifacts/metadata/version_meta.json' of stage: 'preprocess' changed because it is 'modified'.
[2025-08-12T20:09:56.409+0000] {subprocess.py:93} INFO - 2025-08-12 20:09:56,408 DEBUG: stage: 'preprocess' changed.
[2025-08-12T20:09:56.420+0000] {subprocess.py:93} INFO - 2025-08-12 20:09:56,420 DEBUG: Removing output 's3://mlflow-artifacts/preprocess/v20250812_055140/pipeline.pkl' of stage: 'preprocess'.
[2025-08-12T20:09:56.638+0000] {subprocess.py:93} INFO - 2025-08-12 20:09:56,638 DEBUG: Removing output 's3://mlflow-artifacts/preprocess/v20250812_055140/preprocess_metadata.json' of stage: 'preprocess'.
[2025-08-12T20:09:57.098+0000] {subprocess.py:93} INFO - 2025-08-12 20:09:57,097 DEBUG: built tree 'object 602ddb43893d85443cd66ec20dfe4e77.dir'
[2025-08-12T20:09:57.105+0000] {subprocess.py:93} INFO - Running stage 'preprocess':
[2025-08-12T20:09:57.105+0000] {subprocess.py:93} INFO - > python preprocessing/preprocess_task.py
[2025-08-12T20:10:00.211+0000] {subprocess.py:93} INFO - {"asctime": "2025-08-12 20:10:00,141", "levelname": "INFO", "name": "preprocessing_pipeline", "trace_id": null, "span_id": null, "message": "version_meta.json loaded!"}
[2025-08-12T20:10:00.262+0000] {subprocess.py:93} INFO - {"asctime": "2025-08-12 20:10:00,261", "levelname": "INFO", "name": "preprocessing_pipeline", "trace_id": null, "span_id": null, "message": "preprocessor trained!"}
[2025-08-12T20:10:00.286+0000] {subprocess.py:93} INFO - {"asctime": "2025-08-12 20:10:00,286", "levelname": "INFO", "name": "preprocessing_pipeline", "trace_id": null, "span_id": null, "message": "preprocessor saved to s3://mlflow-artifacts/preprocess/v20250812_055140/pipeline.pkl!"}
[2025-08-12T20:10:00.325+0000] {subprocess.py:93} INFO - {"asctime": "2025-08-12 20:10:00,324", "levelname": "INFO", "name": "preprocessing_pipeline", "trace_id": null, "span_id": null, "message": "\u2705 Saved pipeline at: s3://mlflow-artifacts/s3://mlflow-artifacts/preprocess/v20250812_055140/pipeline.pkl"}
[2025-08-12T20:10:00.327+0000] {subprocess.py:93} INFO - {"asctime": "2025-08-12 20:10:00,325", "levelname": "INFO", "name": "preprocessing_pipeline", "trace_id": null, "span_id": null, "message": "\ud83d\udcc4 Saved metadata: s3://mlflow-artifacts/s3://mlflow-artifacts/preprocess/v20250812_055140/preprocess_metadata.json"}
[2025-08-12T20:10:00.329+0000] {subprocess.py:93} INFO - {"asctime": "2025-08-12 20:10:00,325", "levelname": "INFO", "name": "preprocessing_pipeline", "trace_id": null, "span_id": null, "message": "\ud83d\udce6 Updated version_meta.json"}
[2025-08-12T20:10:00.820+0000] {subprocess.py:93} INFO - 2025-08-12 20:10:00,820 DEBUG: built tree 'object 602ddb43893d85443cd66ec20dfe4e77.dir'
[2025-08-12T20:10:00.859+0000] {subprocess.py:93} INFO - 2025-08-12 20:10:00,849 ERROR: failed to reproduce 'preprocess': Saving cached external output s3://mlflow-artifacts/preprocess/v20250812_055140/pipeline.pkl is not supported since DVC 3.0. See <https://dvc.org/doc/user-guide/upgrade> for more info.
[2025-08-12T20:10:00.859+0000] {subprocess.py:93} INFO - Traceback (most recent call last):
[2025-08-12T20:10:00.860+0000] {subprocess.py:93} INFO -   File "/home/***/.local/lib/python3.12/site-packages/dvc/repo/reproduce.py", line 187, in _reproduce
[2025-08-12T20:10:00.861+0000] {subprocess.py:93} INFO -     ret = repro_fn(stage, upstream=upstream, force=force_stage, **kwargs)
[2025-08-12T20:10:00.862+0000] {subprocess.py:93} INFO -           ^^^^^^^^^^^^^^^^^^^^^^^^^^^^^^^^^^^^^^^^^^^^^^^^^^^^^^^^^^^^^^^
[2025-08-12T20:10:00.862+0000] {subprocess.py:93} INFO -   File "/home/***/.local/lib/python3.12/site-packages/dvc/repo/reproduce.py", line 117, in _reproduce_stage
[2025-08-12T20:10:00.863+0000] {subprocess.py:93} INFO -     ret = stage.reproduce(**kwargs)
[2025-08-12T20:10:00.863+0000] {subprocess.py:93} INFO -           ^^^^^^^^^^^^^^^^^^^^^^^^^
[2025-08-12T20:10:00.864+0000] {subprocess.py:93} INFO -   File "/home/***/.local/lib/python3.12/site-packages/funcy/decorators.py", line 47, in wrapper
[2025-08-12T20:10:00.864+0000] {subprocess.py:93} INFO -     return deco(call, *dargs, **dkwargs)
[2025-08-12T20:10:00.865+0000] {subprocess.py:93} INFO -            ^^^^^^^^^^^^^^^^^^^^^^^^^^^^^
[2025-08-12T20:10:00.865+0000] {subprocess.py:93} INFO -   File "/home/***/.local/lib/python3.12/site-packages/dvc/stage/decorators.py", line 44, in rwlocked
[2025-08-12T20:10:00.866+0000] {subprocess.py:93} INFO -     return call()
[2025-08-12T20:10:00.866+0000] {subprocess.py:93} INFO -            ^^^^^^
[2025-08-12T20:10:00.867+0000] {subprocess.py:93} INFO -   File "/home/***/.local/lib/python3.12/site-packages/funcy/decorators.py", line 68, in __call__
[2025-08-12T20:10:00.867+0000] {subprocess.py:93} INFO -     return self._func(*self._args, **self._kwargs)
[2025-08-12T20:10:00.868+0000] {subprocess.py:93} INFO -            ^^^^^^^^^^^^^^^^^^^^^^^^^^^^^^^^^^^^^^^
[2025-08-12T20:10:00.868+0000] {subprocess.py:93} INFO -   File "/home/***/.local/lib/python3.12/site-packages/dvc/stage/__init__.py", line 448, in reproduce
[2025-08-12T20:10:00.869+0000] {subprocess.py:93} INFO -     self.run(**kwargs)
[2025-08-12T20:10:00.869+0000] {subprocess.py:93} INFO -   File "/home/***/.local/lib/python3.12/site-packages/funcy/decorators.py", line 47, in wrapper
[2025-08-12T20:10:00.870+0000] {subprocess.py:93} INFO -     return deco(call, *dargs, **dkwargs)
[2025-08-12T20:10:00.870+0000] {subprocess.py:93} INFO -            ^^^^^^^^^^^^^^^^^^^^^^^^^^^^^
[2025-08-12T20:10:00.871+0000] {subprocess.py:93} INFO -   File "/home/***/.local/lib/python3.12/site-packages/dvc/stage/decorators.py", line 44, in rwlocked
[2025-08-12T20:10:00.871+0000] {subprocess.py:93} INFO -     return call()
[2025-08-12T20:10:00.872+0000] {subprocess.py:93} INFO -            ^^^^^^
[2025-08-12T20:10:00.872+0000] {subprocess.py:93} INFO -   File "/home/***/.local/lib/python3.12/site-packages/funcy/decorators.py", line 68, in __call__
[2025-08-12T20:10:00.873+0000] {subprocess.py:93} INFO -     return self._func(*self._args, **self._kwargs)
[2025-08-12T20:10:00.874+0000] {subprocess.py:93} INFO -            ^^^^^^^^^^^^^^^^^^^^^^^^^^^^^^^^^^^^^^^
[2025-08-12T20:10:00.874+0000] {subprocess.py:93} INFO -   File "/home/***/.local/lib/python3.12/site-packages/dvc/stage/__init__.py", line 629, in run
[2025-08-12T20:10:00.875+0000] {subprocess.py:93} INFO -     self.save(
[2025-08-12T20:10:00.875+0000] {subprocess.py:93} INFO -   File "/home/***/.local/lib/python3.12/site-packages/dvc/stage/__init__.py", line 495, in save
[2025-08-12T20:10:00.876+0000] {subprocess.py:93} INFO -     self.save_outs(allow_missing=allow_missing)
[2025-08-12T20:10:00.876+0000] {subprocess.py:93} INFO -   File "/home/***/.local/lib/python3.12/site-packages/dvc/stage/__init__.py", line 533, in save_outs
[2025-08-12T20:10:00.877+0000] {subprocess.py:93} INFO -     out.save()
[2025-08-12T20:10:00.877+0000] {subprocess.py:93} INFO -   File "/home/***/.local/lib/python3.12/site-packages/dvc/output.py", line 677, in save
[2025-08-12T20:10:00.878+0000] {subprocess.py:93} INFO -     raise DvcException(
[2025-08-12T20:10:00.879+0000] {subprocess.py:93} INFO - dvc.exceptions.DvcException: Saving cached external output s3://mlflow-artifacts/preprocess/v20250812_055140/pipeline.pkl is not supported since DVC 3.0. See <https://dvc.org/doc/user-guide/upgrade> for more info.
[2025-08-12T20:10:00.879+0000] {subprocess.py:93} INFO - 
[2025-08-12T20:10:00.880+0000] {subprocess.py:93} INFO - The above exception was the direct cause of the following exception:
[2025-08-12T20:10:00.880+0000] {subprocess.py:93} INFO - 
[2025-08-12T20:10:00.881+0000] {subprocess.py:93} INFO - Traceback (most recent call last):
[2025-08-12T20:10:00.881+0000] {subprocess.py:93} INFO -   File "/home/***/.local/lib/python3.12/site-packages/dvc/cli/__init__.py", line 211, in main
[2025-08-12T20:10:00.882+0000] {subprocess.py:93} INFO -     ret = cmd.do_run()
[2025-08-12T20:10:00.882+0000] {subprocess.py:93} INFO -           ^^^^^^^^^^^^
[2025-08-12T20:10:00.883+0000] {subprocess.py:93} INFO -   File "/home/***/.local/lib/python3.12/site-packages/dvc/cli/command.py", line 30, in do_run
[2025-08-12T20:10:00.883+0000] {subprocess.py:93} INFO -     return self.run()
[2025-08-12T20:10:00.884+0000] {subprocess.py:93} INFO -            ^^^^^^^^^^
[2025-08-12T20:10:00.884+0000] {subprocess.py:93} INFO -   File "/home/***/.local/lib/python3.12/site-packages/dvc/commands/repro.py", line 11, in run
[2025-08-12T20:10:00.885+0000] {subprocess.py:93} INFO -     stages = self.repo.reproduce(**self._common_kwargs, **self._repro_kwargs)
[2025-08-12T20:10:00.885+0000] {subprocess.py:93} INFO -              ^^^^^^^^^^^^^^^^^^^^^^^^^^^^^^^^^^^^^^^^^^^^^^^^^^^^^^^^^^^^^^^^
[2025-08-12T20:10:00.886+0000] {subprocess.py:93} INFO -   File "/home/***/.local/lib/python3.12/site-packages/dvc/repo/__init__.py", line 58, in wrapper
[2025-08-12T20:10:00.886+0000] {subprocess.py:93} INFO -     return f(repo, *args, **kwargs)
[2025-08-12T20:10:00.887+0000] {subprocess.py:93} INFO -            ^^^^^^^^^^^^^^^^^^^^^^^^
[2025-08-12T20:10:00.887+0000] {subprocess.py:93} INFO -   File "/home/***/.local/lib/python3.12/site-packages/dvc/repo/scm_context.py", line 143, in run
[2025-08-12T20:10:00.888+0000] {subprocess.py:93} INFO -     return method(repo, *args, **kw)
[2025-08-12T20:10:00.888+0000] {subprocess.py:93} INFO -            ^^^^^^^^^^^^^^^^^^^^^^^^^
[2025-08-12T20:10:00.889+0000] {subprocess.py:93} INFO -   File "/home/***/.local/lib/python3.12/site-packages/dvc/repo/reproduce.py", line 248, in reproduce
[2025-08-12T20:10:00.889+0000] {subprocess.py:93} INFO -     return _reproduce(steps, graph=graph, on_error=on_error or "fail", **kwargs)
[2025-08-12T20:10:00.890+0000] {subprocess.py:93} INFO -            ^^^^^^^^^^^^^^^^^^^^^^^^^^^^^^^^^^^^^^^^^^^^^^^^^^^^^^^^^^^^^^^^^^^^^
[2025-08-12T20:10:00.890+0000] {subprocess.py:93} INFO -   File "/home/***/.local/lib/python3.12/site-packages/dvc/repo/reproduce.py", line 191, in _reproduce
[2025-08-12T20:10:00.891+0000] {subprocess.py:93} INFO -     _raise_error(exc, stage)
[2025-08-12T20:10:00.891+0000] {subprocess.py:93} INFO -   File "/home/***/.local/lib/python3.12/site-packages/dvc/repo/reproduce.py", line 155, in _raise_error
[2025-08-12T20:10:00.892+0000] {subprocess.py:93} INFO -     raise ReproductionError(f"failed to reproduce{segment} {names}") from exc
[2025-08-12T20:10:00.892+0000] {subprocess.py:93} INFO - dvc.exceptions.ReproductionError: failed to reproduce 'preprocess'
[2025-08-12T20:10:00.893+0000] {subprocess.py:93} INFO - 
[2025-08-12T20:10:00.894+0000] {subprocess.py:93} INFO - 2025-08-12 20:10:00,862 DEBUG: Analytics is enabled.
[2025-08-12T20:10:00.968+0000] {subprocess.py:93} INFO - 2025-08-12 20:10:00,967 DEBUG: Trying to spawn ['daemon', 'analytics', '/tmp/tmp4l9zmonv', '-v']
[2025-08-12T20:10:00.980+0000] {subprocess.py:93} INFO - 2025-08-12 20:10:00,979 DEBUG: Spawned ['daemon', 'analytics', '/tmp/tmp4l9zmonv', '-v'] with pid 1410
[2025-08-12T20:10:01.480+0000] {subprocess.py:97} INFO - Command exited with return code 255
[2025-08-12T20:10:01.481+0000] {taskinstance.py:441} INFO - ::group::Post task execution logs
[2025-08-12T20:10:01.497+0000] {taskinstance.py:2905} ERROR - Task failed with exception
Traceback (most recent call last):
  File "/home/airflow/.local/lib/python3.12/site-packages/airflow/models/taskinstance.py", line 465, in _execute_task
    result = _execute_callable(context=context, **execute_callable_kwargs)
             ^^^^^^^^^^^^^^^^^^^^^^^^^^^^^^^^^^^^^^^^^^^^^^^^^^^^^^^^^^^^^
  File "/home/airflow/.local/lib/python3.12/site-packages/airflow/models/taskinstance.py", line 432, in _execute_callable
    return execute_callable(context=context, **execute_callable_kwargs)
           ^^^^^^^^^^^^^^^^^^^^^^^^^^^^^^^^^^^^^^^^^^^^^^^^^^^^^^^^^^^^
  File "/home/airflow/.local/lib/python3.12/site-packages/airflow/models/baseoperator.py", line 400, in wrapper
    return func(self, *args, **kwargs)
           ^^^^^^^^^^^^^^^^^^^^^^^^^^^
  File "/home/airflow/.local/lib/python3.12/site-packages/airflow/operators/bash.py", line 243, in execute
    raise AirflowException(
airflow.exceptions.AirflowException: Bash command failed. The command returned a non-zero exit code 255.
[2025-08-12T20:10:01.506+0000] {taskinstance.py:1206} INFO - Marking task as UP_FOR_RETRY. dag_id=ml_pipeline_dvc, task_id=setup_dvc_remote, run_id=manual__2025-08-12T20:09:33.481107+00:00, execution_date=20250812T200933, start_date=20250812T200935, end_date=20250812T201001
[2025-08-12T20:10:01.544+0000] {standard_task_runner.py:110} ERROR - Failed to execute job 157 for task setup_dvc_remote (Bash command failed. The command returned a non-zero exit code 255.; 1222)
[2025-08-12T20:10:01.578+0000] {local_task_job_runner.py:240} INFO - Task exited with return code 1
[2025-08-12T20:10:01.601+0000] {local_task_job_runner.py:222} INFO - ::endgroup::
