[2025-08-12T16:18:06.962+0000] {local_task_job_runner.py:120} INFO - ::group::Pre task execution logs
[2025-08-12T16:18:07.072+0000] {taskinstance.py:2076} INFO - Dependencies all met for dep_context=non-requeueable deps ti=<TaskInstance: ml_pipeline_dvc.setup_dvc_remote manual__2025-08-12T16:18:06.079120+00:00 [queued]>
[2025-08-12T16:18:07.096+0000] {taskinstance.py:2076} INFO - Dependencies all met for dep_context=requeueable deps ti=<TaskInstance: ml_pipeline_dvc.setup_dvc_remote manual__2025-08-12T16:18:06.079120+00:00 [queued]>
[2025-08-12T16:18:07.099+0000] {taskinstance.py:2306} INFO - Starting attempt 1 of 2
[2025-08-12T16:18:07.154+0000] {taskinstance.py:2330} INFO - Executing <Task(BashOperator): setup_dvc_remote> on 2025-08-12 16:18:06.079120+00:00
[2025-08-12T16:18:07.176+0000] {standard_task_runner.py:90} INFO - Running: ['***', 'tasks', 'run', 'ml_pipeline_dvc', 'setup_dvc_remote', 'manual__2025-08-12T16:18:06.079120+00:00', '--job-id', '109', '--raw', '--subdir', 'DAGS_FOLDER/train_pipeline_dag.py', '--cfg-path', '/tmp/tmpitr1cmdj']
[2025-08-12T16:18:07.176+0000] {warnings.py:110} WARNING - /home/***/.local/lib/python3.12/site-packages/***/task/task_runner/standard_task_runner.py:61: DeprecationWarning: This process (pid=3952) is multi-threaded, use of fork() may lead to deadlocks in the child.
  pid = os.fork()

[2025-08-12T16:18:07.182+0000] {standard_task_runner.py:91} INFO - Job 109: Subtask setup_dvc_remote
[2025-08-12T16:18:07.183+0000] {standard_task_runner.py:63} INFO - Started process 3953 to run task
[2025-08-12T16:18:07.439+0000] {task_command.py:426} INFO - Running <TaskInstance: ml_pipeline_dvc.setup_dvc_remote manual__2025-08-12T16:18:06.079120+00:00 [running]> on host 563139bd1525
[2025-08-12T16:18:07.765+0000] {taskinstance.py:2648} INFO - Exporting env vars: AIRFLOW_CTX_DAG_OWNER='yas' AIRFLOW_CTX_DAG_ID='ml_pipeline_dvc' AIRFLOW_CTX_TASK_ID='setup_dvc_remote' AIRFLOW_CTX_EXECUTION_DATE='2025-08-12T16:18:06.079120+00:00' AIRFLOW_CTX_TRY_NUMBER='1' AIRFLOW_CTX_DAG_RUN_ID='manual__2025-08-12T16:18:06.079120+00:00'
[2025-08-12T16:18:07.767+0000] {taskinstance.py:430} INFO - ::endgroup::
[2025-08-12T16:18:07.846+0000] {subprocess.py:63} INFO - Tmp dir root location: /tmp
[2025-08-12T16:18:07.852+0000] {subprocess.py:75} INFO - Running command: ['/usr/bin/bash', '-c', '\n        ls .\n        dvc remote add -f minio s3://mlflow-artifacts\n        dvc remote modify minio endpointurl http://minio:9000\n        dvc remote modify minio access_key_id minioadmin\n        dvc remote modify minio secret_access_key minioadmin\n        dvc remote modify minio use_ssl false\n        dvc remote default minio\n        ']
[2025-08-12T16:18:07.909+0000] {subprocess.py:86} INFO - Output:
[2025-08-12T16:18:11.129+0000] {subprocess.py:93} INFO - ERROR: configuration error - config file error: Not inside a DVC repo
[2025-08-12T16:18:12.753+0000] {subprocess.py:93} INFO - ERROR: configuration error - config file error: Not inside a DVC repo
[2025-08-12T16:18:14.876+0000] {subprocess.py:93} INFO - ERROR: configuration error - config file error: Not inside a DVC repo
[2025-08-12T16:18:16.824+0000] {subprocess.py:93} INFO - ERROR: configuration error - config file error: Not inside a DVC repo
[2025-08-12T16:18:18.810+0000] {subprocess.py:93} INFO - ERROR: configuration error - config file error: Not inside a DVC repo
[2025-08-12T16:18:21.138+0000] {subprocess.py:93} INFO - ERROR: configuration error - config file error: Not inside a DVC repo
[2025-08-12T16:18:21.726+0000] {subprocess.py:97} INFO - Command exited with return code 251
[2025-08-12T16:18:21.732+0000] {taskinstance.py:441} INFO - ::group::Post task execution logs
[2025-08-12T16:18:21.796+0000] {taskinstance.py:2905} ERROR - Task failed with exception
Traceback (most recent call last):
  File "/home/airflow/.local/lib/python3.12/site-packages/airflow/models/taskinstance.py", line 465, in _execute_task
    result = _execute_callable(context=context, **execute_callable_kwargs)
             ^^^^^^^^^^^^^^^^^^^^^^^^^^^^^^^^^^^^^^^^^^^^^^^^^^^^^^^^^^^^^
  File "/home/airflow/.local/lib/python3.12/site-packages/airflow/models/taskinstance.py", line 432, in _execute_callable
    return execute_callable(context=context, **execute_callable_kwargs)
           ^^^^^^^^^^^^^^^^^^^^^^^^^^^^^^^^^^^^^^^^^^^^^^^^^^^^^^^^^^^^
  File "/home/airflow/.local/lib/python3.12/site-packages/airflow/models/baseoperator.py", line 400, in wrapper
    return func(self, *args, **kwargs)
           ^^^^^^^^^^^^^^^^^^^^^^^^^^^
  File "/home/airflow/.local/lib/python3.12/site-packages/airflow/operators/bash.py", line 243, in execute
    raise AirflowException(
airflow.exceptions.AirflowException: Bash command failed. The command returned a non-zero exit code 251.
[2025-08-12T16:18:21.815+0000] {taskinstance.py:1206} INFO - Marking task as UP_FOR_RETRY. dag_id=ml_pipeline_dvc, task_id=setup_dvc_remote, run_id=manual__2025-08-12T16:18:06.079120+00:00, execution_date=20250812T161806, start_date=20250812T161807, end_date=20250812T161821
[2025-08-12T16:18:21.863+0000] {standard_task_runner.py:110} ERROR - Failed to execute job 109 for task setup_dvc_remote (Bash command failed. The command returned a non-zero exit code 251.; 3953)
[2025-08-12T16:18:21.912+0000] {local_task_job_runner.py:240} INFO - Task exited with return code 1
[2025-08-12T16:18:21.958+0000] {taskinstance.py:3498} INFO - 0 downstream tasks scheduled from follow-on schedule check
[2025-08-12T16:18:21.962+0000] {local_task_job_runner.py:222} INFO - ::endgroup::
