[2025-08-12T21:57:15.481+0000] {task_context_logger.py:104} ERROR - Executor reports task instance <TaskInstance: ml_pipeline_dvc.train_outlier manual__2025-08-12T21:51:51.495065+00:00 [queued]> finished (failed) although the task says it's queued. (Info: None) Was the task killed externally?
