[2025-08-07T04:26:52.885+0000] {local_task_job_runner.py:120} INFO - ::group::Pre task execution logs
[2025-08-07T04:26:53.167+0000] {taskinstance.py:2076} INFO - Dependencies all met for dep_context=non-requeueable deps ti=<TaskInstance: register_high_latency_model.rollback_model manual__2025-08-07T04:21:41.978479+00:00 [queued]>
[2025-08-07T04:26:53.180+0000] {taskinstance.py:2076} INFO - Dependencies all met for dep_context=requeueable deps ti=<TaskInstance: register_high_latency_model.rollback_model manual__2025-08-07T04:21:41.978479+00:00 [queued]>
[2025-08-07T04:26:53.181+0000] {taskinstance.py:2306} INFO - Starting attempt 2 of 2
[2025-08-07T04:26:53.202+0000] {taskinstance.py:2330} INFO - Executing <Task(PythonOperator): rollback_model> on 2025-08-07 04:21:41.978479+00:00
[2025-08-07T04:26:53.220+0000] {warnings.py:110} WARNING - /home/***/.local/lib/python3.12/site-packages/***/task/task_runner/standard_task_runner.py:61: DeprecationWarning: This process (pid=4707) is multi-threaded, use of fork() may lead to deadlocks in the child.
  pid = os.fork()

[2025-08-07T04:26:53.223+0000] {standard_task_runner.py:63} INFO - Started process 4717 to run task
[2025-08-07T04:26:53.223+0000] {standard_task_runner.py:90} INFO - Running: ['***', 'tasks', 'run', 'register_high_latency_model', 'rollback_model', 'manual__2025-08-07T04:21:41.978479+00:00', '--job-id', '17', '--raw', '--subdir', 'DAGS_FOLDER/test_model_rollback.py', '--cfg-path', '/tmp/tmpqzbpnx9z']
[2025-08-07T04:26:53.228+0000] {standard_task_runner.py:91} INFO - Job 17: Subtask rollback_model
[2025-08-07T04:26:53.308+0000] {task_command.py:426} INFO - Running <TaskInstance: register_high_latency_model.rollback_model manual__2025-08-07T04:21:41.978479+00:00 [running]> on host 875a2765ee06
[2025-08-07T04:26:53.473+0000] {taskinstance.py:2648} INFO - Exporting env vars: AIRFLOW_CTX_DAG_OWNER='***' AIRFLOW_CTX_DAG_ID='register_high_latency_model' AIRFLOW_CTX_TASK_ID='rollback_model' AIRFLOW_CTX_EXECUTION_DATE='2025-08-07T04:21:41.978479+00:00' AIRFLOW_CTX_TRY_NUMBER='2' AIRFLOW_CTX_DAG_RUN_ID='manual__2025-08-07T04:21:41.978479+00:00'
[2025-08-07T04:26:53.475+0000] {taskinstance.py:430} INFO - ::endgroup::
[2025-08-07T04:26:53.710+0000] {taskinstance.py:441} INFO - ::group::Post task execution logs
[2025-08-07T04:26:53.712+0000] {taskinstance.py:2905} ERROR - Task failed with exception
Traceback (most recent call last):
  File "/home/airflow/.local/lib/python3.12/site-packages/airflow/models/taskinstance.py", line 465, in _execute_task
    result = _execute_callable(context=context, **execute_callable_kwargs)
             ^^^^^^^^^^^^^^^^^^^^^^^^^^^^^^^^^^^^^^^^^^^^^^^^^^^^^^^^^^^^^
  File "/home/airflow/.local/lib/python3.12/site-packages/airflow/models/taskinstance.py", line 432, in _execute_callable
    return execute_callable(context=context, **execute_callable_kwargs)
           ^^^^^^^^^^^^^^^^^^^^^^^^^^^^^^^^^^^^^^^^^^^^^^^^^^^^^^^^^^^^
  File "/home/airflow/.local/lib/python3.12/site-packages/airflow/models/baseoperator.py", line 400, in wrapper
    return func(self, *args, **kwargs)
           ^^^^^^^^^^^^^^^^^^^^^^^^^^^
  File "/home/airflow/.local/lib/python3.12/site-packages/airflow/operators/python.py", line 235, in execute
    return_value = self.execute_callable()
                   ^^^^^^^^^^^^^^^^^^^^^^^
  File "/home/airflow/.local/lib/python3.12/site-packages/airflow/operators/python.py", line 252, in execute_callable
    return self.python_callable(*self.op_args, **self.op_kwargs)
           ^^^^^^^^^^^^^^^^^^^^^^^^^^^^^^^^^^^^^^^^^^^^^^^^^^^^^
  File "/opt/airflow/dags/test_model_rollback.py", line 33, in wrap_and_register_model
    original_model = mlflow.pyfunc.load_model(model_uri=f"models:/{MODEL_NAME}/Production")
                     ^^^^^^^^^^^^^^^^^^^^^^^^^^^^^^^^^^^^^^^^^^^^^^^^^^^^^^^^^^^^^^^^^^^^^^
  File "/home/airflow/.local/lib/python3.12/site-packages/mlflow/tracing/provider.py", line 465, in wrapper
    result = f(*args, **kwargs)
             ^^^^^^^^^^^^^^^^^^
  File "/home/airflow/.local/lib/python3.12/site-packages/mlflow/pyfunc/__init__.py", line 1131, in load_model
    local_path = _download_artifact_from_uri(
                 ^^^^^^^^^^^^^^^^^^^^^^^^^^^^
  File "/home/airflow/.local/lib/python3.12/site-packages/mlflow/tracking/artifact_utils.py", line 115, in _download_artifact_from_uri
    repo = get_artifact_repository(artifact_uri=root_uri, tracking_uri=tracking_uri)
           ^^^^^^^^^^^^^^^^^^^^^^^^^^^^^^^^^^^^^^^^^^^^^^^^^^^^^^^^^^^^^^^^^^^^^^^^^
  File "/home/airflow/.local/lib/python3.12/site-packages/mlflow/store/artifact/artifact_repository_registry.py", line 144, in get_artifact_repository
    return _artifact_repository_registry.get_artifact_repository(artifact_uri, tracking_uri)
           ^^^^^^^^^^^^^^^^^^^^^^^^^^^^^^^^^^^^^^^^^^^^^^^^^^^^^^^^^^^^^^^^^^^^^^^^^^^^^^^^^
  File "/home/airflow/.local/lib/python3.12/site-packages/mlflow/store/artifact/artifact_repository_registry.py", line 82, in get_artifact_repository
    return repository(artifact_uri, tracking_uri=tracking_uri)
           ^^^^^^^^^^^^^^^^^^^^^^^^^^^^^^^^^^^^^^^^^^^^^^^^^^^
  File "/home/airflow/.local/lib/python3.12/site-packages/mlflow/store/artifact/models_artifact_repo.py", line 73, in __init__
    ) = ModelsArtifactRepository._get_model_uri_infos(artifact_uri)
        ^^^^^^^^^^^^^^^^^^^^^^^^^^^^^^^^^^^^^^^^^^^^^^^^^^^^^^^^^^^
  File "/home/airflow/.local/lib/python3.12/site-packages/mlflow/store/artifact/models_artifact_repo.py", line 124, in _get_model_uri_infos
    name_and_version_or_id = get_model_name_and_version(client, uri)
                             ^^^^^^^^^^^^^^^^^^^^^^^^^^^^^^^^^^^^^^^
  File "/home/airflow/.local/lib/python3.12/site-packages/mlflow/store/artifact/utils/models.py", line 148, in get_model_name_and_version
    return model_name, str(_get_latest_model_version(client, model_name, model_stage))
                           ^^^^^^^^^^^^^^^^^^^^^^^^^^^^^^^^^^^^^^^^^^^^^^^^^^^^^^^^^^
  File "/home/airflow/.local/lib/python3.12/site-packages/mlflow/store/artifact/utils/models.py", line 40, in _get_latest_model_version
    latest = client.get_latest_versions(name, None if stage is None else [stage])
             ^^^^^^^^^^^^^^^^^^^^^^^^^^^^^^^^^^^^^^^^^^^^^^^^^^^^^^^^^^^^^^^^^^^^
  File "/home/airflow/.local/lib/python3.12/site-packages/mlflow/tracking/_model_registry/client.py", line 186, in get_latest_versions
    return self.store.get_latest_versions(name, stages)
           ^^^^^^^^^^^^^^^^^^^^^^^^^^^^^^^^^^^^^^^^^^^^
  File "/home/airflow/.local/lib/python3.12/site-packages/mlflow/store/model_registry/file_store.py", line 444, in get_latest_versions
    raise MlflowException(
mlflow.exceptions.MlflowException: Registered Model with name=FraudDetectionModel not found
[2025-08-07T04:26:53.731+0000] {taskinstance.py:1206} INFO - Marking task as FAILED. dag_id=register_high_latency_model, task_id=rollback_model, run_id=manual__2025-08-07T04:21:41.978479+00:00, execution_date=20250807T042141, start_date=20250807T042653, end_date=20250807T042653
[2025-08-07T04:26:53.753+0000] {standard_task_runner.py:110} ERROR - Failed to execute job 17 for task rollback_model (Registered Model with name=FraudDetectionModel not found; 4717)
[2025-08-07T04:26:53.773+0000] {local_task_job_runner.py:240} INFO - Task exited with return code 1
[2025-08-07T04:26:53.798+0000] {taskinstance.py:3498} INFO - 0 downstream tasks scheduled from follow-on schedule check
[2025-08-07T04:26:53.802+0000] {local_task_job_runner.py:222} INFO - ::endgroup::
