[2025-08-06T03:36:29.040+0000] {local_task_job_runner.py:120} INFO - ::group::Pre task execution logs
[2025-08-06T03:36:29.076+0000] {taskinstance.py:2076} INFO - Dependencies all met for dep_context=non-requeueable deps ti=<TaskInstance: ml_pipeline_dvc.train_dvc manual__2025-08-06T03:36:17.219079+00:00 [queued]>
[2025-08-06T03:36:29.089+0000] {taskinstance.py:2076} INFO - Dependencies all met for dep_context=requeueable deps ti=<TaskInstance: ml_pipeline_dvc.train_dvc manual__2025-08-06T03:36:17.219079+00:00 [queued]>
[2025-08-06T03:36:29.090+0000] {taskinstance.py:2306} INFO - Starting attempt 1 of 2
[2025-08-06T03:36:29.113+0000] {taskinstance.py:2330} INFO - Executing <Task(BashOperator): train_dvc> on 2025-08-06 03:36:17.219079+00:00
[2025-08-06T03:36:29.121+0000] {warnings.py:110} WARNING - /home/***/.local/lib/python3.12/site-packages/***/task/task_runner/standard_task_runner.py:61: DeprecationWarning: This process (pid=533) is multi-threaded, use of fork() may lead to deadlocks in the child.
  pid = os.fork()

[2025-08-06T03:36:29.124+0000] {standard_task_runner.py:63} INFO - Started process 550 to run task
[2025-08-06T03:36:29.123+0000] {standard_task_runner.py:90} INFO - Running: ['***', 'tasks', 'run', 'ml_pipeline_dvc', 'train_dvc', 'manual__2025-08-06T03:36:17.219079+00:00', '--job-id', '11', '--raw', '--subdir', 'DAGS_FOLDER/ml_pipeline_dag_2.py', '--cfg-path', '/tmp/tmpv1j6vqor']
[2025-08-06T03:36:29.125+0000] {standard_task_runner.py:91} INFO - Job 11: Subtask train_dvc
[2025-08-06T03:36:29.217+0000] {task_command.py:426} INFO - Running <TaskInstance: ml_pipeline_dvc.train_dvc manual__2025-08-06T03:36:17.219079+00:00 [running]> on host 1d9cc99197c4
[2025-08-06T03:36:29.358+0000] {taskinstance.py:2648} INFO - Exporting env vars: AIRFLOW_CTX_DAG_OWNER='yas' AIRFLOW_CTX_DAG_ID='ml_pipeline_dvc' AIRFLOW_CTX_TASK_ID='train_dvc' AIRFLOW_CTX_EXECUTION_DATE='2025-08-06T03:36:17.219079+00:00' AIRFLOW_CTX_TRY_NUMBER='1' AIRFLOW_CTX_DAG_RUN_ID='manual__2025-08-06T03:36:17.219079+00:00'
[2025-08-06T03:36:29.360+0000] {taskinstance.py:430} INFO - ::endgroup::
[2025-08-06T03:36:29.380+0000] {subprocess.py:63} INFO - Tmp dir root location: /tmp
[2025-08-06T03:36:29.381+0000] {subprocess.py:75} INFO - Running command: ['/usr/bin/bash', '-c', 'cd /opt/***/ml_pipeline && dvc repro train']
[2025-08-06T03:36:29.394+0000] {subprocess.py:86} INFO - Output:
[2025-08-06T03:36:31.893+0000] {subprocess.py:93} INFO - Stage 'preprocess' didn't change, skipping
[2025-08-06T03:36:32.004+0000] {subprocess.py:93} INFO - Running stage 'train':
[2025-08-06T03:36:32.005+0000] {subprocess.py:93} INFO - > python train/train_task.py
[2025-08-06T03:36:36.118+0000] {subprocess.py:93} INFO - INFO:__main__:Outlier detector saved to artifacts/models/outlier_detector_v20250801_144307.pkl
[2025-08-06T03:36:36.135+0000] {subprocess.py:93} INFO - /home/***/.local/lib/python3.12/site-packages/sklearn/metrics/_ranking.py:1201: UndefinedMetricWarning: No positive samples in y_true, true positive value should be meaningless
[2025-08-06T03:36:36.137+0000] {subprocess.py:93} INFO -   warnings.warn(
[2025-08-06T03:36:36.165+0000] {subprocess.py:93} INFO - INFO:__main__:üìÑ Training metadata saved to artifacts/train/train_metadata_v20250801_144307.json
[2025-08-06T03:36:36.166+0000] {subprocess.py:93} INFO - INFO:__main__:üì¶ Updated version_meta.json
[2025-08-06T03:36:36.167+0000] {subprocess.py:93} INFO - INFO:__main__:üìÑ Registering the model FraudDetectionModel
[2025-08-06T03:36:36.397+0000] {subprocess.py:93} INFO - 2025/08/06 03:36:36 WARNING mlflow.utils.git_utils: Failed to import Git (the Git executable is probably not on your PATH), so Git SHA is not available. Error: Failed to initialize: Bad git executable.
[2025-08-06T03:36:36.398+0000] {subprocess.py:93} INFO - The git executable must be specified in one of the following ways:
[2025-08-06T03:36:36.399+0000] {subprocess.py:93} INFO -     - be included in your $PATH
[2025-08-06T03:36:36.400+0000] {subprocess.py:93} INFO -     - be set via $GIT_PYTHON_GIT_EXECUTABLE
[2025-08-06T03:36:36.401+0000] {subprocess.py:93} INFO -     - explicitly set via git.refresh(<full-path-to-git-executable>)
[2025-08-06T03:36:36.401+0000] {subprocess.py:93} INFO - 
[2025-08-06T03:36:36.402+0000] {subprocess.py:93} INFO - All git commands will error until this is rectified.
[2025-08-06T03:36:36.403+0000] {subprocess.py:93} INFO - 
[2025-08-06T03:36:36.403+0000] {subprocess.py:93} INFO - This initial message can be silenced or aggravated in the future by setting the
[2025-08-06T03:36:36.404+0000] {subprocess.py:93} INFO - $GIT_PYTHON_REFRESH environment variable. Use one of the following values:
[2025-08-06T03:36:36.405+0000] {subprocess.py:93} INFO -     - quiet|q|silence|s|silent|none|n|0: for no message or exception
[2025-08-06T03:36:36.405+0000] {subprocess.py:93} INFO -     - warn|w|warning|log|l|1: for a warning message (logging level CRITICAL, displayed by default)
[2025-08-06T03:36:36.406+0000] {subprocess.py:93} INFO -     - error|e|exception|raise|r|2: for a raised exception
[2025-08-06T03:36:36.407+0000] {subprocess.py:93} INFO - 
[2025-08-06T03:36:36.408+0000] {subprocess.py:93} INFO - Example:
[2025-08-06T03:36:36.408+0000] {subprocess.py:93} INFO -     export GIT_PYTHON_REFRESH=quiet
[2025-08-06T03:36:36.409+0000] {subprocess.py:93} INFO - 
[2025-08-06T03:36:36.436+0000] {subprocess.py:93} INFO - 2025/08/06 03:36:36 WARNING mlflow.models.model: `artifact_path` is deprecated. Please use `name` instead.
[2025-08-06T03:36:42.804+0000] {subprocess.py:93} INFO - [31m2025/08/06 03:36:42 WARNING mlflow.models.model: Model logged without a signature and input example. Please set `input_example` parameter when logging the model to auto infer the model signature.[0m
[2025-08-06T03:36:43.030+0000] {subprocess.py:93} INFO - INFO:botocore.credentials:Found credentials in environment variables.
[2025-08-06T03:36:43.675+0000] {subprocess.py:93} INFO - Run ID: d2735dab2841449f83c88dd6f72b1603
[2025-08-06T03:36:43.676+0000] {subprocess.py:93} INFO - üèÉ View run suave-mare-343 at: http://mlflow:5000/#/experiments/1/runs/d2735dab2841449f83c88dd6f72b1603
[2025-08-06T03:36:43.678+0000] {subprocess.py:93} INFO - üß™ View experiment at: http://mlflow:5000/#/experiments/1
[2025-08-06T03:36:43.679+0000] {subprocess.py:93} INFO - Traceback (most recent call last):
[2025-08-06T03:36:43.681+0000] {subprocess.py:93} INFO -   File "/home/***/.local/lib/python3.12/site-packages/boto3/s3/transfer.py", line 371, in upload_file
[2025-08-06T03:36:43.682+0000] {subprocess.py:93} INFO -     future.result()
[2025-08-06T03:36:43.683+0000] {subprocess.py:93} INFO -   File "/home/***/.local/lib/python3.12/site-packages/s3transfer/futures.py", line 103, in result
[2025-08-06T03:36:43.684+0000] {subprocess.py:93} INFO -     return self._coordinator.result()
[2025-08-06T03:36:43.684+0000] {subprocess.py:93} INFO -            ^^^^^^^^^^^^^^^^^^^^^^^^^^
[2025-08-06T03:36:43.685+0000] {subprocess.py:93} INFO -   File "/home/***/.local/lib/python3.12/site-packages/s3transfer/futures.py", line 266, in result
[2025-08-06T03:36:43.686+0000] {subprocess.py:93} INFO -     raise self._exception
[2025-08-06T03:36:43.687+0000] {subprocess.py:93} INFO -   File "/home/***/.local/lib/python3.12/site-packages/s3transfer/tasks.py", line 139, in __call__
[2025-08-06T03:36:43.688+0000] {subprocess.py:93} INFO -     return self._execute_main(kwargs)
[2025-08-06T03:36:43.688+0000] {subprocess.py:93} INFO -            ^^^^^^^^^^^^^^^^^^^^^^^^^^
[2025-08-06T03:36:43.689+0000] {subprocess.py:93} INFO -   File "/home/***/.local/lib/python3.12/site-packages/s3transfer/tasks.py", line 162, in _execute_main
[2025-08-06T03:36:43.690+0000] {subprocess.py:93} INFO -     return_value = self._main(**kwargs)
[2025-08-06T03:36:43.690+0000] {subprocess.py:93} INFO -                    ^^^^^^^^^^^^^^^^^^^^
[2025-08-06T03:36:43.691+0000] {subprocess.py:93} INFO -   File "/home/***/.local/lib/python3.12/site-packages/s3transfer/upload.py", line 764, in _main
[2025-08-06T03:36:43.691+0000] {subprocess.py:93} INFO -     client.put_object(Bucket=bucket, Key=key, Body=body, **extra_args)
[2025-08-06T03:36:43.692+0000] {subprocess.py:93} INFO -   File "/home/***/.local/lib/python3.12/site-packages/botocore/client.py", line 553, in _api_call
[2025-08-06T03:36:43.693+0000] {subprocess.py:93} INFO -     return self._make_api_call(operation_name, kwargs)
[2025-08-06T03:36:43.693+0000] {subprocess.py:93} INFO -            ^^^^^^^^^^^^^^^^^^^^^^^^^^^^^^^^^^^^^^^^^^^
[2025-08-06T03:36:43.694+0000] {subprocess.py:93} INFO -   File "/home/***/.local/lib/python3.12/site-packages/botocore/client.py", line 1009, in _make_api_call
[2025-08-06T03:36:43.695+0000] {subprocess.py:93} INFO -     raise error_class(parsed_response, operation_name)
[2025-08-06T03:36:43.696+0000] {subprocess.py:93} INFO - botocore.errorfactory.NoSuchBucket: An error occurred (NoSuchBucket) when calling the PutObject operation: The specified bucket does not exist
[2025-08-06T03:36:43.697+0000] {subprocess.py:93} INFO - 
[2025-08-06T03:36:43.698+0000] {subprocess.py:93} INFO - During handling of the above exception, another exception occurred:
[2025-08-06T03:36:43.699+0000] {subprocess.py:93} INFO - 
[2025-08-06T03:36:43.700+0000] {subprocess.py:93} INFO - Traceback (most recent call last):
[2025-08-06T03:36:43.701+0000] {subprocess.py:93} INFO -   File "/opt/***/ml_pipeline/train/train_task.py", line 227, in <module>
[2025-08-06T03:36:43.702+0000] {subprocess.py:93} INFO -     main()
[2025-08-06T03:36:43.703+0000] {subprocess.py:93} INFO -   File "/opt/***/ml_pipeline/train/train_task.py", line 221, in main
[2025-08-06T03:36:43.704+0000] {subprocess.py:93} INFO -     register_model_with_mlflow(model, metrics)
[2025-08-06T03:36:43.705+0000] {subprocess.py:93} INFO -   File "/opt/***/ml_pipeline/train/train_task.py", line 145, in register_model_with_mlflow
[2025-08-06T03:36:43.706+0000] {subprocess.py:93} INFO -     mlflow.sklearn.log_model(model, artifact_path="model")
[2025-08-06T03:36:43.707+0000] {subprocess.py:93} INFO -   File "/home/***/.local/lib/python3.12/site-packages/mlflow/sklearn/__init__.py", line 426, in log_model
[2025-08-06T03:36:43.708+0000] {subprocess.py:93} INFO -     return Model.log(
[2025-08-06T03:36:43.709+0000] {subprocess.py:93} INFO -            ^^^^^^^^^^
[2025-08-06T03:36:43.710+0000] {subprocess.py:93} INFO -   File "/home/***/.local/lib/python3.12/site-packages/mlflow/models/model.py", line 1298, in log
[2025-08-06T03:36:43.711+0000] {subprocess.py:93} INFO -     client.log_model_artifacts(model.model_id, local_path)
[2025-08-06T03:36:43.711+0000] {subprocess.py:93} INFO -   File "/home/***/.local/lib/python3.12/site-packages/mlflow/tracking/client.py", line 5522, in log_model_artifacts
[2025-08-06T03:36:43.712+0000] {subprocess.py:93} INFO -     return self._tracking_client.log_model_artifacts(model_id, local_dir)
[2025-08-06T03:36:43.713+0000] {subprocess.py:93} INFO -            ^^^^^^^^^^^^^^^^^^^^^^^^^^^^^^^^^^^^^^^^^^^^^^^^^^^^^^^^^^^^^^
[2025-08-06T03:36:43.714+0000] {subprocess.py:93} INFO -   File "/home/***/.local/lib/python3.12/site-packages/mlflow/tracking/_tracking_service/client.py", line 881, in log_model_artifacts
[2025-08-06T03:36:43.715+0000] {subprocess.py:93} INFO -     self._get_artifact_repo(model_id, resource="logged_model").log_artifacts(local_dir)
[2025-08-06T03:36:43.715+0000] {subprocess.py:93} INFO -   File "/home/***/.local/lib/python3.12/site-packages/mlflow/store/artifact/s3_artifact_repo.py", line 286, in log_artifacts
[2025-08-06T03:36:43.716+0000] {subprocess.py:93} INFO -     self._upload_file(
[2025-08-06T03:36:43.717+0000] {subprocess.py:93} INFO -   File "/home/***/.local/lib/python3.12/site-packages/mlflow/store/artifact/s3_artifact_repo.py", line 234, in _upload_file
[2025-08-06T03:36:43.718+0000] {subprocess.py:93} INFO -     s3_client.upload_file(Filename=local_file, Bucket=bucket, Key=key, ExtraArgs=extra_args)
[2025-08-06T03:36:43.718+0000] {subprocess.py:93} INFO -   File "/home/***/.local/lib/python3.12/site-packages/boto3/s3/inject.py", line 145, in upload_file
[2025-08-06T03:36:43.719+0000] {subprocess.py:93} INFO -     return transfer.upload_file(
[2025-08-06T03:36:43.720+0000] {subprocess.py:93} INFO -            ^^^^^^^^^^^^^^^^^^^^^
[2025-08-06T03:36:43.721+0000] {subprocess.py:93} INFO -   File "/home/***/.local/lib/python3.12/site-packages/boto3/s3/transfer.py", line 377, in upload_file
[2025-08-06T03:36:43.721+0000] {subprocess.py:93} INFO -     raise S3UploadFailedError(
[2025-08-06T03:36:43.722+0000] {subprocess.py:93} INFO - boto3.exceptions.S3UploadFailedError: Failed to upload /tmp/tmpq157afce/model/requirements.txt to mlflow-artifacts/1/models/m-f85a0f4fbe624ef8b32b6c2451b77cf3/artifacts/requirements.txt: An error occurred (NoSuchBucket) when calling the PutObject operation: The specified bucket does not exist
[2025-08-06T03:36:44.201+0000] {subprocess.py:93} INFO - ERROR: failed to reproduce 'train': failed to run: python train/train_task.py, exited with 1
[2025-08-06T03:36:44.505+0000] {subprocess.py:97} INFO - Command exited with return code 255
[2025-08-06T03:36:44.506+0000] {taskinstance.py:441} INFO - ::group::Post task execution logs
[2025-08-06T03:36:44.521+0000] {taskinstance.py:2905} ERROR - Task failed with exception
Traceback (most recent call last):
  File "/home/airflow/.local/lib/python3.12/site-packages/airflow/models/taskinstance.py", line 465, in _execute_task
    result = _execute_callable(context=context, **execute_callable_kwargs)
             ^^^^^^^^^^^^^^^^^^^^^^^^^^^^^^^^^^^^^^^^^^^^^^^^^^^^^^^^^^^^^
  File "/home/airflow/.local/lib/python3.12/site-packages/airflow/models/taskinstance.py", line 432, in _execute_callable
    return execute_callable(context=context, **execute_callable_kwargs)
           ^^^^^^^^^^^^^^^^^^^^^^^^^^^^^^^^^^^^^^^^^^^^^^^^^^^^^^^^^^^^
  File "/home/airflow/.local/lib/python3.12/site-packages/airflow/models/baseoperator.py", line 400, in wrapper
    return func(self, *args, **kwargs)
           ^^^^^^^^^^^^^^^^^^^^^^^^^^^
  File "/home/airflow/.local/lib/python3.12/site-packages/airflow/operators/bash.py", line 243, in execute
    raise AirflowException(
airflow.exceptions.AirflowException: Bash command failed. The command returned a non-zero exit code 255.
[2025-08-06T03:36:44.529+0000] {taskinstance.py:1206} INFO - Marking task as UP_FOR_RETRY. dag_id=ml_pipeline_dvc, task_id=train_dvc, run_id=manual__2025-08-06T03:36:17.219079+00:00, execution_date=20250806T033617, start_date=20250806T033629, end_date=20250806T033644
[2025-08-06T03:36:44.550+0000] {standard_task_runner.py:110} ERROR - Failed to execute job 11 for task train_dvc (Bash command failed. The command returned a non-zero exit code 255.; 550)
[2025-08-06T03:36:44.581+0000] {local_task_job_runner.py:240} INFO - Task exited with return code 1
[2025-08-06T03:36:44.601+0000] {taskinstance.py:3498} INFO - 0 downstream tasks scheduled from follow-on schedule check
[2025-08-06T03:36:44.603+0000] {local_task_job_runner.py:222} INFO - ::endgroup::
