[2025-08-17T17:19:13.997+0000] {local_task_job_runner.py:120} INFO - ::group::Pre task execution logs
[2025-08-17T17:19:14.085+0000] {taskinstance.py:2076} INFO - Dependencies all met for dep_context=non-requeueable deps ti=<TaskInstance: ml_pipeline_dvc.ingest_dvc manual__2025-08-17T17:19:12.889595+00:00 [queued]>
[2025-08-17T17:19:14.107+0000] {taskinstance.py:2076} INFO - Dependencies all met for dep_context=requeueable deps ti=<TaskInstance: ml_pipeline_dvc.ingest_dvc manual__2025-08-17T17:19:12.889595+00:00 [queued]>
[2025-08-17T17:19:14.108+0000] {taskinstance.py:2306} INFO - Starting attempt 1 of 1
[2025-08-17T17:19:14.141+0000] {taskinstance.py:2330} INFO - Executing <Task(BashOperator): ingest_dvc> on 2025-08-17 17:19:12.889595+00:00
[2025-08-17T17:19:14.189+0000] {standard_task_runner.py:90} INFO - Running: ['***', 'tasks', 'run', 'ml_pipeline_dvc', 'ingest_dvc', 'manual__2025-08-17T17:19:12.889595+00:00', '--job-id', '298', '--raw', '--subdir', 'DAGS_FOLDER/train_pipeline_dag.py', '--cfg-path', '/tmp/tmpalqdcz44']
[2025-08-17T17:19:14.214+0000] {standard_task_runner.py:91} INFO - Job 298: Subtask ingest_dvc
[2025-08-17T17:19:14.203+0000] {warnings.py:110} WARNING - /home/***/.local/lib/python3.12/site-packages/***/task/task_runner/standard_task_runner.py:61: DeprecationWarning: This process (pid=318) is multi-threaded, use of fork() may lead to deadlocks in the child.
  pid = os.fork()

[2025-08-17T17:19:14.219+0000] {standard_task_runner.py:63} INFO - Started process 319 to run task
[2025-08-17T17:19:14.404+0000] {task_command.py:426} INFO - Running <TaskInstance: ml_pipeline_dvc.ingest_dvc manual__2025-08-17T17:19:12.889595+00:00 [running]> on host bea494a05fb4
[2025-08-17T17:19:14.715+0000] {taskinstance.py:2648} INFO - Exporting env vars: AIRFLOW_CTX_DAG_OWNER='yas' AIRFLOW_CTX_DAG_ID='ml_pipeline_dvc' AIRFLOW_CTX_TASK_ID='ingest_dvc' AIRFLOW_CTX_EXECUTION_DATE='2025-08-17T17:19:12.889595+00:00' AIRFLOW_CTX_TRY_NUMBER='1' AIRFLOW_CTX_DAG_RUN_ID='manual__2025-08-17T17:19:12.889595+00:00'
[2025-08-17T17:19:14.722+0000] {taskinstance.py:430} INFO - ::endgroup::
[2025-08-17T17:19:14.847+0000] {subprocess.py:63} INFO - Tmp dir root location: /tmp
[2025-08-17T17:19:14.850+0000] {subprocess.py:75} INFO - Running command: ['/usr/bin/bash', '-c', '\n            cd /opt/***/ml_pipeline \n            dvc repro ingest\n            dvc push\n        ']
[2025-08-17T17:19:14.882+0000] {subprocess.py:86} INFO - Output:
[2025-08-17T17:19:22.043+0000] {subprocess.py:93} INFO - Running stage 'ingest':
[2025-08-17T17:19:22.044+0000] {subprocess.py:93} INFO - > python ingest/etl_task.py && python ingest/download.py
[2025-08-17T17:19:27.095+0000] {subprocess.py:93} INFO - {"asctime": "2025-08-17 17:19:26,950", "levelname": "INFO", "name": "model_training", "trace_id": null, "span_id": null, "message": "AWS ENDPOINT is: http://minio:9000"}
[2025-08-17T17:19:27.113+0000] {subprocess.py:93} INFO - {"asctime": "2025-08-17 17:19:27,113", "levelname": "INFO", "name": "model_training", "trace_id": null, "span_id": null, "message": "Simulated data generated."}
[2025-08-17T17:19:27.197+0000] {subprocess.py:93} INFO - {"asctime": "2025-08-17 17:19:27,196", "levelname": "INFO", "name": "model_training", "trace_id": null, "span_id": null, "message": "Simulated data saved at s3://mlflow-artifacts/data/raw/fraud_data_v20250817_171927.csv."}
[2025-08-17T17:19:27.224+0000] {subprocess.py:93} INFO - {"asctime": "2025-08-17 17:19:27,224", "levelname": "INFO", "name": "model_training", "trace_id": null, "span_id": null, "message": "\u2705 Uploaded version_meta.json to s3://mlflow-artifacts/metadata/version_meta.json"}
[2025-08-17T17:19:27.256+0000] {subprocess.py:93} INFO - {"asctime": "2025-08-17 17:19:27,256", "levelname": "INFO", "name": "model_training", "trace_id": null, "span_id": null, "message": "Meta Version saved to: s3://mlflow-artifacts/data/raw/metadata_v20250817_171927.json"}
[2025-08-17T17:19:27.693+0000] {subprocess.py:93} INFO - python: can't open file '/opt/***/ml_pipeline/ingest/download.py': [Errno 2] No such file or directory
[2025-08-17T17:19:27.713+0000] {subprocess.py:93} INFO - ERROR: failed to reproduce 'ingest': failed to run: python ingest/etl_task.py && python ingest/download.py, exited with 2
[2025-08-17T17:19:32.101+0000] {subprocess.py:93} INFO - Everything is up to date.
[2025-08-17T17:19:32.458+0000] {subprocess.py:97} INFO - Command exited with return code 0
[2025-08-17T17:19:32.460+0000] {taskinstance.py:441} INFO - ::group::Post task execution logs
[2025-08-17T17:19:32.494+0000] {taskinstance.py:1206} INFO - Marking task as SUCCESS. dag_id=ml_pipeline_dvc, task_id=ingest_dvc, run_id=manual__2025-08-17T17:19:12.889595+00:00, execution_date=20250817T171912, start_date=20250817T171914, end_date=20250817T171932
[2025-08-17T17:19:32.555+0000] {local_task_job_runner.py:240} INFO - Task exited with return code 0
[2025-08-17T17:19:32.576+0000] {taskinstance.py:3498} INFO - 0 downstream tasks scheduled from follow-on schedule check
[2025-08-17T17:19:32.578+0000] {local_task_job_runner.py:222} INFO - ::endgroup::
