[2025-08-03T05:09:43.875+0000] {local_task_job_runner.py:120} INFO - ::group::Pre task execution logs
[2025-08-03T05:09:43.909+0000] {taskinstance.py:2076} INFO - Dependencies all met for dep_context=non-requeueable deps ti=<TaskInstance: daily_batch_inference.run_batch_inference manual__2025-08-03T05:04:35.088692+00:00 [queued]>
[2025-08-03T05:09:43.919+0000] {taskinstance.py:2076} INFO - Dependencies all met for dep_context=requeueable deps ti=<TaskInstance: daily_batch_inference.run_batch_inference manual__2025-08-03T05:04:35.088692+00:00 [queued]>
[2025-08-03T05:09:43.920+0000] {taskinstance.py:2306} INFO - Starting attempt 2 of 2
[2025-08-03T05:09:43.936+0000] {taskinstance.py:2330} INFO - Executing <Task(BashOperator): run_batch_inference> on 2025-08-03 05:04:35.088692+00:00
[2025-08-03T05:09:43.945+0000] {warnings.py:110} WARNING - /home/***/.local/lib/python3.12/site-packages/***/task/task_runner/standard_task_runner.py:61: DeprecationWarning: This process (pid=338) is multi-threaded, use of fork() may lead to deadlocks in the child.
  pid = os.fork()

[2025-08-03T05:09:43.947+0000] {standard_task_runner.py:90} INFO - Running: ['***', 'tasks', 'run', 'daily_batch_inference', 'run_batch_inference', 'manual__2025-08-03T05:04:35.088692+00:00', '--job-id', '107', '--raw', '--subdir', 'DAGS_FOLDER/batch_inference_dag.py', '--cfg-path', '/tmp/tmpd_wynwzj']
[2025-08-03T05:09:43.949+0000] {standard_task_runner.py:63} INFO - Started process 339 to run task
[2025-08-03T05:09:43.949+0000] {standard_task_runner.py:91} INFO - Job 107: Subtask run_batch_inference
[2025-08-03T05:09:44.013+0000] {task_command.py:426} INFO - Running <TaskInstance: daily_batch_inference.run_batch_inference manual__2025-08-03T05:04:35.088692+00:00 [running]> on host 0869a4a1051d
[2025-08-03T05:09:44.141+0000] {taskinstance.py:2648} INFO - Exporting env vars: AIRFLOW_CTX_DAG_OWNER='***' AIRFLOW_CTX_DAG_ID='daily_batch_inference' AIRFLOW_CTX_TASK_ID='run_batch_inference' AIRFLOW_CTX_EXECUTION_DATE='2025-08-03T05:04:35.088692+00:00' AIRFLOW_CTX_TRY_NUMBER='2' AIRFLOW_CTX_DAG_RUN_ID='manual__2025-08-03T05:04:35.088692+00:00'
[2025-08-03T05:09:44.143+0000] {taskinstance.py:430} INFO - ::endgroup::
[2025-08-03T05:09:44.182+0000] {subprocess.py:63} INFO - Tmp dir root location: /tmp
[2025-08-03T05:09:44.183+0000] {subprocess.py:75} INFO - Running command: ['/usr/bin/bash', '-c', 'cd /opt/***/ml_pipeline && python batch/batch_inference.py >> /opt/***/logs/batch_inference.log 2>&1']
[2025-08-03T05:09:44.198+0000] {subprocess.py:86} INFO - Output:
[2025-08-03T05:09:44.404+0000] {subprocess.py:97} INFO - Command exited with return code 2
[2025-08-03T05:09:44.406+0000] {taskinstance.py:441} INFO - ::group::Post task execution logs
[2025-08-03T05:09:44.431+0000] {taskinstance.py:2905} ERROR - Task failed with exception
Traceback (most recent call last):
  File "/home/airflow/.local/lib/python3.12/site-packages/airflow/models/taskinstance.py", line 465, in _execute_task
    result = _execute_callable(context=context, **execute_callable_kwargs)
             ^^^^^^^^^^^^^^^^^^^^^^^^^^^^^^^^^^^^^^^^^^^^^^^^^^^^^^^^^^^^^
  File "/home/airflow/.local/lib/python3.12/site-packages/airflow/models/taskinstance.py", line 432, in _execute_callable
    return execute_callable(context=context, **execute_callable_kwargs)
           ^^^^^^^^^^^^^^^^^^^^^^^^^^^^^^^^^^^^^^^^^^^^^^^^^^^^^^^^^^^^
  File "/home/airflow/.local/lib/python3.12/site-packages/airflow/models/baseoperator.py", line 400, in wrapper
    return func(self, *args, **kwargs)
           ^^^^^^^^^^^^^^^^^^^^^^^^^^^
  File "/home/airflow/.local/lib/python3.12/site-packages/airflow/operators/bash.py", line 243, in execute
    raise AirflowException(
airflow.exceptions.AirflowException: Bash command failed. The command returned a non-zero exit code 2.
[2025-08-03T05:09:44.442+0000] {taskinstance.py:1206} INFO - Marking task as FAILED. dag_id=daily_batch_inference, task_id=run_batch_inference, run_id=manual__2025-08-03T05:04:35.088692+00:00, execution_date=20250803T050435, start_date=20250803T050943, end_date=20250803T050944
[2025-08-03T05:09:44.464+0000] {standard_task_runner.py:110} ERROR - Failed to execute job 107 for task run_batch_inference (Bash command failed. The command returned a non-zero exit code 2.; 339)
[2025-08-03T05:09:44.500+0000] {local_task_job_runner.py:240} INFO - Task exited with return code 1
[2025-08-03T05:09:44.532+0000] {taskinstance.py:3498} INFO - 0 downstream tasks scheduled from follow-on schedule check
[2025-08-03T05:09:44.535+0000] {local_task_job_runner.py:222} INFO - ::endgroup::
