[2025-08-07T03:43:02.086+0000] {local_task_job_runner.py:120} INFO - ::group::Pre task execution logs
[2025-08-07T03:43:02.394+0000] {taskinstance.py:2076} INFO - Dependencies all met for dep_context=non-requeueable deps ti=<TaskInstance: register_high_latency_model.rollback_model manual__2025-08-07T03:37:52.071017+00:00 [queued]>
[2025-08-07T03:43:02.407+0000] {taskinstance.py:2076} INFO - Dependencies all met for dep_context=requeueable deps ti=<TaskInstance: register_high_latency_model.rollback_model manual__2025-08-07T03:37:52.071017+00:00 [queued]>
[2025-08-07T03:43:02.408+0000] {taskinstance.py:2306} INFO - Starting attempt 2 of 2
[2025-08-07T03:43:02.434+0000] {taskinstance.py:2330} INFO - Executing <Task(PythonOperator): rollback_model> on 2025-08-07 03:37:52.071017+00:00
[2025-08-07T03:43:02.453+0000] {warnings.py:110} WARNING - /home/***/.local/lib/python3.12/site-packages/***/task/task_runner/standard_task_runner.py:61: DeprecationWarning: This process (pid=4158) is multi-threaded, use of fork() may lead to deadlocks in the child.
  pid = os.fork()

[2025-08-07T03:43:02.457+0000] {standard_task_runner.py:63} INFO - Started process 4168 to run task
[2025-08-07T03:43:02.458+0000] {standard_task_runner.py:90} INFO - Running: ['***', 'tasks', 'run', 'register_high_latency_model', 'rollback_model', 'manual__2025-08-07T03:37:52.071017+00:00', '--job-id', '15', '--raw', '--subdir', 'DAGS_FOLDER/test_model_rollback.py', '--cfg-path', '/tmp/tmpx7zh7w9f']
[2025-08-07T03:43:02.464+0000] {standard_task_runner.py:91} INFO - Job 15: Subtask rollback_model
[2025-08-07T03:43:02.560+0000] {task_command.py:426} INFO - Running <TaskInstance: register_high_latency_model.rollback_model manual__2025-08-07T03:37:52.071017+00:00 [running]> on host 875a2765ee06
[2025-08-07T03:43:02.766+0000] {taskinstance.py:2648} INFO - Exporting env vars: AIRFLOW_CTX_DAG_OWNER='***' AIRFLOW_CTX_DAG_ID='register_high_latency_model' AIRFLOW_CTX_TASK_ID='rollback_model' AIRFLOW_CTX_EXECUTION_DATE='2025-08-07T03:37:52.071017+00:00' AIRFLOW_CTX_TRY_NUMBER='2' AIRFLOW_CTX_DAG_RUN_ID='manual__2025-08-07T03:37:52.071017+00:00'
[2025-08-07T03:43:02.768+0000] {taskinstance.py:430} INFO - ::endgroup::
[2025-08-07T03:43:02.954+0000] {logging_mixin.py:188} INFO - üì• Fetching latest production model version from registry...
[2025-08-07T03:43:02.957+0000] {warnings.py:110} WARNING - /opt/***/dags/test_model_rollback.py:57: FutureWarning: ``mlflow.tracking.client.MlflowClient.get_latest_versions`` is deprecated since 2.9.0. Model registry stages will be removed in a future major release. To learn more about the deprecation of model registry stages, see our migration guide here: https://mlflow.org/docs/latest/model-registry.html#migrating-from-stages
  prod_version = client.get_latest_versions(MODEL_NAME, stages=["Production"])[0]

[2025-08-07T03:43:03.083+0000] {logging_mixin.py:188} INFO - Using version: 1
[2025-08-07T03:43:03.231+0000] {logging_mixin.py:188} WARNING - 2025/08/07 03:43:03 WARNING mlflow.utils.git_utils: Failed to import Git (the Git executable is probably not on your PATH), so Git SHA is not available. Error: Failed to initialize: Bad git executable.
The git executable must be specified in one of the following ways:
    - be included in your $PATH
    - be set via $GIT_PYTHON_GIT_EXECUTABLE
    - explicitly set via git.refresh(<full-path-to-git-executable>)

All git commands will error until this is rectified.

This initial message can be silenced or aggravated in the future by setting the
$GIT_PYTHON_REFRESH environment variable. Use one of the following values:
    - quiet|q|silence|s|silent|none|n|0: for no message or exception
    - warn|w|warning|log|l|1: for a warning message (logging level CRITICAL, displayed by default)
    - error|e|exception|raise|r|2: for a raised exception

Example:
    export GIT_PYTHON_REFRESH=quiet
[2025-08-07T03:43:03.285+0000] {logging_mixin.py:188} WARNING - 2025/08/07 03:43:03 WARNING mlflow.models.model: `artifact_path` is deprecated. Please use `name` instead.
[2025-08-07T03:43:03.639+0000] {logging_mixin.py:188} INFO - üèÉ View run zealous-donkey-403 at: http://mlflow:5000/#/experiments/1/runs/6717bea86a6b4df1bc947ab43d52f4c3
[2025-08-07T03:43:03.641+0000] {logging_mixin.py:188} INFO - üß™ View experiment at: http://mlflow:5000/#/experiments/1
[2025-08-07T03:43:03.679+0000] {taskinstance.py:441} INFO - ::group::Post task execution logs
[2025-08-07T03:43:03.680+0000] {taskinstance.py:2905} ERROR - Task failed with exception
Traceback (most recent call last):
  File "/home/airflow/.local/lib/python3.12/site-packages/airflow/models/taskinstance.py", line 465, in _execute_task
    result = _execute_callable(context=context, **execute_callable_kwargs)
             ^^^^^^^^^^^^^^^^^^^^^^^^^^^^^^^^^^^^^^^^^^^^^^^^^^^^^^^^^^^^^
  File "/home/airflow/.local/lib/python3.12/site-packages/airflow/models/taskinstance.py", line 432, in _execute_callable
    return execute_callable(context=context, **execute_callable_kwargs)
           ^^^^^^^^^^^^^^^^^^^^^^^^^^^^^^^^^^^^^^^^^^^^^^^^^^^^^^^^^^^^
  File "/home/airflow/.local/lib/python3.12/site-packages/airflow/models/baseoperator.py", line 400, in wrapper
    return func(self, *args, **kwargs)
           ^^^^^^^^^^^^^^^^^^^^^^^^^^^
  File "/home/airflow/.local/lib/python3.12/site-packages/airflow/operators/python.py", line 235, in execute
    return_value = self.execute_callable()
                   ^^^^^^^^^^^^^^^^^^^^^^^
  File "/home/airflow/.local/lib/python3.12/site-packages/airflow/operators/python.py", line 252, in execute_callable
    return self.python_callable(*self.op_args, **self.op_kwargs)
           ^^^^^^^^^^^^^^^^^^^^^^^^^^^^^^^^^^^^^^^^^^^^^^^^^^^^^
  File "/opt/airflow/dags/test_model_rollback.py", line 63, in register_high_latency_model_from_latest_version
    mlflow.pyfunc.log_model(
  File "/home/airflow/.local/lib/python3.12/site-packages/mlflow/tracing/provider.py", line 465, in wrapper
    result = f(*args, **kwargs)
             ^^^^^^^^^^^^^^^^^^
  File "/home/airflow/.local/lib/python3.12/site-packages/mlflow/pyfunc/__init__.py", line 3602, in log_model
    return Model.log(
           ^^^^^^^^^^
  File "/home/airflow/.local/lib/python3.12/site-packages/mlflow/models/model.py", line 1214, in log
    flavor.save_model(path=local_path, mlflow_model=mlflow_model, **kwargs)
  File "/home/airflow/.local/lib/python3.12/site-packages/mlflow/tracing/provider.py", line 470, in wrapper
    result = f(*args, **kwargs)
             ^^^^^^^^^^^^^^^^^^
  File "/home/airflow/.local/lib/python3.12/site-packages/mlflow/pyfunc/__init__.py", line 3206, in save_model
    model_for_signature_inference.load_context(context)
  File "/opt/airflow/dags/test_model_rollback.py", line 34, in load_context
    self.pipeline = joblib.load(context.artifacts["original_model"])
                    ^^^^^^^^^^^^^^^^^^^^^^^^^^^^^^^^^^^^^^^^^^^^^^^^
  File "/home/airflow/.local/lib/python3.12/site-packages/joblib/numpy_pickle.py", line 735, in load
    with open(filename, "rb") as f:
         ^^^^^^^^^^^^^^^^^^^^
FileNotFoundError: [Errno 2] No such file or directory: 'models:/FraudDetectionModel/Production'
[2025-08-07T03:43:03.713+0000] {taskinstance.py:1206} INFO - Marking task as FAILED. dag_id=register_high_latency_model, task_id=rollback_model, run_id=manual__2025-08-07T03:37:52.071017+00:00, execution_date=20250807T033752, start_date=20250807T034302, end_date=20250807T034303
[2025-08-07T03:43:03.743+0000] {standard_task_runner.py:110} ERROR - Failed to execute job 15 for task rollback_model ([Errno 2] No such file or directory: 'models:/FraudDetectionModel/Production'; 4168)
[2025-08-07T03:43:03.790+0000] {local_task_job_runner.py:240} INFO - Task exited with return code 1
[2025-08-07T03:43:03.831+0000] {taskinstance.py:3498} INFO - 0 downstream tasks scheduled from follow-on schedule check
[2025-08-07T03:43:03.834+0000] {local_task_job_runner.py:222} INFO - ::endgroup::
