[2025-08-12T22:36:14.727+0000] {local_task_job_runner.py:120} INFO - ::group::Pre task execution logs
[2025-08-12T22:36:14.812+0000] {taskinstance.py:2076} INFO - Dependencies all met for dep_context=non-requeueable deps ti=<TaskInstance: ml_pipeline_dvc.preprocess_dvc manual__2025-08-12T22:36:11.467908+00:00 [queued]>
[2025-08-12T22:36:14.856+0000] {taskinstance.py:2076} INFO - Dependencies all met for dep_context=requeueable deps ti=<TaskInstance: ml_pipeline_dvc.preprocess_dvc manual__2025-08-12T22:36:11.467908+00:00 [queued]>
[2025-08-12T22:36:14.863+0000] {taskinstance.py:2306} INFO - Starting attempt 1 of 1
[2025-08-12T22:36:14.954+0000] {taskinstance.py:2330} INFO - Executing <Task(BashOperator): preprocess_dvc> on 2025-08-12 22:36:11.467908+00:00
[2025-08-12T22:36:14.972+0000] {warnings.py:110} WARNING - /home/***/.local/lib/python3.12/site-packages/***/task/task_runner/standard_task_runner.py:61: DeprecationWarning: This process (pid=704) is multi-threaded, use of fork() may lead to deadlocks in the child.
  pid = os.fork()

[2025-08-12T22:36:14.978+0000] {standard_task_runner.py:63} INFO - Started process 705 to run task
[2025-08-12T22:36:14.976+0000] {standard_task_runner.py:90} INFO - Running: ['***', 'tasks', 'run', 'ml_pipeline_dvc', 'preprocess_dvc', 'manual__2025-08-12T22:36:11.467908+00:00', '--job-id', '204', '--raw', '--subdir', 'DAGS_FOLDER/train_pipeline_dag.py', '--cfg-path', '/tmp/tmpc4riu_20']
[2025-08-12T22:36:14.980+0000] {standard_task_runner.py:91} INFO - Job 204: Subtask preprocess_dvc
[2025-08-12T22:36:15.093+0000] {task_command.py:426} INFO - Running <TaskInstance: ml_pipeline_dvc.preprocess_dvc manual__2025-08-12T22:36:11.467908+00:00 [running]> on host 276ab97d4dd8
[2025-08-12T22:36:15.345+0000] {taskinstance.py:2648} INFO - Exporting env vars: AIRFLOW_CTX_DAG_OWNER='yas' AIRFLOW_CTX_DAG_ID='ml_pipeline_dvc' AIRFLOW_CTX_TASK_ID='preprocess_dvc' AIRFLOW_CTX_EXECUTION_DATE='2025-08-12T22:36:11.467908+00:00' AIRFLOW_CTX_TRY_NUMBER='1' AIRFLOW_CTX_DAG_RUN_ID='manual__2025-08-12T22:36:11.467908+00:00'
[2025-08-12T22:36:15.347+0000] {taskinstance.py:430} INFO - ::endgroup::
[2025-08-12T22:36:15.379+0000] {subprocess.py:63} INFO - Tmp dir root location: /tmp
[2025-08-12T22:36:15.382+0000] {subprocess.py:75} INFO - Running command: ['/usr/bin/bash', '-c', 'cd /opt/***/ml_pipeline && dvc repro preprocess']
[2025-08-12T22:36:15.413+0000] {subprocess.py:86} INFO - Output:
[2025-08-12T22:36:17.568+0000] {subprocess.py:93} INFO - './dvc.yaml' validation failed.
[2025-08-12T22:36:17.572+0000] {subprocess.py:93} INFO - 
[2025-08-12T22:36:17.573+0000] {subprocess.py:93} INFO - extra keys not allowed, in stages -> preprocess -> cache, line 3, column 5
[2025-08-12T22:36:17.580+0000] {subprocess.py:93} INFO -    2   preprocess:
[2025-08-12T22:36:17.581+0000] {subprocess.py:93} INFO -    3 │   cmd: python preprocessing/preprocess_task.py
[2025-08-12T22:36:17.581+0000] {subprocess.py:93} INFO -    4 │   deps:
[2025-08-12T22:36:17.824+0000] {subprocess.py:97} INFO - Command exited with return code 255
[2025-08-12T22:36:17.825+0000] {taskinstance.py:441} INFO - ::group::Post task execution logs
[2025-08-12T22:36:17.841+0000] {taskinstance.py:2905} ERROR - Task failed with exception
Traceback (most recent call last):
  File "/home/airflow/.local/lib/python3.12/site-packages/airflow/models/taskinstance.py", line 465, in _execute_task
    result = _execute_callable(context=context, **execute_callable_kwargs)
             ^^^^^^^^^^^^^^^^^^^^^^^^^^^^^^^^^^^^^^^^^^^^^^^^^^^^^^^^^^^^^
  File "/home/airflow/.local/lib/python3.12/site-packages/airflow/models/taskinstance.py", line 432, in _execute_callable
    return execute_callable(context=context, **execute_callable_kwargs)
           ^^^^^^^^^^^^^^^^^^^^^^^^^^^^^^^^^^^^^^^^^^^^^^^^^^^^^^^^^^^^
  File "/home/airflow/.local/lib/python3.12/site-packages/airflow/models/baseoperator.py", line 400, in wrapper
    return func(self, *args, **kwargs)
           ^^^^^^^^^^^^^^^^^^^^^^^^^^^
  File "/home/airflow/.local/lib/python3.12/site-packages/airflow/operators/bash.py", line 243, in execute
    raise AirflowException(
airflow.exceptions.AirflowException: Bash command failed. The command returned a non-zero exit code 255.
[2025-08-12T22:36:17.848+0000] {taskinstance.py:1206} INFO - Marking task as FAILED. dag_id=ml_pipeline_dvc, task_id=preprocess_dvc, run_id=manual__2025-08-12T22:36:11.467908+00:00, execution_date=20250812T223611, start_date=20250812T223614, end_date=20250812T223617
[2025-08-12T22:36:17.870+0000] {standard_task_runner.py:110} ERROR - Failed to execute job 204 for task preprocess_dvc (Bash command failed. The command returned a non-zero exit code 255.; 705)
[2025-08-12T22:36:17.914+0000] {local_task_job_runner.py:240} INFO - Task exited with return code 1
[2025-08-12T22:36:17.954+0000] {taskinstance.py:3498} INFO - 0 downstream tasks scheduled from follow-on schedule check
[2025-08-12T22:36:17.960+0000] {local_task_job_runner.py:222} INFO - ::endgroup::
