[2025-08-05T19:50:22.834+0000] {local_task_job_runner.py:120} INFO - ::group::Pre task execution logs
[2025-08-05T19:50:22.875+0000] {taskinstance.py:2076} INFO - Dependencies all met for dep_context=non-requeueable deps ti=<TaskInstance: ml_pipeline_dvc.train_dvc manual__2025-08-05T19:50:09.502369+00:00 [queued]>
[2025-08-05T19:50:22.891+0000] {taskinstance.py:2076} INFO - Dependencies all met for dep_context=requeueable deps ti=<TaskInstance: ml_pipeline_dvc.train_dvc manual__2025-08-05T19:50:09.502369+00:00 [queued]>
[2025-08-05T19:50:22.892+0000] {taskinstance.py:2306} INFO - Starting attempt 1 of 2
[2025-08-05T19:50:22.912+0000] {taskinstance.py:2330} INFO - Executing <Task(BashOperator): train_dvc> on 2025-08-05 19:50:09.502369+00:00
[2025-08-05T19:50:22.923+0000] {warnings.py:110} WARNING - /home/***/.local/lib/python3.12/site-packages/***/task/task_runner/standard_task_runner.py:61: DeprecationWarning: This process (pid=1906) is multi-threaded, use of fork() may lead to deadlocks in the child.
  pid = os.fork()

[2025-08-05T19:50:22.926+0000] {standard_task_runner.py:90} INFO - Running: ['***', 'tasks', 'run', 'ml_pipeline_dvc', 'train_dvc', 'manual__2025-08-05T19:50:09.502369+00:00', '--job-id', '31', '--raw', '--subdir', 'DAGS_FOLDER/ml_pipeline_dag_2.py', '--cfg-path', '/tmp/tmpcnwxplbs']
[2025-08-05T19:50:22.927+0000] {standard_task_runner.py:63} INFO - Started process 1907 to run task
[2025-08-05T19:50:22.928+0000] {standard_task_runner.py:91} INFO - Job 31: Subtask train_dvc
[2025-08-05T19:50:23.014+0000] {task_command.py:426} INFO - Running <TaskInstance: ml_pipeline_dvc.train_dvc manual__2025-08-05T19:50:09.502369+00:00 [running]> on host cb274dbeb17b
[2025-08-05T19:50:23.165+0000] {taskinstance.py:2648} INFO - Exporting env vars: AIRFLOW_CTX_DAG_OWNER='yas' AIRFLOW_CTX_DAG_ID='ml_pipeline_dvc' AIRFLOW_CTX_TASK_ID='train_dvc' AIRFLOW_CTX_EXECUTION_DATE='2025-08-05T19:50:09.502369+00:00' AIRFLOW_CTX_TRY_NUMBER='1' AIRFLOW_CTX_DAG_RUN_ID='manual__2025-08-05T19:50:09.502369+00:00'
[2025-08-05T19:50:23.167+0000] {taskinstance.py:430} INFO - ::endgroup::
[2025-08-05T19:50:23.194+0000] {subprocess.py:63} INFO - Tmp dir root location: /tmp
[2025-08-05T19:50:23.196+0000] {subprocess.py:75} INFO - Running command: ['/usr/bin/bash', '-c', 'cd /opt/***/ml_pipeline && dvc repro train']
[2025-08-05T19:50:23.213+0000] {subprocess.py:86} INFO - Output:
[2025-08-05T19:50:25.349+0000] {subprocess.py:93} INFO - Stage 'preprocess' didn't change, skipping
[2025-08-05T19:50:25.485+0000] {subprocess.py:93} INFO - Running stage 'train':
[2025-08-05T19:50:25.486+0000] {subprocess.py:93} INFO - > python train/train_task.py
[2025-08-05T19:50:29.702+0000] {subprocess.py:93} INFO - INFO:__main__:Outlier detector saved to artifacts/models/outlier_detector_v20250801_144307.pkl
[2025-08-05T19:50:29.749+0000] {subprocess.py:93} INFO - /home/***/.local/lib/python3.12/site-packages/sklearn/metrics/_ranking.py:1201: UndefinedMetricWarning: No positive samples in y_true, true positive value should be meaningless
[2025-08-05T19:50:29.750+0000] {subprocess.py:93} INFO -   warnings.warn(
[2025-08-05T19:50:29.776+0000] {subprocess.py:93} INFO - INFO:__main__:üìÑ Training metadata saved to artifacts/train/train_metadata_v20250801_144307.json
[2025-08-05T19:50:29.778+0000] {subprocess.py:93} INFO - INFO:__main__:üì¶ Updated version_meta.json
[2025-08-05T19:50:30.166+0000] {subprocess.py:93} INFO - 2025/08/05 19:50:30 WARNING mlflow.utils.git_utils: Failed to import Git (the Git executable is probably not on your PATH), so Git SHA is not available. Error: Failed to initialize: Bad git executable.
[2025-08-05T19:50:30.167+0000] {subprocess.py:93} INFO - The git executable must be specified in one of the following ways:
[2025-08-05T19:50:30.167+0000] {subprocess.py:93} INFO -     - be included in your $PATH
[2025-08-05T19:50:30.169+0000] {subprocess.py:93} INFO -     - be set via $GIT_PYTHON_GIT_EXECUTABLE
[2025-08-05T19:50:30.176+0000] {subprocess.py:93} INFO -     - explicitly set via git.refresh(<full-path-to-git-executable>)
[2025-08-05T19:50:30.177+0000] {subprocess.py:93} INFO - 
[2025-08-05T19:50:30.178+0000] {subprocess.py:93} INFO - All git commands will error until this is rectified.
[2025-08-05T19:50:30.179+0000] {subprocess.py:93} INFO - 
[2025-08-05T19:50:30.180+0000] {subprocess.py:93} INFO - This initial message can be silenced or aggravated in the future by setting the
[2025-08-05T19:50:30.181+0000] {subprocess.py:93} INFO - $GIT_PYTHON_REFRESH environment variable. Use one of the following values:
[2025-08-05T19:50:30.182+0000] {subprocess.py:93} INFO -     - quiet|q|silence|s|silent|none|n|0: for no message or exception
[2025-08-05T19:50:30.183+0000] {subprocess.py:93} INFO -     - warn|w|warning|log|l|1: for a warning message (logging level CRITICAL, displayed by default)
[2025-08-05T19:50:30.184+0000] {subprocess.py:93} INFO -     - error|e|exception|raise|r|2: for a raised exception
[2025-08-05T19:50:30.184+0000] {subprocess.py:93} INFO - 
[2025-08-05T19:50:30.186+0000] {subprocess.py:93} INFO - Example:
[2025-08-05T19:50:30.187+0000] {subprocess.py:93} INFO -     export GIT_PYTHON_REFRESH=quiet
[2025-08-05T19:50:30.187+0000] {subprocess.py:93} INFO - 
[2025-08-05T19:50:30.207+0000] {subprocess.py:93} INFO - 2025/08/05 19:50:30 WARNING mlflow.models.model: `artifact_path` is deprecated. Please use `name` instead.
[2025-08-05T19:50:30.265+0000] {subprocess.py:93} INFO - üèÉ View run tasteful-skunk-859 at: http://mlflow:5000/#/experiments/2/runs/f3ca5f6325e34995939138eaa610c6a1
[2025-08-05T19:50:30.266+0000] {subprocess.py:93} INFO - üß™ View experiment at: http://mlflow:5000/#/experiments/2
[2025-08-05T19:50:30.267+0000] {subprocess.py:93} INFO - Traceback (most recent call last):
[2025-08-05T19:50:30.267+0000] {subprocess.py:93} INFO -   File "/opt/***/ml_pipeline/train/train_task.py", line 158, in <module>
[2025-08-05T19:50:30.268+0000] {subprocess.py:93} INFO -     main()
[2025-08-05T19:50:30.269+0000] {subprocess.py:93} INFO -   File "/opt/***/ml_pipeline/train/train_task.py", line 152, in main
[2025-08-05T19:50:30.270+0000] {subprocess.py:93} INFO -     register_model_with_mlflow(model, metrics)
[2025-08-05T19:50:30.271+0000] {subprocess.py:93} INFO -   File "/opt/***/ml_pipeline/train/train_task.py", line 125, in register_model_with_mlflow
[2025-08-05T19:50:30.271+0000] {subprocess.py:93} INFO -     mlflow.sklearn.log_model(model, "model", registered_model_name=MODEL_NAME)
[2025-08-05T19:50:30.272+0000] {subprocess.py:93} INFO -   File "/home/***/.local/lib/python3.12/site-packages/mlflow/sklearn/__init__.py", line 426, in log_model
[2025-08-05T19:50:30.273+0000] {subprocess.py:93} INFO -     return Model.log(
[2025-08-05T19:50:30.273+0000] {subprocess.py:93} INFO -            ^^^^^^^^^^
[2025-08-05T19:50:30.274+0000] {subprocess.py:93} INFO -   File "/home/***/.local/lib/python3.12/site-packages/mlflow/models/model.py", line 1166, in log
[2025-08-05T19:50:30.275+0000] {subprocess.py:93} INFO -     model = _create_logged_model(
[2025-08-05T19:50:30.275+0000] {subprocess.py:93} INFO -             ^^^^^^^^^^^^^^^^^^^^^
[2025-08-05T19:50:30.276+0000] {subprocess.py:93} INFO -   File "/home/***/.local/lib/python3.12/site-packages/mlflow/tracking/fluent.py", line 2282, in _create_logged_model
[2025-08-05T19:50:30.277+0000] {subprocess.py:93} INFO -     return MlflowClient()._create_logged_model(
[2025-08-05T19:50:30.277+0000] {subprocess.py:93} INFO -            ^^^^^^^^^^^^^^^^^^^^^^^^^^^^^^^^^^^^
[2025-08-05T19:50:30.278+0000] {subprocess.py:93} INFO -   File "/home/***/.local/lib/python3.12/site-packages/mlflow/tracking/client.py", line 5379, in _create_logged_model
[2025-08-05T19:50:30.279+0000] {subprocess.py:93} INFO -     return self._tracking_client.create_logged_model(
[2025-08-05T19:50:30.279+0000] {subprocess.py:93} INFO -            ^^^^^^^^^^^^^^^^^^^^^^^^^^^^^^^^^^^^^^^^^^
[2025-08-05T19:50:30.280+0000] {subprocess.py:93} INFO -   File "/home/***/.local/lib/python3.12/site-packages/mlflow/telemetry/track.py", line 22, in wrapper
[2025-08-05T19:50:30.281+0000] {subprocess.py:93} INFO -     return func(*args, **kwargs)
[2025-08-05T19:50:30.281+0000] {subprocess.py:93} INFO -            ^^^^^^^^^^^^^^^^^^^^^
[2025-08-05T19:50:30.282+0000] {subprocess.py:93} INFO -   File "/home/***/.local/lib/python3.12/site-packages/mlflow/tracking/_tracking_service/client.py", line 841, in create_logged_model
[2025-08-05T19:50:30.283+0000] {subprocess.py:93} INFO -     return self.store.create_logged_model(
[2025-08-05T19:50:30.283+0000] {subprocess.py:93} INFO -            ^^^^^^^^^^^^^^^^^^^^^^^^^^^^^^^
[2025-08-05T19:50:30.284+0000] {subprocess.py:93} INFO -   File "/home/***/.local/lib/python3.12/site-packages/mlflow/store/tracking/rest_store.py", line 823, in create_logged_model
[2025-08-05T19:50:30.284+0000] {subprocess.py:93} INFO -     response_proto = self._call_endpoint(CreateLoggedModel, req_body)
[2025-08-05T19:50:30.285+0000] {subprocess.py:93} INFO -                      ^^^^^^^^^^^^^^^^^^^^^^^^^^^^^^^^^^^^^^^^^^^^^^^^
[2025-08-05T19:50:30.286+0000] {subprocess.py:93} INFO -   File "/home/***/.local/lib/python3.12/site-packages/mlflow/store/tracking/rest_store.py", line 133, in _call_endpoint
[2025-08-05T19:50:30.286+0000] {subprocess.py:93} INFO -     return call_endpoint(
[2025-08-05T19:50:30.287+0000] {subprocess.py:93} INFO -            ^^^^^^^^^^^^^^
[2025-08-05T19:50:30.288+0000] {subprocess.py:93} INFO -   File "/home/***/.local/lib/python3.12/site-packages/mlflow/utils/rest_utils.py", line 553, in call_endpoint
[2025-08-05T19:50:30.289+0000] {subprocess.py:93} INFO -     response = verify_rest_response(response, endpoint)
[2025-08-05T19:50:30.289+0000] {subprocess.py:93} INFO -                ^^^^^^^^^^^^^^^^^^^^^^^^^^^^^^^^^^^^^^^^
[2025-08-05T19:50:30.290+0000] {subprocess.py:93} INFO -   File "/home/***/.local/lib/python3.12/site-packages/mlflow/utils/rest_utils.py", line 314, in verify_rest_response
[2025-08-05T19:50:30.291+0000] {subprocess.py:93} INFO -     raise MlflowException(
[2025-08-05T19:50:30.293+0000] {subprocess.py:93} INFO - mlflow.exceptions.MlflowException: API request to endpoint /api/2.0/mlflow/logged-models failed with error code 404 != 200. Response body: '<!doctype html>
[2025-08-05T19:50:30.294+0000] {subprocess.py:93} INFO - <html lang=en>
[2025-08-05T19:50:30.295+0000] {subprocess.py:93} INFO - <title>404 Not Found</title>
[2025-08-05T19:50:30.295+0000] {subprocess.py:93} INFO - <h1>Not Found</h1>
[2025-08-05T19:50:30.296+0000] {subprocess.py:93} INFO - <p>The requested URL was not found on the server. If you entered the URL manually please check your spelling and try again.</p>
[2025-08-05T19:50:30.297+0000] {subprocess.py:93} INFO - '
[2025-08-05T19:50:30.734+0000] {subprocess.py:93} INFO - ERROR: failed to reproduce 'train': failed to run: python train/train_task.py, exited with 1
[2025-08-05T19:50:31.162+0000] {subprocess.py:97} INFO - Command exited with return code 255
[2025-08-05T19:50:31.164+0000] {taskinstance.py:441} INFO - ::group::Post task execution logs
[2025-08-05T19:50:31.186+0000] {taskinstance.py:2905} ERROR - Task failed with exception
Traceback (most recent call last):
  File "/home/airflow/.local/lib/python3.12/site-packages/airflow/models/taskinstance.py", line 465, in _execute_task
    result = _execute_callable(context=context, **execute_callable_kwargs)
             ^^^^^^^^^^^^^^^^^^^^^^^^^^^^^^^^^^^^^^^^^^^^^^^^^^^^^^^^^^^^^
  File "/home/airflow/.local/lib/python3.12/site-packages/airflow/models/taskinstance.py", line 432, in _execute_callable
    return execute_callable(context=context, **execute_callable_kwargs)
           ^^^^^^^^^^^^^^^^^^^^^^^^^^^^^^^^^^^^^^^^^^^^^^^^^^^^^^^^^^^^
  File "/home/airflow/.local/lib/python3.12/site-packages/airflow/models/baseoperator.py", line 400, in wrapper
    return func(self, *args, **kwargs)
           ^^^^^^^^^^^^^^^^^^^^^^^^^^^
  File "/home/airflow/.local/lib/python3.12/site-packages/airflow/operators/bash.py", line 243, in execute
    raise AirflowException(
airflow.exceptions.AirflowException: Bash command failed. The command returned a non-zero exit code 255.
[2025-08-05T19:50:31.197+0000] {taskinstance.py:1206} INFO - Marking task as UP_FOR_RETRY. dag_id=ml_pipeline_dvc, task_id=train_dvc, run_id=manual__2025-08-05T19:50:09.502369+00:00, execution_date=20250805T195009, start_date=20250805T195022, end_date=20250805T195031
[2025-08-05T19:50:31.229+0000] {standard_task_runner.py:110} ERROR - Failed to execute job 31 for task train_dvc (Bash command failed. The command returned a non-zero exit code 255.; 1907)
[2025-08-05T19:50:31.250+0000] {local_task_job_runner.py:240} INFO - Task exited with return code 1
[2025-08-05T19:50:31.274+0000] {local_task_job_runner.py:222} INFO - ::endgroup::
