[2025-08-06T17:03:36.124+0000] {local_task_job_runner.py:120} INFO - ::group::Pre task execution logs
[2025-08-06T17:03:36.203+0000] {taskinstance.py:2076} INFO - Dependencies all met for dep_context=non-requeueable deps ti=<TaskInstance: register_high_latency_model.rollback_model manual__2025-08-06T17:03:28.434850+00:00 [queued]>
[2025-08-06T17:03:36.220+0000] {taskinstance.py:2076} INFO - Dependencies all met for dep_context=requeueable deps ti=<TaskInstance: register_high_latency_model.rollback_model manual__2025-08-06T17:03:28.434850+00:00 [queued]>
[2025-08-06T17:03:36.221+0000] {taskinstance.py:2306} INFO - Starting attempt 1 of 2
[2025-08-06T17:03:36.252+0000] {taskinstance.py:2330} INFO - Executing <Task(PythonOperator): rollback_model> on 2025-08-06 17:03:28.434850+00:00
[2025-08-06T17:03:36.278+0000] {warnings.py:110} WARNING - /home/***/.local/lib/python3.12/site-packages/***/task/task_runner/standard_task_runner.py:61: DeprecationWarning: This process (pid=643) is multi-threaded, use of fork() may lead to deadlocks in the child.
  pid = os.fork()

[2025-08-06T17:03:36.277+0000] {standard_task_runner.py:90} INFO - Running: ['***', 'tasks', 'run', 'register_high_latency_model', 'rollback_model', 'manual__2025-08-06T17:03:28.434850+00:00', '--job-id', '4', '--raw', '--subdir', 'DAGS_FOLDER/test_model_rollback.py', '--cfg-path', '/tmp/tmpapl9mjy2']
[2025-08-06T17:03:36.287+0000] {standard_task_runner.py:63} INFO - Started process 653 to run task
[2025-08-06T17:03:36.288+0000] {standard_task_runner.py:91} INFO - Job 4: Subtask rollback_model
[2025-08-06T17:03:36.561+0000] {task_command.py:426} INFO - Running <TaskInstance: register_high_latency_model.rollback_model manual__2025-08-06T17:03:28.434850+00:00 [running]> on host 36543e3c12b4
[2025-08-06T17:03:41.550+0000] {taskinstance.py:2648} INFO - Exporting env vars: AIRFLOW_CTX_DAG_OWNER='***' AIRFLOW_CTX_DAG_ID='register_high_latency_model' AIRFLOW_CTX_TASK_ID='rollback_model' AIRFLOW_CTX_EXECUTION_DATE='2025-08-06T17:03:28.434850+00:00' AIRFLOW_CTX_TRY_NUMBER='1' AIRFLOW_CTX_DAG_RUN_ID='manual__2025-08-06T17:03:28.434850+00:00'
[2025-08-06T17:03:41.553+0000] {taskinstance.py:430} INFO - ::endgroup::
[2025-08-06T17:03:42.812+0000] {logging_mixin.py:188} WARNING - 2025/08/06 17:03:42 INFO mlflow.tracking.fluent: Experiment with name 'FraudDetectionModel' does not exist. Creating a new experiment.
[2025-08-06T17:03:43.776+0000] {logging_mixin.py:188} WARNING - 2025/08/06 17:03:43 WARNING mlflow.utils.git_utils: Failed to import Git (the Git executable is probably not on your PATH), so Git SHA is not available. Error: Failed to initialize: Bad git executable.
The git executable must be specified in one of the following ways:
    - be included in your $PATH
    - be set via $GIT_PYTHON_GIT_EXECUTABLE
    - explicitly set via git.refresh(<full-path-to-git-executable>)

All git commands will error until this is rectified.

This initial message can be silenced or aggravated in the future by setting the
$GIT_PYTHON_REFRESH environment variable. Use one of the following values:
    - quiet|q|silence|s|silent|none|n|0: for no message or exception
    - warn|w|warning|log|l|1: for a warning message (logging level CRITICAL, displayed by default)
    - error|e|exception|raise|r|2: for a raised exception

Example:
    export GIT_PYTHON_REFRESH=quiet
[2025-08-06T17:03:43.860+0000] {logging_mixin.py:188} WARNING - 2025/08/06 17:03:43 WARNING mlflow.models.model: `artifact_path` is deprecated. Please use `name` instead.
[2025-08-06T17:04:03.966+0000] {logging_mixin.py:188} WARNING - 2025/08/06 17:04:03 WARNING mlflow.models.model: Model logged without a signature and input example. Please set `input_example` parameter when logging the model to auto infer the model signature.
[2025-08-06T17:04:07.605+0000] {logging_mixin.py:188} INFO - üèÉ View run rumbling-squid-140 at: http://mlflow:5000/#/experiments/3/runs/54463ba66c8943fcb198fb2e0712d826
[2025-08-06T17:04:07.606+0000] {logging_mixin.py:188} INFO - üß™ View experiment at: http://mlflow:5000/#/experiments/3
[2025-08-06T17:04:07.657+0000] {taskinstance.py:441} INFO - ::group::Post task execution logs
[2025-08-06T17:04:07.658+0000] {taskinstance.py:2905} ERROR - Task failed with exception
Traceback (most recent call last):
  File "/home/airflow/.local/lib/python3.12/site-packages/airflow/models/taskinstance.py", line 465, in _execute_task
    result = _execute_callable(context=context, **execute_callable_kwargs)
             ^^^^^^^^^^^^^^^^^^^^^^^^^^^^^^^^^^^^^^^^^^^^^^^^^^^^^^^^^^^^^
  File "/home/airflow/.local/lib/python3.12/site-packages/airflow/models/taskinstance.py", line 432, in _execute_callable
    return execute_callable(context=context, **execute_callable_kwargs)
           ^^^^^^^^^^^^^^^^^^^^^^^^^^^^^^^^^^^^^^^^^^^^^^^^^^^^^^^^^^^^
  File "/home/airflow/.local/lib/python3.12/site-packages/airflow/models/baseoperator.py", line 400, in wrapper
    return func(self, *args, **kwargs)
           ^^^^^^^^^^^^^^^^^^^^^^^^^^^
  File "/home/airflow/.local/lib/python3.12/site-packages/airflow/operators/python.py", line 235, in execute
    return_value = self.execute_callable()
                   ^^^^^^^^^^^^^^^^^^^^^^^
  File "/home/airflow/.local/lib/python3.12/site-packages/airflow/operators/python.py", line 252, in execute_callable
    return self.python_callable(*self.op_args, **self.op_kwargs)
           ^^^^^^^^^^^^^^^^^^^^^^^^^^^^^^^^^^^^^^^^^^^^^^^^^^^^^
  File "/opt/airflow/dags/test_model_rollback.py", line 55, in register_high_latency_model
    mlflow.sklearn.log_model(pipeline, artifact_path="model", registered_model_name="FraudDetectionModel")
  File "/home/airflow/.local/lib/python3.12/site-packages/mlflow/sklearn/__init__.py", line 426, in log_model
    return Model.log(
           ^^^^^^^^^^
  File "/home/airflow/.local/lib/python3.12/site-packages/mlflow/models/model.py", line 1298, in log
    client.log_model_artifacts(model.model_id, local_path)
  File "/home/airflow/.local/lib/python3.12/site-packages/mlflow/tracking/client.py", line 5522, in log_model_artifacts
    return self._tracking_client.log_model_artifacts(model_id, local_dir)
           ^^^^^^^^^^^^^^^^^^^^^^^^^^^^^^^^^^^^^^^^^^^^^^^^^^^^^^^^^^^^^^
  File "/home/airflow/.local/lib/python3.12/site-packages/mlflow/tracking/_tracking_service/client.py", line 881, in log_model_artifacts
    self._get_artifact_repo(model_id, resource="logged_model").log_artifacts(local_dir)
  File "/home/airflow/.local/lib/python3.12/site-packages/mlflow/store/artifact/s3_artifact_repo.py", line 286, in log_artifacts
    self._upload_file(
  File "/home/airflow/.local/lib/python3.12/site-packages/mlflow/store/artifact/s3_artifact_repo.py", line 234, in _upload_file
    s3_client.upload_file(Filename=local_file, Bucket=bucket, Key=key, ExtraArgs=extra_args)
  File "/home/airflow/.local/lib/python3.12/site-packages/boto3/s3/inject.py", line 145, in upload_file
    return transfer.upload_file(
           ^^^^^^^^^^^^^^^^^^^^^
  File "/home/airflow/.local/lib/python3.12/site-packages/boto3/s3/transfer.py", line 371, in upload_file
    future.result()
  File "/home/airflow/.local/lib/python3.12/site-packages/s3transfer/futures.py", line 103, in result
    return self._coordinator.result()
           ^^^^^^^^^^^^^^^^^^^^^^^^^^
  File "/home/airflow/.local/lib/python3.12/site-packages/s3transfer/futures.py", line 266, in result
    raise self._exception
  File "/home/airflow/.local/lib/python3.12/site-packages/s3transfer/tasks.py", line 139, in __call__
    return self._execute_main(kwargs)
           ^^^^^^^^^^^^^^^^^^^^^^^^^^
  File "/home/airflow/.local/lib/python3.12/site-packages/s3transfer/tasks.py", line 162, in _execute_main
    return_value = self._main(**kwargs)
                   ^^^^^^^^^^^^^^^^^^^^
  File "/home/airflow/.local/lib/python3.12/site-packages/s3transfer/upload.py", line 764, in _main
    client.put_object(Bucket=bucket, Key=key, Body=body, **extra_args)
  File "/home/airflow/.local/lib/python3.12/site-packages/botocore/client.py", line 553, in _api_call
    return self._make_api_call(operation_name, kwargs)
           ^^^^^^^^^^^^^^^^^^^^^^^^^^^^^^^^^^^^^^^^^^^
  File "/home/airflow/.local/lib/python3.12/site-packages/botocore/client.py", line 989, in _make_api_call
    http, parsed_response = self._make_request(
                            ^^^^^^^^^^^^^^^^^^^
  File "/home/airflow/.local/lib/python3.12/site-packages/botocore/client.py", line 1015, in _make_request
    return self._endpoint.make_request(operation_model, request_dict)
           ^^^^^^^^^^^^^^^^^^^^^^^^^^^^^^^^^^^^^^^^^^^^^^^^^^^^^^^^^^
  File "/home/airflow/.local/lib/python3.12/site-packages/botocore/endpoint.py", line 119, in make_request
    return self._send_request(request_dict, operation_model)
           ^^^^^^^^^^^^^^^^^^^^^^^^^^^^^^^^^^^^^^^^^^^^^^^^^
  File "/home/airflow/.local/lib/python3.12/site-packages/botocore/endpoint.py", line 198, in _send_request
    request = self.create_request(request_dict, operation_model)
              ^^^^^^^^^^^^^^^^^^^^^^^^^^^^^^^^^^^^^^^^^^^^^^^^^^
  File "/home/airflow/.local/lib/python3.12/site-packages/botocore/endpoint.py", line 134, in create_request
    self._event_emitter.emit(
  File "/home/airflow/.local/lib/python3.12/site-packages/botocore/hooks.py", line 412, in emit
    return self._emitter.emit(aliased_event_name, **kwargs)
           ^^^^^^^^^^^^^^^^^^^^^^^^^^^^^^^^^^^^^^^^^^^^^^^^
  File "/home/airflow/.local/lib/python3.12/site-packages/botocore/hooks.py", line 256, in emit
    return self._emit(event_name, kwargs)
           ^^^^^^^^^^^^^^^^^^^^^^^^^^^^^^
  File "/home/airflow/.local/lib/python3.12/site-packages/botocore/hooks.py", line 239, in _emit
    response = handler(**kwargs)
               ^^^^^^^^^^^^^^^^^
  File "/home/airflow/.local/lib/python3.12/site-packages/botocore/signers.py", line 105, in handler
    return self.sign(operation_name, request)
           ^^^^^^^^^^^^^^^^^^^^^^^^^^^^^^^^^^
  File "/home/airflow/.local/lib/python3.12/site-packages/botocore/signers.py", line 195, in sign
    auth.add_auth(request)
  File "/home/airflow/.local/lib/python3.12/site-packages/botocore/auth.py", line 418, in add_auth
    raise NoCredentialsError()
botocore.exceptions.NoCredentialsError: Unable to locate credentials
[2025-08-06T17:04:07.718+0000] {taskinstance.py:1206} INFO - Marking task as UP_FOR_RETRY. dag_id=register_high_latency_model, task_id=rollback_model, run_id=manual__2025-08-06T17:03:28.434850+00:00, execution_date=20250806T170328, start_date=20250806T170336, end_date=20250806T170407
[2025-08-06T17:04:07.752+0000] {standard_task_runner.py:110} ERROR - Failed to execute job 4 for task rollback_model (Unable to locate credentials; 653)
[2025-08-06T17:04:07.812+0000] {local_task_job_runner.py:240} INFO - Task exited with return code 1
[2025-08-06T17:04:07.842+0000] {taskinstance.py:3498} INFO - 0 downstream tasks scheduled from follow-on schedule check
[2025-08-06T17:04:07.847+0000] {local_task_job_runner.py:222} INFO - ::endgroup::
