[2025-08-12T18:58:43.929+0000] {local_task_job_runner.py:120} INFO - ::group::Pre task execution logs
[2025-08-12T18:58:43.961+0000] {taskinstance.py:2076} INFO - Dependencies all met for dep_context=non-requeueable deps ti=<TaskInstance: ml_pipeline_dvc.preprocess_dvc manual__2025-08-12T18:58:22.948127+00:00 [queued]>
[2025-08-12T18:58:43.971+0000] {taskinstance.py:2076} INFO - Dependencies all met for dep_context=requeueable deps ti=<TaskInstance: ml_pipeline_dvc.preprocess_dvc manual__2025-08-12T18:58:22.948127+00:00 [queued]>
[2025-08-12T18:58:43.972+0000] {taskinstance.py:2306} INFO - Starting attempt 1 of 2
[2025-08-12T18:58:43.989+0000] {taskinstance.py:2330} INFO - Executing <Task(BashOperator): preprocess_dvc> on 2025-08-12 18:58:22.948127+00:00
[2025-08-12T18:58:43.996+0000] {warnings.py:110} WARNING - /home/***/.local/lib/python3.12/site-packages/***/task/task_runner/standard_task_runner.py:61: DeprecationWarning: This process (pid=5521) is multi-threaded, use of fork() may lead to deadlocks in the child.
  pid = os.fork()

[2025-08-12T18:58:43.998+0000] {standard_task_runner.py:63} INFO - Started process 5538 to run task
[2025-08-12T18:58:43.998+0000] {standard_task_runner.py:90} INFO - Running: ['***', 'tasks', 'run', 'ml_pipeline_dvc', 'preprocess_dvc', 'manual__2025-08-12T18:58:22.948127+00:00', '--job-id', '150', '--raw', '--subdir', 'DAGS_FOLDER/train_pipeline_dag.py', '--cfg-path', '/tmp/tmp9qxo63nc']
[2025-08-12T18:58:44.000+0000] {standard_task_runner.py:91} INFO - Job 150: Subtask preprocess_dvc
[2025-08-12T18:58:44.079+0000] {task_command.py:426} INFO - Running <TaskInstance: ml_pipeline_dvc.preprocess_dvc manual__2025-08-12T18:58:22.948127+00:00 [running]> on host 08abdf02b345
[2025-08-12T18:58:44.251+0000] {taskinstance.py:2648} INFO - Exporting env vars: AIRFLOW_CTX_DAG_OWNER='yas' AIRFLOW_CTX_DAG_ID='ml_pipeline_dvc' AIRFLOW_CTX_TASK_ID='preprocess_dvc' AIRFLOW_CTX_EXECUTION_DATE='2025-08-12T18:58:22.948127+00:00' AIRFLOW_CTX_TRY_NUMBER='1' AIRFLOW_CTX_DAG_RUN_ID='manual__2025-08-12T18:58:22.948127+00:00'
[2025-08-12T18:58:44.255+0000] {taskinstance.py:430} INFO - ::endgroup::
[2025-08-12T18:58:44.272+0000] {subprocess.py:63} INFO - Tmp dir root location: /tmp
[2025-08-12T18:58:44.273+0000] {subprocess.py:75} INFO - Running command: ['/usr/bin/bash', '-c', 'cd /opt/***/ml_pipeline && dvc repro preprocess']
[2025-08-12T18:58:44.285+0000] {subprocess.py:86} INFO - Output:
[2025-08-12T18:58:48.490+0000] {subprocess.py:93} INFO - ERROR: failed to reproduce 'preprocess': Forbidden: An error occurred (403) when calling the HeadObject operation: Forbidden
[2025-08-12T18:58:48.951+0000] {subprocess.py:97} INFO - Command exited with return code 255
[2025-08-12T18:58:48.952+0000] {taskinstance.py:441} INFO - ::group::Post task execution logs
[2025-08-12T18:58:48.968+0000] {taskinstance.py:2905} ERROR - Task failed with exception
Traceback (most recent call last):
  File "/home/airflow/.local/lib/python3.12/site-packages/airflow/models/taskinstance.py", line 465, in _execute_task
    result = _execute_callable(context=context, **execute_callable_kwargs)
             ^^^^^^^^^^^^^^^^^^^^^^^^^^^^^^^^^^^^^^^^^^^^^^^^^^^^^^^^^^^^^
  File "/home/airflow/.local/lib/python3.12/site-packages/airflow/models/taskinstance.py", line 432, in _execute_callable
    return execute_callable(context=context, **execute_callable_kwargs)
           ^^^^^^^^^^^^^^^^^^^^^^^^^^^^^^^^^^^^^^^^^^^^^^^^^^^^^^^^^^^^
  File "/home/airflow/.local/lib/python3.12/site-packages/airflow/models/baseoperator.py", line 400, in wrapper
    return func(self, *args, **kwargs)
           ^^^^^^^^^^^^^^^^^^^^^^^^^^^
  File "/home/airflow/.local/lib/python3.12/site-packages/airflow/operators/bash.py", line 243, in execute
    raise AirflowException(
airflow.exceptions.AirflowException: Bash command failed. The command returned a non-zero exit code 255.
[2025-08-12T18:58:48.977+0000] {taskinstance.py:1206} INFO - Marking task as UP_FOR_RETRY. dag_id=ml_pipeline_dvc, task_id=preprocess_dvc, run_id=manual__2025-08-12T18:58:22.948127+00:00, execution_date=20250812T185822, start_date=20250812T185843, end_date=20250812T185848
[2025-08-12T18:58:48.997+0000] {standard_task_runner.py:110} ERROR - Failed to execute job 150 for task preprocess_dvc (Bash command failed. The command returned a non-zero exit code 255.; 5538)
[2025-08-12T18:58:49.019+0000] {local_task_job_runner.py:240} INFO - Task exited with return code 1
[2025-08-12T18:58:49.055+0000] {taskinstance.py:3498} INFO - 0 downstream tasks scheduled from follow-on schedule check
[2025-08-12T18:58:49.056+0000] {local_task_job_runner.py:222} INFO - ::endgroup::
