[2025-08-03T05:00:12.717+0000] {local_task_job_runner.py:120} INFO - ::group::Pre task execution logs
[2025-08-03T05:00:12.779+0000] {taskinstance.py:2076} INFO - Dependencies all met for dep_context=non-requeueable deps ti=<TaskInstance: daily_batch_inference.generate_batch_input manual__2025-08-03T05:00:10.518480+00:00 [queued]>
[2025-08-03T05:00:12.796+0000] {taskinstance.py:2076} INFO - Dependencies all met for dep_context=requeueable deps ti=<TaskInstance: daily_batch_inference.generate_batch_input manual__2025-08-03T05:00:10.518480+00:00 [queued]>
[2025-08-03T05:00:12.797+0000] {taskinstance.py:2306} INFO - Starting attempt 1 of 2
[2025-08-03T05:00:12.824+0000] {taskinstance.py:2330} INFO - Executing <Task(BashOperator): generate_batch_input> on 2025-08-03 05:00:10.518480+00:00
[2025-08-03T05:00:12.840+0000] {warnings.py:110} WARNING - /home/***/.local/lib/python3.12/site-packages/***/task/task_runner/standard_task_runner.py:61: DeprecationWarning: This process (pid=151) is multi-threaded, use of fork() may lead to deadlocks in the child.
  pid = os.fork()

[2025-08-03T05:00:12.844+0000] {standard_task_runner.py:63} INFO - Started process 152 to run task
[2025-08-03T05:00:12.843+0000] {standard_task_runner.py:90} INFO - Running: ['***', 'tasks', 'run', 'daily_batch_inference', 'generate_batch_input', 'manual__2025-08-03T05:00:10.518480+00:00', '--job-id', '97', '--raw', '--subdir', 'DAGS_FOLDER/batch_inference_dag.py', '--cfg-path', '/tmp/tmpnkc2xh9s']
[2025-08-03T05:00:12.849+0000] {standard_task_runner.py:91} INFO - Job 97: Subtask generate_batch_input
[2025-08-03T05:00:12.978+0000] {task_command.py:426} INFO - Running <TaskInstance: daily_batch_inference.generate_batch_input manual__2025-08-03T05:00:10.518480+00:00 [running]> on host 0869a4a1051d
[2025-08-03T05:00:13.167+0000] {taskinstance.py:2648} INFO - Exporting env vars: AIRFLOW_CTX_DAG_OWNER='***' AIRFLOW_CTX_DAG_ID='daily_batch_inference' AIRFLOW_CTX_TASK_ID='generate_batch_input' AIRFLOW_CTX_EXECUTION_DATE='2025-08-03T05:00:10.518480+00:00' AIRFLOW_CTX_TRY_NUMBER='1' AIRFLOW_CTX_DAG_RUN_ID='manual__2025-08-03T05:00:10.518480+00:00'
[2025-08-03T05:00:13.169+0000] {taskinstance.py:430} INFO - ::endgroup::
[2025-08-03T05:00:13.232+0000] {subprocess.py:63} INFO - Tmp dir root location: /tmp
[2025-08-03T05:00:13.244+0000] {subprocess.py:75} INFO - Running command: ['/usr/bin/bash', '-c', 'python /opt/***/ml_pipeline/batch/generate_batch_input.py']
[2025-08-03T05:00:13.303+0000] {subprocess.py:86} INFO - Output:
[2025-08-03T05:00:16.206+0000] {subprocess.py:93} INFO - Traceback (most recent call last):
[2025-08-03T05:00:16.223+0000] {subprocess.py:93} INFO -   File "/opt/***/ml_pipeline/batch/generate_batch_input.py", line 6, in <module>
[2025-08-03T05:00:16.226+0000] {subprocess.py:93} INFO -     with open("version_meta.json") as f:
[2025-08-03T05:00:16.229+0000] {subprocess.py:93} INFO -          ^^^^^^^^^^^^^^^^^^^^^^^^^
[2025-08-03T05:00:16.233+0000] {subprocess.py:93} INFO - FileNotFoundError: [Errno 2] No such file or directory: 'version_meta.json'
[2025-08-03T05:00:16.509+0000] {subprocess.py:97} INFO - Command exited with return code 1
[2025-08-03T05:00:16.512+0000] {taskinstance.py:441} INFO - ::group::Post task execution logs
[2025-08-03T05:00:16.543+0000] {taskinstance.py:2905} ERROR - Task failed with exception
Traceback (most recent call last):
  File "/home/airflow/.local/lib/python3.12/site-packages/airflow/models/taskinstance.py", line 465, in _execute_task
    result = _execute_callable(context=context, **execute_callable_kwargs)
             ^^^^^^^^^^^^^^^^^^^^^^^^^^^^^^^^^^^^^^^^^^^^^^^^^^^^^^^^^^^^^
  File "/home/airflow/.local/lib/python3.12/site-packages/airflow/models/taskinstance.py", line 432, in _execute_callable
    return execute_callable(context=context, **execute_callable_kwargs)
           ^^^^^^^^^^^^^^^^^^^^^^^^^^^^^^^^^^^^^^^^^^^^^^^^^^^^^^^^^^^^
  File "/home/airflow/.local/lib/python3.12/site-packages/airflow/models/baseoperator.py", line 400, in wrapper
    return func(self, *args, **kwargs)
           ^^^^^^^^^^^^^^^^^^^^^^^^^^^
  File "/home/airflow/.local/lib/python3.12/site-packages/airflow/operators/bash.py", line 243, in execute
    raise AirflowException(
airflow.exceptions.AirflowException: Bash command failed. The command returned a non-zero exit code 1.
[2025-08-03T05:00:16.559+0000] {taskinstance.py:1206} INFO - Marking task as UP_FOR_RETRY. dag_id=daily_batch_inference, task_id=generate_batch_input, run_id=manual__2025-08-03T05:00:10.518480+00:00, execution_date=20250803T050010, start_date=20250803T050012, end_date=20250803T050016
[2025-08-03T05:00:16.596+0000] {standard_task_runner.py:110} ERROR - Failed to execute job 97 for task generate_batch_input (Bash command failed. The command returned a non-zero exit code 1.; 152)
[2025-08-03T05:00:16.618+0000] {local_task_job_runner.py:240} INFO - Task exited with return code 1
[2025-08-03T05:00:16.707+0000] {taskinstance.py:3498} INFO - 0 downstream tasks scheduled from follow-on schedule check
[2025-08-03T05:00:16.715+0000] {local_task_job_runner.py:222} INFO - ::endgroup::
