[2025-08-12T18:36:59.749+0000] {local_task_job_runner.py:120} INFO - ::group::Pre task execution logs
[2025-08-12T18:36:59.888+0000] {taskinstance.py:2076} INFO - Dependencies all met for dep_context=non-requeueable deps ti=<TaskInstance: ml_pipeline_dvc.setup_dvc_remote manual__2025-08-12T18:36:56.821904+00:00 [queued]>
[2025-08-12T18:36:59.958+0000] {taskinstance.py:2076} INFO - Dependencies all met for dep_context=requeueable deps ti=<TaskInstance: ml_pipeline_dvc.setup_dvc_remote manual__2025-08-12T18:36:56.821904+00:00 [queued]>
[2025-08-12T18:36:59.965+0000] {taskinstance.py:2306} INFO - Starting attempt 1 of 2
[2025-08-12T18:37:00.053+0000] {taskinstance.py:2330} INFO - Executing <Task(BashOperator): setup_dvc_remote> on 2025-08-12 18:36:56.821904+00:00
[2025-08-12T18:37:00.069+0000] {warnings.py:110} WARNING - /home/***/.local/lib/python3.12/site-packages/***/task/task_runner/standard_task_runner.py:61: DeprecationWarning: This process (pid=4387) is multi-threaded, use of fork() may lead to deadlocks in the child.
  pid = os.fork()

[2025-08-12T18:37:00.074+0000] {standard_task_runner.py:63} INFO - Started process 4388 to run task
[2025-08-12T18:37:00.072+0000] {standard_task_runner.py:90} INFO - Running: ['***', 'tasks', 'run', 'ml_pipeline_dvc', 'setup_dvc_remote', 'manual__2025-08-12T18:36:56.821904+00:00', '--job-id', '141', '--raw', '--subdir', 'DAGS_FOLDER/train_pipeline_dag.py', '--cfg-path', '/tmp/tmp3y_ab8_t']
[2025-08-12T18:37:00.076+0000] {standard_task_runner.py:91} INFO - Job 141: Subtask setup_dvc_remote
[2025-08-12T18:37:00.219+0000] {task_command.py:426} INFO - Running <TaskInstance: ml_pipeline_dvc.setup_dvc_remote manual__2025-08-12T18:36:56.821904+00:00 [running]> on host 08abdf02b345
[2025-08-12T18:37:00.406+0000] {taskinstance.py:2648} INFO - Exporting env vars: AIRFLOW_CTX_DAG_OWNER='yas' AIRFLOW_CTX_DAG_ID='ml_pipeline_dvc' AIRFLOW_CTX_TASK_ID='setup_dvc_remote' AIRFLOW_CTX_EXECUTION_DATE='2025-08-12T18:36:56.821904+00:00' AIRFLOW_CTX_TRY_NUMBER='1' AIRFLOW_CTX_DAG_RUN_ID='manual__2025-08-12T18:36:56.821904+00:00'
[2025-08-12T18:37:00.408+0000] {taskinstance.py:430} INFO - ::endgroup::
[2025-08-12T18:37:00.459+0000] {subprocess.py:63} INFO - Tmp dir root location: /tmp
[2025-08-12T18:37:00.462+0000] {subprocess.py:75} INFO - Running command: ['/usr/bin/bash', '-c', '\n        cd /opt/***/ml_pipeline\n        export AWS_ACCESS_KEY_ID=minioadmin\n        export AWS_SECRET_ACCESS_KEY=minioadmin\n        export AWS_ENDPOINT_URL=http://minio:9000\n        dvc remote remove minio\n        dvc remote add -d minio s3://mlflow-artifacts\n        dvc remote modify minio endpointurl http://minio:9000\n        dvc remote modify minio access_key_id minioadmin\n        dvc remote modify minio secret_access_key minioadmin\n        dvc remote modify minio use_ssl false\n        ls -l .dvc/\n        dvc push --verbose\n        dvc repro preprocess -v\n        ']
[2025-08-12T18:37:00.484+0000] {subprocess.py:86} INFO - Output:
[2025-08-12T18:37:02.249+0000] {subprocess.py:93} INFO - ERROR: configuration error - config file error: expected 'url' for dictionary value @ data['remote']['minio']
[2025-08-12T18:37:03.822+0000] {subprocess.py:93} INFO - Setting 'minio' as a default remote.
[2025-08-12T18:37:12.313+0000] {subprocess.py:93} INFO - total 8
[2025-08-12T18:37:12.315+0000] {subprocess.py:93} INFO - drwxr-xr-x 10 default root 320 Aug  5 20:10 cache
[2025-08-12T18:37:12.319+0000] {subprocess.py:93} INFO - -rw-r--r--  1 default root 199 Aug 12 18:37 config
[2025-08-12T18:37:12.320+0000] {subprocess.py:93} INFO - -rw-r--r--  1 default root  86 Aug 12 17:15 config.local
[2025-08-12T18:37:12.321+0000] {subprocess.py:93} INFO - drwxr-xr-x  8 default root 256 Aug 11 22:52 tmp
[2025-08-12T18:37:13.510+0000] {subprocess.py:93} INFO - 2025-08-12 18:37:13,509 DEBUG: v3.61.0 (pip), CPython 3.12.3 on Linux-6.6.31-linuxkit-x86_64-with-glibc2.36
[2025-08-12T18:37:13.512+0000] {subprocess.py:93} INFO - 2025-08-12 18:37:13,510 DEBUG: command: /home/***/.local/bin/dvc push --verbose
[2025-08-12T18:37:14.879+0000] {subprocess.py:93} INFO - 2025-08-12 18:37:14,878 DEBUG: Lockfile 'dvc.lock' needs to be updated.
[2025-08-12T18:37:17.023+0000] {subprocess.py:93} INFO - Everything is up to date.
[2025-08-12T18:37:17.036+0000] {subprocess.py:93} INFO - 2025-08-12 18:37:17,035 DEBUG: Analytics is enabled.
[2025-08-12T18:37:17.269+0000] {subprocess.py:93} INFO - 2025-08-12 18:37:17,268 DEBUG: Trying to spawn ['daemon', 'analytics', '/tmp/tmp8gh77zvl', '-v']
[2025-08-12T18:37:17.296+0000] {subprocess.py:93} INFO - 2025-08-12 18:37:17,295 DEBUG: Spawned ['daemon', 'analytics', '/tmp/tmp8gh77zvl', '-v'] with pid 4633
[2025-08-12T18:37:19.761+0000] {subprocess.py:93} INFO - 2025-08-12 18:37:19,755 DEBUG: v3.61.0 (pip), CPython 3.12.3 on Linux-6.6.31-linuxkit-x86_64-with-glibc2.36
[2025-08-12T18:37:19.771+0000] {subprocess.py:93} INFO - 2025-08-12 18:37:19,760 DEBUG: command: /home/***/.local/bin/dvc repro preprocess -v
[2025-08-12T18:37:23.151+0000] {subprocess.py:93} INFO - 2025-08-12 18:37:23,151 DEBUG: Assuming 'preprocess' to be a stage inside 'dvc.yaml'
[2025-08-12T18:37:23.452+0000] {subprocess.py:93} INFO - 2025-08-12 18:37:23,452 DEBUG: Lockfile 'dvc.lock' needs to be updated.
[2025-08-12T18:37:32.427+0000] {subprocess.py:93} INFO - 2025-08-12 18:37:32,425 DEBUG: built tree 'object 602ddb43893d85443cd66ec20dfe4e77.dir'
[2025-08-12T18:37:33.347+0000] {subprocess.py:93} INFO - 2025-08-12 18:37:33,298 ERROR: failed to reproduce 'preprocess':
[2025-08-12T18:37:33.352+0000] {subprocess.py:93} INFO - Traceback (most recent call last):
[2025-08-12T18:37:33.353+0000] {subprocess.py:93} INFO -   File "/home/***/.local/lib/python3.12/site-packages/dvc/repo/reproduce.py", line 187, in _reproduce
[2025-08-12T18:37:33.360+0000] {subprocess.py:93} INFO -     ret = repro_fn(stage, upstream=upstream, force=force_stage, **kwargs)
[2025-08-12T18:37:33.364+0000] {subprocess.py:93} INFO -           ^^^^^^^^^^^^^^^^^^^^^^^^^^^^^^^^^^^^^^^^^^^^^^^^^^^^^^^^^^^^^^^
[2025-08-12T18:37:33.368+0000] {subprocess.py:93} INFO -   File "/home/***/.local/lib/python3.12/site-packages/dvc/repo/reproduce.py", line 117, in _reproduce_stage
[2025-08-12T18:37:33.370+0000] {subprocess.py:93} INFO -     ret = stage.reproduce(**kwargs)
[2025-08-12T18:37:33.372+0000] {subprocess.py:93} INFO -           ^^^^^^^^^^^^^^^^^^^^^^^^^
[2025-08-12T18:37:33.374+0000] {subprocess.py:93} INFO -   File "/home/***/.local/lib/python3.12/site-packages/funcy/decorators.py", line 47, in wrapper
[2025-08-12T18:37:33.377+0000] {subprocess.py:93} INFO -     return deco(call, *dargs, **dkwargs)
[2025-08-12T18:37:33.378+0000] {subprocess.py:93} INFO -            ^^^^^^^^^^^^^^^^^^^^^^^^^^^^^
[2025-08-12T18:37:33.379+0000] {subprocess.py:93} INFO -   File "/home/***/.local/lib/python3.12/site-packages/dvc/stage/decorators.py", line 44, in rwlocked
[2025-08-12T18:37:33.382+0000] {subprocess.py:93} INFO -     return call()
[2025-08-12T18:37:33.383+0000] {subprocess.py:93} INFO -            ^^^^^^
[2025-08-12T18:37:33.384+0000] {subprocess.py:93} INFO -   File "/home/***/.local/lib/python3.12/site-packages/funcy/decorators.py", line 68, in __call__
[2025-08-12T18:37:33.386+0000] {subprocess.py:93} INFO -     return self._func(*self._args, **self._kwargs)
[2025-08-12T18:37:33.388+0000] {subprocess.py:93} INFO -            ^^^^^^^^^^^^^^^^^^^^^^^^^^^^^^^^^^^^^^^
[2025-08-12T18:37:33.390+0000] {subprocess.py:93} INFO -   File "/home/***/.local/lib/python3.12/site-packages/dvc/stage/__init__.py", line 428, in reproduce
[2025-08-12T18:37:33.391+0000] {subprocess.py:93} INFO -     elif not self.changed(allow_missing, upstream):
[2025-08-12T18:37:33.392+0000] {subprocess.py:93} INFO -              ^^^^^^^^^^^^^^^^^^^^^^^^^^^^^^^^^^^^^
[2025-08-12T18:37:33.393+0000] {subprocess.py:93} INFO -   File "/home/***/.local/lib/python3.12/site-packages/funcy/decorators.py", line 47, in wrapper
[2025-08-12T18:37:33.398+0000] {subprocess.py:93} INFO -     return deco(call, *dargs, **dkwargs)
[2025-08-12T18:37:33.401+0000] {subprocess.py:93} INFO -            ^^^^^^^^^^^^^^^^^^^^^^^^^^^^^
[2025-08-12T18:37:33.404+0000] {subprocess.py:93} INFO -   File "/home/***/.local/lib/python3.12/site-packages/dvc/stage/decorators.py", line 44, in rwlocked
[2025-08-12T18:37:33.405+0000] {subprocess.py:93} INFO -     return call()
[2025-08-12T18:37:33.408+0000] {subprocess.py:93} INFO -            ^^^^^^
[2025-08-12T18:37:33.410+0000] {subprocess.py:93} INFO -   File "/home/***/.local/lib/python3.12/site-packages/funcy/decorators.py", line 68, in __call__
[2025-08-12T18:37:33.412+0000] {subprocess.py:93} INFO -     return self._func(*self._args, **self._kwargs)
[2025-08-12T18:37:33.415+0000] {subprocess.py:93} INFO -            ^^^^^^^^^^^^^^^^^^^^^^^^^^^^^^^^^^^^^^^
[2025-08-12T18:37:33.418+0000] {subprocess.py:93} INFO -   File "/home/***/.local/lib/python3.12/site-packages/dvc/stage/__init__.py", line 369, in changed
[2025-08-12T18:37:33.421+0000] {subprocess.py:93} INFO -     or self.changed_outs(allow_missing=allow_missing)
[2025-08-12T18:37:33.423+0000] {subprocess.py:93} INFO -        ^^^^^^^^^^^^^^^^^^^^^^^^^^^^^^^^^^^^^^^^^^^^^^
[2025-08-12T18:37:33.424+0000] {subprocess.py:93} INFO -   File "/home/***/.local/lib/python3.12/site-packages/funcy/decorators.py", line 47, in wrapper
[2025-08-12T18:37:33.426+0000] {subprocess.py:93} INFO -     return deco(call, *dargs, **dkwargs)
[2025-08-12T18:37:33.428+0000] {subprocess.py:93} INFO -            ^^^^^^^^^^^^^^^^^^^^^^^^^^^^^
[2025-08-12T18:37:33.429+0000] {subprocess.py:93} INFO -   File "/home/***/.local/lib/python3.12/site-packages/dvc/stage/decorators.py", line 44, in rwlocked
[2025-08-12T18:37:33.431+0000] {subprocess.py:93} INFO -     return call()
[2025-08-12T18:37:33.434+0000] {subprocess.py:93} INFO -            ^^^^^^
[2025-08-12T18:37:33.437+0000] {subprocess.py:93} INFO -   File "/home/***/.local/lib/python3.12/site-packages/funcy/decorators.py", line 68, in __call__
[2025-08-12T18:37:33.440+0000] {subprocess.py:93} INFO -     return self._func(*self._args, **self._kwargs)
[2025-08-12T18:37:33.442+0000] {subprocess.py:93} INFO -            ^^^^^^^^^^^^^^^^^^^^^^^^^^^^^^^^^^^^^^^
[2025-08-12T18:37:33.444+0000] {subprocess.py:93} INFO -   File "/home/***/.local/lib/python3.12/site-packages/dvc/stage/__init__.py", line 340, in changed_outs
[2025-08-12T18:37:33.445+0000] {subprocess.py:93} INFO -     status = out.status()
[2025-08-12T18:37:33.447+0000] {subprocess.py:93} INFO -              ^^^^^^^^^^^^
[2025-08-12T18:37:33.450+0000] {subprocess.py:93} INFO -   File "/home/***/.local/lib/python3.12/site-packages/dvc/output.py", line 633, in status
[2025-08-12T18:37:33.451+0000] {subprocess.py:93} INFO -     return self.workspace_status()
[2025-08-12T18:37:33.453+0000] {subprocess.py:93} INFO -            ^^^^^^^^^^^^^^^^^^^^^^^
[2025-08-12T18:37:33.454+0000] {subprocess.py:93} INFO -   File "/home/***/.local/lib/python3.12/site-packages/dvc/output.py", line 621, in workspace_status
[2025-08-12T18:37:33.456+0000] {subprocess.py:93} INFO -     if self.changed_checksum():
[2025-08-12T18:37:33.457+0000] {subprocess.py:93} INFO -        ^^^^^^^^^^^^^^^^^^^^^^^
[2025-08-12T18:37:33.459+0000] {subprocess.py:93} INFO -   File "/home/***/.local/lib/python3.12/site-packages/dvc/output.py", line 596, in changed_checksum
[2025-08-12T18:37:33.461+0000] {subprocess.py:93} INFO -     return self.hash_info != self.get_hash()
[2025-08-12T18:37:33.464+0000] {subprocess.py:93} INFO -                              ^^^^^^^^^^^^^^^
[2025-08-12T18:37:33.468+0000] {subprocess.py:93} INFO -   File "/home/***/.local/lib/python3.12/site-packages/dvc/output.py", line 532, in get_hash
[2025-08-12T18:37:33.470+0000] {subprocess.py:93} INFO -     _, hash_info = self._get_hash_meta()
[2025-08-12T18:37:33.471+0000] {subprocess.py:93} INFO -                    ^^^^^^^^^^^^^^^^^^^^^
[2025-08-12T18:37:33.472+0000] {subprocess.py:93} INFO -   File "/home/***/.local/lib/python3.12/site-packages/dvc/output.py", line 551, in _get_hash_meta
[2025-08-12T18:37:33.474+0000] {subprocess.py:93} INFO -     odb = self.cache
[2025-08-12T18:37:33.477+0000] {subprocess.py:93} INFO -           ^^^^^^^^^^
[2025-08-12T18:37:33.479+0000] {subprocess.py:93} INFO -   File "/home/***/.local/lib/python3.12/site-packages/dvc/output.py", line 513, in cache
[2025-08-12T18:37:33.483+0000] {subprocess.py:93} INFO -     assert self.is_in_repo
[2025-08-12T18:37:33.486+0000] {subprocess.py:93} INFO -            ^^^^^^^^^^^^^^^
[2025-08-12T18:37:33.488+0000] {subprocess.py:93} INFO - AssertionError
[2025-08-12T18:37:33.491+0000] {subprocess.py:93} INFO - 
[2025-08-12T18:37:33.494+0000] {subprocess.py:93} INFO - The above exception was the direct cause of the following exception:
[2025-08-12T18:37:33.496+0000] {subprocess.py:93} INFO - 
[2025-08-12T18:37:33.501+0000] {subprocess.py:93} INFO - Traceback (most recent call last):
[2025-08-12T18:37:33.504+0000] {subprocess.py:93} INFO -   File "/home/***/.local/lib/python3.12/site-packages/dvc/cli/__init__.py", line 211, in main
[2025-08-12T18:37:33.505+0000] {subprocess.py:93} INFO -     ret = cmd.do_run()
[2025-08-12T18:37:33.506+0000] {subprocess.py:93} INFO -           ^^^^^^^^^^^^
[2025-08-12T18:37:33.507+0000] {subprocess.py:93} INFO -   File "/home/***/.local/lib/python3.12/site-packages/dvc/cli/command.py", line 30, in do_run
[2025-08-12T18:37:33.509+0000] {subprocess.py:93} INFO -     return self.run()
[2025-08-12T18:37:33.510+0000] {subprocess.py:93} INFO -            ^^^^^^^^^^
[2025-08-12T18:37:33.511+0000] {subprocess.py:93} INFO -   File "/home/***/.local/lib/python3.12/site-packages/dvc/commands/repro.py", line 11, in run
[2025-08-12T18:37:33.513+0000] {subprocess.py:93} INFO -     stages = self.repo.reproduce(**self._common_kwargs, **self._repro_kwargs)
[2025-08-12T18:37:33.516+0000] {subprocess.py:93} INFO -              ^^^^^^^^^^^^^^^^^^^^^^^^^^^^^^^^^^^^^^^^^^^^^^^^^^^^^^^^^^^^^^^^
[2025-08-12T18:37:33.518+0000] {subprocess.py:93} INFO -   File "/home/***/.local/lib/python3.12/site-packages/dvc/repo/__init__.py", line 58, in wrapper
[2025-08-12T18:37:33.521+0000] {subprocess.py:93} INFO -     return f(repo, *args, **kwargs)
[2025-08-12T18:37:33.523+0000] {subprocess.py:93} INFO -            ^^^^^^^^^^^^^^^^^^^^^^^^
[2025-08-12T18:37:33.525+0000] {subprocess.py:93} INFO -   File "/home/***/.local/lib/python3.12/site-packages/dvc/repo/scm_context.py", line 143, in run
[2025-08-12T18:37:33.527+0000] {subprocess.py:93} INFO -     return method(repo, *args, **kw)
[2025-08-12T18:37:33.529+0000] {subprocess.py:93} INFO -            ^^^^^^^^^^^^^^^^^^^^^^^^^
[2025-08-12T18:37:33.533+0000] {subprocess.py:93} INFO -   File "/home/***/.local/lib/python3.12/site-packages/dvc/repo/reproduce.py", line 248, in reproduce
[2025-08-12T18:37:33.535+0000] {subprocess.py:93} INFO -     return _reproduce(steps, graph=graph, on_error=on_error or "fail", **kwargs)
[2025-08-12T18:37:33.537+0000] {subprocess.py:93} INFO -            ^^^^^^^^^^^^^^^^^^^^^^^^^^^^^^^^^^^^^^^^^^^^^^^^^^^^^^^^^^^^^^^^^^^^^
[2025-08-12T18:37:33.538+0000] {subprocess.py:93} INFO -   File "/home/***/.local/lib/python3.12/site-packages/dvc/repo/reproduce.py", line 191, in _reproduce
[2025-08-12T18:37:33.539+0000] {subprocess.py:93} INFO -     _raise_error(exc, stage)
[2025-08-12T18:37:33.540+0000] {subprocess.py:93} INFO -   File "/home/***/.local/lib/python3.12/site-packages/dvc/repo/reproduce.py", line 155, in _raise_error
[2025-08-12T18:37:33.541+0000] {subprocess.py:93} INFO -     raise ReproductionError(f"failed to reproduce{segment} {names}") from exc
[2025-08-12T18:37:33.543+0000] {subprocess.py:93} INFO - dvc.exceptions.ReproductionError: failed to reproduce 'preprocess'
[2025-08-12T18:37:33.544+0000] {subprocess.py:93} INFO - 
[2025-08-12T18:37:33.545+0000] {subprocess.py:93} INFO - 2025-08-12 18:37:33,359 DEBUG: Analytics is enabled.
[2025-08-12T18:37:33.802+0000] {subprocess.py:93} INFO - 2025-08-12 18:37:33,790 DEBUG: Trying to spawn ['daemon', 'analytics', '/tmp/tmpd2ca6s8v', '-v']
[2025-08-12T18:37:33.843+0000] {subprocess.py:93} INFO - 2025-08-12 18:37:33,840 DEBUG: Spawned ['daemon', 'analytics', '/tmp/tmpd2ca6s8v', '-v'] with pid 4702
[2025-08-12T18:37:34.864+0000] {subprocess.py:97} INFO - Command exited with return code 255
[2025-08-12T18:37:34.867+0000] {taskinstance.py:441} INFO - ::group::Post task execution logs
[2025-08-12T18:37:34.896+0000] {taskinstance.py:2905} ERROR - Task failed with exception
Traceback (most recent call last):
  File "/home/airflow/.local/lib/python3.12/site-packages/airflow/models/taskinstance.py", line 465, in _execute_task
    result = _execute_callable(context=context, **execute_callable_kwargs)
             ^^^^^^^^^^^^^^^^^^^^^^^^^^^^^^^^^^^^^^^^^^^^^^^^^^^^^^^^^^^^^
  File "/home/airflow/.local/lib/python3.12/site-packages/airflow/models/taskinstance.py", line 432, in _execute_callable
    return execute_callable(context=context, **execute_callable_kwargs)
           ^^^^^^^^^^^^^^^^^^^^^^^^^^^^^^^^^^^^^^^^^^^^^^^^^^^^^^^^^^^^
  File "/home/airflow/.local/lib/python3.12/site-packages/airflow/models/baseoperator.py", line 400, in wrapper
    return func(self, *args, **kwargs)
           ^^^^^^^^^^^^^^^^^^^^^^^^^^^
  File "/home/airflow/.local/lib/python3.12/site-packages/airflow/operators/bash.py", line 243, in execute
    raise AirflowException(
airflow.exceptions.AirflowException: Bash command failed. The command returned a non-zero exit code 255.
[2025-08-12T18:37:34.910+0000] {taskinstance.py:1206} INFO - Marking task as UP_FOR_RETRY. dag_id=ml_pipeline_dvc, task_id=setup_dvc_remote, run_id=manual__2025-08-12T18:36:56.821904+00:00, execution_date=20250812T183656, start_date=20250812T183659, end_date=20250812T183734
[2025-08-12T18:37:34.950+0000] {standard_task_runner.py:110} ERROR - Failed to execute job 141 for task setup_dvc_remote (Bash command failed. The command returned a non-zero exit code 255.; 4388)
[2025-08-12T18:37:34.984+0000] {local_task_job_runner.py:240} INFO - Task exited with return code 1
[2025-08-12T18:37:35.072+0000] {taskinstance.py:3498} INFO - 0 downstream tasks scheduled from follow-on schedule check
[2025-08-12T18:37:35.083+0000] {local_task_job_runner.py:222} INFO - ::endgroup::
