[2025-08-12T20:59:35.116+0000] {local_task_job_runner.py:120} INFO - ::group::Pre task execution logs
[2025-08-12T20:59:35.147+0000] {taskinstance.py:2076} INFO - Dependencies all met for dep_context=non-requeueable deps ti=<TaskInstance: ml_pipeline_dvc.preprocess_dvc manual__2025-08-12T20:54:09.469613+00:00 [queued]>
[2025-08-12T20:59:35.157+0000] {taskinstance.py:2076} INFO - Dependencies all met for dep_context=requeueable deps ti=<TaskInstance: ml_pipeline_dvc.preprocess_dvc manual__2025-08-12T20:54:09.469613+00:00 [queued]>
[2025-08-12T20:59:35.157+0000] {taskinstance.py:2306} INFO - Starting attempt 2 of 2
[2025-08-12T20:59:35.174+0000] {taskinstance.py:2330} INFO - Executing <Task(BashOperator): preprocess_dvc> on 2025-08-12 20:54:09.469613+00:00
[2025-08-12T20:59:35.181+0000] {warnings.py:110} WARNING - /home/***/.local/lib/python3.12/site-packages/***/task/task_runner/standard_task_runner.py:61: DeprecationWarning: This process (pid=1053) is multi-threaded, use of fork() may lead to deadlocks in the child.
  pid = os.fork()

[2025-08-12T20:59:35.184+0000] {standard_task_runner.py:63} INFO - Started process 1054 to run task
[2025-08-12T20:59:35.184+0000] {standard_task_runner.py:90} INFO - Running: ['***', 'tasks', 'run', 'ml_pipeline_dvc', 'preprocess_dvc', 'manual__2025-08-12T20:54:09.469613+00:00', '--job-id', '173', '--raw', '--subdir', 'DAGS_FOLDER/train_pipeline_dag.py', '--cfg-path', '/tmp/tmpa1xi3by_']
[2025-08-12T20:59:35.185+0000] {standard_task_runner.py:91} INFO - Job 173: Subtask preprocess_dvc
[2025-08-12T20:59:35.249+0000] {task_command.py:426} INFO - Running <TaskInstance: ml_pipeline_dvc.preprocess_dvc manual__2025-08-12T20:54:09.469613+00:00 [running]> on host 134dd3b4dfb6
[2025-08-12T20:59:35.394+0000] {taskinstance.py:2648} INFO - Exporting env vars: AIRFLOW_CTX_DAG_OWNER='yas' AIRFLOW_CTX_DAG_ID='ml_pipeline_dvc' AIRFLOW_CTX_TASK_ID='preprocess_dvc' AIRFLOW_CTX_EXECUTION_DATE='2025-08-12T20:54:09.469613+00:00' AIRFLOW_CTX_TRY_NUMBER='2' AIRFLOW_CTX_DAG_RUN_ID='manual__2025-08-12T20:54:09.469613+00:00'
[2025-08-12T20:59:35.396+0000] {taskinstance.py:430} INFO - ::endgroup::
[2025-08-12T20:59:35.413+0000] {subprocess.py:63} INFO - Tmp dir root location: /tmp
[2025-08-12T20:59:35.414+0000] {subprocess.py:75} INFO - Running command: ['/usr/bin/bash', '-c', '\n        cd /opt/***/ml_pipeline\n        aws --endpoint-url http://minio:9000 s3 ls s3://mlflow-artifacts\n        dvc remote remove minio || true\n        dvc remote add -d minio s3://mlflow-artifacts\n        dvc remote modify minio endpointurl http://minio:9000\n        dvc remote modify minio access_key_id minioadmin\n        dvc remote modify minio secret_access_key minioadmin\n        dvc remote modify minio use_ssl false\n        export AWS_ACCESS_KEY_ID=minioadmin\n        export AWS_SECRET_ACCESS_KEY=minioadmin\n        export AWS_ENDPOINT_URL=http://minio:9000\n        dvc push --verbose\n        cd /opt/***/ml_pipeline && dvc repro preprocess\n        ']
[2025-08-12T20:59:35.428+0000] {subprocess.py:86} INFO - Output:
[2025-08-12T20:59:36.653+0000] {subprocess.py:93} INFO -                            PRE data/
[2025-08-12T20:59:36.654+0000] {subprocess.py:93} INFO -                            PRE metadata/
[2025-08-12T20:59:36.655+0000] {subprocess.py:93} INFO -                            PRE preprocess/
[2025-08-12T20:59:37.753+0000] {subprocess.py:93} INFO - ERROR: configuration error - config file error: expected 'url' for dictionary value @ data['remote']['minio']
[2025-08-12T20:59:39.201+0000] {subprocess.py:93} INFO - Setting 'minio' as a default remote.
[2025-08-12T20:59:46.193+0000] {subprocess.py:93} INFO - 2025-08-12 20:59:46,193 DEBUG: v3.61.0 (pip), CPython 3.12.3 on Linux-6.6.31-linuxkit-x86_64-with-glibc2.36
[2025-08-12T20:59:46.194+0000] {subprocess.py:93} INFO - 2025-08-12 20:59:46,193 DEBUG: command: /home/***/.local/bin/dvc push --verbose
[2025-08-12T20:59:46.967+0000] {subprocess.py:93} INFO - 2025-08-12 20:59:46,967 DEBUG: Lockfile 'dvc.lock' needs to be updated.
[2025-08-12T20:59:48.040+0000] {subprocess.py:93} INFO - Everything is up to date.
[2025-08-12T20:59:48.046+0000] {subprocess.py:93} INFO - 2025-08-12 20:59:48,046 DEBUG: Analytics is enabled.
[2025-08-12T20:59:48.109+0000] {subprocess.py:93} INFO - 2025-08-12 20:59:48,109 DEBUG: Trying to spawn ['daemon', 'analytics', '/tmp/tmpqxmd28tb', '-v']
[2025-08-12T20:59:48.119+0000] {subprocess.py:93} INFO - 2025-08-12 20:59:48,118 DEBUG: Spawned ['daemon', 'analytics', '/tmp/tmpqxmd28tb', '-v'] with pid 1189
[2025-08-12T20:59:52.508+0000] {subprocess.py:93} INFO - Running stage 'preprocess':
[2025-08-12T20:59:52.509+0000] {subprocess.py:93} INFO - > python preprocessing/preprocess_task.py
[2025-08-12T20:59:55.180+0000] {subprocess.py:93} INFO - {"asctime": "2025-08-12 20:59:55,056", "levelname": "INFO", "name": "preprocessing_pipeline", "trace_id": null, "span_id": null, "message": "version_meta.json loaded!"}
[2025-08-12T20:59:55.232+0000] {subprocess.py:93} INFO - {"asctime": "2025-08-12 20:59:55,232", "levelname": "INFO", "name": "preprocessing_pipeline", "trace_id": null, "span_id": null, "message": "preprocessor trained!"}
[2025-08-12T20:59:55.266+0000] {subprocess.py:93} INFO - {"asctime": "2025-08-12 20:59:55,265", "levelname": "INFO", "name": "preprocessing_pipeline", "trace_id": null, "span_id": null, "message": "preprocessor saved to s3://mlflow-artifacts/preprocess/v20250812_203000/pipeline.pkl!"}
[2025-08-12T20:59:55.311+0000] {subprocess.py:93} INFO - {"asctime": "2025-08-12 20:59:55,310", "levelname": "INFO", "name": "preprocessing_pipeline", "trace_id": null, "span_id": null, "message": "\u2705 Saved pipeline at: s3://mlflow-artifacts/s3://mlflow-artifacts/preprocess/v20250812_203000/pipeline.pkl"}
[2025-08-12T20:59:55.313+0000] {subprocess.py:93} INFO - {"asctime": "2025-08-12 20:59:55,311", "levelname": "INFO", "name": "preprocessing_pipeline", "trace_id": null, "span_id": null, "message": "\ud83d\udcc4 Saved metadata: s3://mlflow-artifacts/s3://mlflow-artifacts/preprocess/v20250812_203000/preprocess_metadata.json"}
[2025-08-12T20:59:55.314+0000] {subprocess.py:93} INFO - {"asctime": "2025-08-12 20:59:55,311", "levelname": "INFO", "name": "preprocessing_pipeline", "trace_id": null, "span_id": null, "message": "\ud83d\udce6 Updated version_meta.json"}
[2025-08-12T20:59:55.852+0000] {subprocess.py:93} INFO - ERROR: failed to reproduce 'preprocess': Saving cached external output s3://mlflow-artifacts/preprocess/v20250812_203000/pipeline.pkl is not supported since DVC 3.0. See <https://dvc.org/doc/user-guide/upgrade> for more info.
[2025-08-12T20:59:56.493+0000] {subprocess.py:97} INFO - Command exited with return code 255
[2025-08-12T20:59:56.495+0000] {taskinstance.py:441} INFO - ::group::Post task execution logs
[2025-08-12T20:59:56.514+0000] {taskinstance.py:2905} ERROR - Task failed with exception
Traceback (most recent call last):
  File "/home/airflow/.local/lib/python3.12/site-packages/airflow/models/taskinstance.py", line 465, in _execute_task
    result = _execute_callable(context=context, **execute_callable_kwargs)
             ^^^^^^^^^^^^^^^^^^^^^^^^^^^^^^^^^^^^^^^^^^^^^^^^^^^^^^^^^^^^^
  File "/home/airflow/.local/lib/python3.12/site-packages/airflow/models/taskinstance.py", line 432, in _execute_callable
    return execute_callable(context=context, **execute_callable_kwargs)
           ^^^^^^^^^^^^^^^^^^^^^^^^^^^^^^^^^^^^^^^^^^^^^^^^^^^^^^^^^^^^
  File "/home/airflow/.local/lib/python3.12/site-packages/airflow/models/baseoperator.py", line 400, in wrapper
    return func(self, *args, **kwargs)
           ^^^^^^^^^^^^^^^^^^^^^^^^^^^
  File "/home/airflow/.local/lib/python3.12/site-packages/airflow/operators/bash.py", line 243, in execute
    raise AirflowException(
airflow.exceptions.AirflowException: Bash command failed. The command returned a non-zero exit code 255.
[2025-08-12T20:59:56.522+0000] {taskinstance.py:1206} INFO - Marking task as FAILED. dag_id=ml_pipeline_dvc, task_id=preprocess_dvc, run_id=manual__2025-08-12T20:54:09.469613+00:00, execution_date=20250812T205409, start_date=20250812T205935, end_date=20250812T205956
[2025-08-12T20:59:56.550+0000] {standard_task_runner.py:110} ERROR - Failed to execute job 173 for task preprocess_dvc (Bash command failed. The command returned a non-zero exit code 255.; 1054)
[2025-08-12T20:59:56.593+0000] {local_task_job_runner.py:240} INFO - Task exited with return code 1
[2025-08-12T20:59:56.635+0000] {taskinstance.py:3498} INFO - 0 downstream tasks scheduled from follow-on schedule check
[2025-08-12T20:59:56.641+0000] {local_task_job_runner.py:222} INFO - ::endgroup::
