[2025-08-11T19:47:50.491+0000] {local_task_job_runner.py:120} INFO - ::group::Pre task execution logs
[2025-08-11T19:47:50.527+0000] {taskinstance.py:2076} INFO - Dependencies all met for dep_context=non-requeueable deps ti=<TaskInstance: ml_pipeline_dvc.preprocess_dvc manual__2025-08-11T19:42:33.813103+00:00 [queued]>
[2025-08-11T19:47:50.538+0000] {taskinstance.py:2076} INFO - Dependencies all met for dep_context=requeueable deps ti=<TaskInstance: ml_pipeline_dvc.preprocess_dvc manual__2025-08-11T19:42:33.813103+00:00 [queued]>
[2025-08-11T19:47:50.539+0000] {taskinstance.py:2306} INFO - Starting attempt 2 of 2
[2025-08-11T19:47:50.558+0000] {taskinstance.py:2330} INFO - Executing <Task(BashOperator): preprocess_dvc> on 2025-08-11 19:42:33.813103+00:00
[2025-08-11T19:47:50.565+0000] {warnings.py:110} WARNING - /home/***/.local/lib/python3.12/site-packages/***/task/task_runner/standard_task_runner.py:61: DeprecationWarning: This process (pid=3621) is multi-threaded, use of fork() may lead to deadlocks in the child.
  pid = os.fork()

[2025-08-11T19:47:50.568+0000] {standard_task_runner.py:63} INFO - Started process 3622 to run task
[2025-08-11T19:47:50.567+0000] {standard_task_runner.py:90} INFO - Running: ['***', 'tasks', 'run', 'ml_pipeline_dvc', 'preprocess_dvc', 'manual__2025-08-11T19:42:33.813103+00:00', '--job-id', '63', '--raw', '--subdir', 'DAGS_FOLDER/train_pipeline_dag.py', '--cfg-path', '/tmp/tmp3f_djuuk']
[2025-08-11T19:47:50.569+0000] {standard_task_runner.py:91} INFO - Job 63: Subtask preprocess_dvc
[2025-08-11T19:47:50.633+0000] {task_command.py:426} INFO - Running <TaskInstance: ml_pipeline_dvc.preprocess_dvc manual__2025-08-11T19:42:33.813103+00:00 [running]> on host 631cb2647807
[2025-08-11T19:47:50.742+0000] {taskinstance.py:2648} INFO - Exporting env vars: AIRFLOW_CTX_DAG_OWNER='yas' AIRFLOW_CTX_DAG_ID='ml_pipeline_dvc' AIRFLOW_CTX_TASK_ID='preprocess_dvc' AIRFLOW_CTX_EXECUTION_DATE='2025-08-11T19:42:33.813103+00:00' AIRFLOW_CTX_TRY_NUMBER='2' AIRFLOW_CTX_DAG_RUN_ID='manual__2025-08-11T19:42:33.813103+00:00'
[2025-08-11T19:47:50.744+0000] {taskinstance.py:430} INFO - ::endgroup::
[2025-08-11T19:47:50.765+0000] {subprocess.py:63} INFO - Tmp dir root location: /tmp
[2025-08-11T19:47:50.766+0000] {subprocess.py:75} INFO - Running command: ['/usr/bin/bash', '-c', 'cd /opt/***/ml_pipeline && dvc repro preprocess']
[2025-08-11T19:47:50.779+0000] {subprocess.py:86} INFO - Output:
[2025-08-11T19:47:55.449+0000] {subprocess.py:93} INFO - ERROR: failed to reproduce 'preprocess': The AWS Access Key Id you provided does not exist in our records.: An error occurred (InvalidAccessKeyId) when calling the ListObjectsV2 operation: The AWS Access Key Id you provided does not exist in our records.
[2025-08-11T19:47:55.876+0000] {subprocess.py:97} INFO - Command exited with return code 255
[2025-08-11T19:47:55.881+0000] {taskinstance.py:441} INFO - ::group::Post task execution logs
[2025-08-11T19:47:55.894+0000] {taskinstance.py:2905} ERROR - Task failed with exception
Traceback (most recent call last):
  File "/home/airflow/.local/lib/python3.12/site-packages/airflow/models/taskinstance.py", line 465, in _execute_task
    result = _execute_callable(context=context, **execute_callable_kwargs)
             ^^^^^^^^^^^^^^^^^^^^^^^^^^^^^^^^^^^^^^^^^^^^^^^^^^^^^^^^^^^^^
  File "/home/airflow/.local/lib/python3.12/site-packages/airflow/models/taskinstance.py", line 432, in _execute_callable
    return execute_callable(context=context, **execute_callable_kwargs)
           ^^^^^^^^^^^^^^^^^^^^^^^^^^^^^^^^^^^^^^^^^^^^^^^^^^^^^^^^^^^^
  File "/home/airflow/.local/lib/python3.12/site-packages/airflow/models/baseoperator.py", line 400, in wrapper
    return func(self, *args, **kwargs)
           ^^^^^^^^^^^^^^^^^^^^^^^^^^^
  File "/home/airflow/.local/lib/python3.12/site-packages/airflow/operators/bash.py", line 243, in execute
    raise AirflowException(
airflow.exceptions.AirflowException: Bash command failed. The command returned a non-zero exit code 255.
[2025-08-11T19:47:55.901+0000] {taskinstance.py:1206} INFO - Marking task as FAILED. dag_id=ml_pipeline_dvc, task_id=preprocess_dvc, run_id=manual__2025-08-11T19:42:33.813103+00:00, execution_date=20250811T194233, start_date=20250811T194750, end_date=20250811T194755
[2025-08-11T19:47:55.919+0000] {standard_task_runner.py:110} ERROR - Failed to execute job 63 for task preprocess_dvc (Bash command failed. The command returned a non-zero exit code 255.; 3622)
[2025-08-11T19:47:55.968+0000] {local_task_job_runner.py:240} INFO - Task exited with return code 1
[2025-08-11T19:47:55.997+0000] {taskinstance.py:3498} INFO - 0 downstream tasks scheduled from follow-on schedule check
[2025-08-11T19:47:56.001+0000] {local_task_job_runner.py:222} INFO - ::endgroup::
