[2025-08-05T19:43:20.832+0000] {local_task_job_runner.py:120} INFO - ::group::Pre task execution logs
[2025-08-05T19:43:21.075+0000] {taskinstance.py:2076} INFO - Dependencies all met for dep_context=non-requeueable deps ti=<TaskInstance: ml_pipeline_dvc.train_dvc manual__2025-08-05T19:32:51.876609+00:00 [queued]>
[2025-08-05T19:43:21.137+0000] {taskinstance.py:2076} INFO - Dependencies all met for dep_context=requeueable deps ti=<TaskInstance: ml_pipeline_dvc.train_dvc manual__2025-08-05T19:32:51.876609+00:00 [queued]>
[2025-08-05T19:43:21.140+0000] {taskinstance.py:2306} INFO - Starting attempt 2 of 2
[2025-08-05T19:43:21.256+0000] {taskinstance.py:2330} INFO - Executing <Task(BashOperator): train_dvc> on 2025-08-05 19:32:51.876609+00:00
[2025-08-05T19:43:21.284+0000] {warnings.py:110} WARNING - /home/***/.local/lib/python3.12/site-packages/***/task/task_runner/standard_task_runner.py:61: DeprecationWarning: This process (pid=1738) is multi-threaded, use of fork() may lead to deadlocks in the child.
  pid = os.fork()

[2025-08-05T19:43:21.296+0000] {standard_task_runner.py:63} INFO - Started process 1746 to run task
[2025-08-05T19:43:21.296+0000] {standard_task_runner.py:90} INFO - Running: ['***', 'tasks', 'run', 'ml_pipeline_dvc', 'train_dvc', 'manual__2025-08-05T19:32:51.876609+00:00', '--job-id', '29', '--raw', '--subdir', 'DAGS_FOLDER/ml_pipeline_dag_2.py', '--cfg-path', '/tmp/tmp1i7s_wnh']
[2025-08-05T19:43:21.304+0000] {standard_task_runner.py:91} INFO - Job 29: Subtask train_dvc
[2025-08-05T19:43:21.617+0000] {task_command.py:426} INFO - Running <TaskInstance: ml_pipeline_dvc.train_dvc manual__2025-08-05T19:32:51.876609+00:00 [running]> on host cb274dbeb17b
[2025-08-05T19:43:22.173+0000] {taskinstance.py:2648} INFO - Exporting env vars: AIRFLOW_CTX_DAG_OWNER='yas' AIRFLOW_CTX_DAG_ID='ml_pipeline_dvc' AIRFLOW_CTX_TASK_ID='train_dvc' AIRFLOW_CTX_EXECUTION_DATE='2025-08-05T19:32:51.876609+00:00' AIRFLOW_CTX_TRY_NUMBER='2' AIRFLOW_CTX_DAG_RUN_ID='manual__2025-08-05T19:32:51.876609+00:00'
[2025-08-05T19:43:22.179+0000] {taskinstance.py:430} INFO - ::endgroup::
[2025-08-05T19:43:22.284+0000] {subprocess.py:63} INFO - Tmp dir root location: /tmp
[2025-08-05T19:43:22.292+0000] {subprocess.py:75} INFO - Running command: ['/usr/bin/bash', '-c', 'cd /opt/***/ml_pipeline && dvc repro train']
[2025-08-05T19:43:22.360+0000] {subprocess.py:86} INFO - Output:
[2025-08-05T19:43:34.953+0000] {subprocess.py:93} INFO - ERROR: failed to reproduce 'preprocess': '/opt/***/ml_pipeline/artifacts/preprocess' is busy, it is being blocked by:
[2025-08-05T19:43:34.961+0000] {subprocess.py:93} INFO -   (PID 1709): /home/***/.local/bin/dvc repro train
[2025-08-05T19:43:34.964+0000] {subprocess.py:93} INFO - 
[2025-08-05T19:43:34.966+0000] {subprocess.py:93} INFO - If there are no processes with such PIDs, you can manually remove '/opt/***/ml_pipeline/.dvc/tmp/rwlock' and try again.
[2025-08-05T19:43:36.113+0000] {subprocess.py:97} INFO - Command exited with return code 255
[2025-08-05T19:43:36.146+0000] {taskinstance.py:441} INFO - ::group::Post task execution logs
[2025-08-05T19:43:36.307+0000] {taskinstance.py:2905} ERROR - Task failed with exception
Traceback (most recent call last):
  File "/home/airflow/.local/lib/python3.12/site-packages/airflow/models/taskinstance.py", line 465, in _execute_task
    result = _execute_callable(context=context, **execute_callable_kwargs)
             ^^^^^^^^^^^^^^^^^^^^^^^^^^^^^^^^^^^^^^^^^^^^^^^^^^^^^^^^^^^^^
  File "/home/airflow/.local/lib/python3.12/site-packages/airflow/models/taskinstance.py", line 432, in _execute_callable
    return execute_callable(context=context, **execute_callable_kwargs)
           ^^^^^^^^^^^^^^^^^^^^^^^^^^^^^^^^^^^^^^^^^^^^^^^^^^^^^^^^^^^^
  File "/home/airflow/.local/lib/python3.12/site-packages/airflow/models/baseoperator.py", line 400, in wrapper
    return func(self, *args, **kwargs)
           ^^^^^^^^^^^^^^^^^^^^^^^^^^^
  File "/home/airflow/.local/lib/python3.12/site-packages/airflow/operators/bash.py", line 243, in execute
    raise AirflowException(
airflow.exceptions.AirflowException: Bash command failed. The command returned a non-zero exit code 255.
[2025-08-05T19:43:36.329+0000] {taskinstance.py:1206} INFO - Marking task as FAILED. dag_id=ml_pipeline_dvc, task_id=train_dvc, run_id=manual__2025-08-05T19:32:51.876609+00:00, execution_date=20250805T193251, start_date=20250805T194321, end_date=20250805T194336
[2025-08-05T19:43:36.375+0000] {standard_task_runner.py:110} ERROR - Failed to execute job 29 for task train_dvc (Bash command failed. The command returned a non-zero exit code 255.; 1746)
[2025-08-05T19:43:36.407+0000] {local_task_job_runner.py:240} INFO - Task exited with return code 1
[2025-08-05T19:43:36.461+0000] {taskinstance.py:3498} INFO - 0 downstream tasks scheduled from follow-on schedule check
[2025-08-05T19:43:36.465+0000] {local_task_job_runner.py:222} INFO - ::endgroup::
