[2025-08-11T02:46:05.288+0000] {local_task_job_runner.py:120} INFO - ::group::Pre task execution logs
[2025-08-11T02:46:05.356+0000] {taskinstance.py:2076} INFO - Dependencies all met for dep_context=non-requeueable deps ti=<TaskInstance: etl.etl_task manual__2025-08-11T02:45:59.839887+00:00 [queued]>
[2025-08-11T02:46:05.370+0000] {taskinstance.py:2076} INFO - Dependencies all met for dep_context=requeueable deps ti=<TaskInstance: etl.etl_task manual__2025-08-11T02:45:59.839887+00:00 [queued]>
[2025-08-11T02:46:05.371+0000] {taskinstance.py:2306} INFO - Starting attempt 1 of 1
[2025-08-11T02:46:05.395+0000] {taskinstance.py:2330} INFO - Executing <Task(PythonOperator): etl_task> on 2025-08-11 02:45:59.839887+00:00
[2025-08-11T02:46:05.407+0000] {warnings.py:110} WARNING - /home/***/.local/lib/python3.12/site-packages/***/task/task_runner/standard_task_runner.py:61: DeprecationWarning: This process (pid=371) is multi-threaded, use of fork() may lead to deadlocks in the child.
  pid = os.fork()

[2025-08-11T02:46:05.410+0000] {standard_task_runner.py:63} INFO - Started process 373 to run task
[2025-08-11T02:46:05.410+0000] {standard_task_runner.py:90} INFO - Running: ['***', 'tasks', 'run', 'etl', 'etl_task', 'manual__2025-08-11T02:45:59.839887+00:00', '--job-id', '26', '--raw', '--subdir', 'DAGS_FOLDER/etl_pipeline.py', '--cfg-path', '/tmp/tmp7pvktu0h']
[2025-08-11T02:46:05.415+0000] {standard_task_runner.py:91} INFO - Job 26: Subtask etl_task
[2025-08-11T02:46:05.504+0000] {task_command.py:426} INFO - Running <TaskInstance: etl.etl_task manual__2025-08-11T02:45:59.839887+00:00 [running]> on host 4ada121dfef0
[2025-08-11T02:46:05.656+0000] {taskinstance.py:2648} INFO - Exporting env vars: AIRFLOW_CTX_DAG_OWNER='***' AIRFLOW_CTX_DAG_ID='etl' AIRFLOW_CTX_TASK_ID='etl_task' AIRFLOW_CTX_EXECUTION_DATE='2025-08-11T02:45:59.839887+00:00' AIRFLOW_CTX_TRY_NUMBER='1' AIRFLOW_CTX_DAG_RUN_ID='manual__2025-08-11T02:45:59.839887+00:00'
[2025-08-11T02:46:05.657+0000] {taskinstance.py:430} INFO - ::endgroup::
[2025-08-11T02:46:05.787+0000] {log.py:232} WARNING - {"asctime": "2025-08-11 02:46:05,720", "levelname": "INFO", "name": "model_training", "trace_id": null, "span_id": null, "message": "Simulated data generated."}
[2025-08-11T02:46:05.720+0000] {etl_task.py:106} INFO - Simulated data generated.
[2025-08-11T02:46:05.843+0000] {taskinstance.py:441} INFO - ::group::Post task execution logs
[2025-08-11T02:46:05.844+0000] {taskinstance.py:2905} ERROR - Task failed with exception
Traceback (most recent call last):
  File "/home/airflow/.local/lib/python3.12/site-packages/airflow/models/taskinstance.py", line 465, in _execute_task
    result = _execute_callable(context=context, **execute_callable_kwargs)
             ^^^^^^^^^^^^^^^^^^^^^^^^^^^^^^^^^^^^^^^^^^^^^^^^^^^^^^^^^^^^^
  File "/home/airflow/.local/lib/python3.12/site-packages/airflow/models/taskinstance.py", line 432, in _execute_callable
    return execute_callable(context=context, **execute_callable_kwargs)
           ^^^^^^^^^^^^^^^^^^^^^^^^^^^^^^^^^^^^^^^^^^^^^^^^^^^^^^^^^^^^
  File "/home/airflow/.local/lib/python3.12/site-packages/airflow/models/baseoperator.py", line 400, in wrapper
    return func(self, *args, **kwargs)
           ^^^^^^^^^^^^^^^^^^^^^^^^^^^
  File "/home/airflow/.local/lib/python3.12/site-packages/airflow/operators/python.py", line 235, in execute
    return_value = self.execute_callable()
                   ^^^^^^^^^^^^^^^^^^^^^^^
  File "/home/airflow/.local/lib/python3.12/site-packages/airflow/operators/python.py", line 252, in execute_callable
    return self.python_callable(*self.op_args, **self.op_kwargs)
           ^^^^^^^^^^^^^^^^^^^^^^^^^^^^^^^^^^^^^^^^^^^^^^^^^^^^^
  File "/opt/airflow/ml_pipeline/preprocessing/etl_task.py", line 107, in main
    raw_data_path, meta_path = save_data_with_version(data, version)
                               ^^^^^^^^^^^^^^^^^^^^^^^^^^^^^^^^^^^^^
  File "/opt/airflow/ml_pipeline/preprocessing/etl_task.py", line 98, in save_data_with_version
    meta_path = save_matadata_to_minio(metadata, version_tag)
                ^^^^^^^^^^^^^^^^^^^^^^^^^^^^^^^^^^^^^^^^^^^^^
  File "/opt/airflow/ml_pipeline/preprocessing/etl_task.py", line 37, in save_matadata_to_minio
    json.dump(meta, buffer)
  File "/usr/local/lib/python3.12/json/__init__.py", line 180, in dump
    fp.write(chunk)
TypeError: a bytes-like object is required, not 'str'
[2025-08-11T02:46:05.864+0000] {taskinstance.py:1206} INFO - Marking task as FAILED. dag_id=etl, task_id=etl_task, run_id=manual__2025-08-11T02:45:59.839887+00:00, execution_date=20250811T024559, start_date=20250811T024605, end_date=20250811T024605
[2025-08-11T02:46:05.885+0000] {standard_task_runner.py:110} ERROR - Failed to execute job 26 for task etl_task (a bytes-like object is required, not 'str'; 373)
[2025-08-11T02:46:05.921+0000] {local_task_job_runner.py:240} INFO - Task exited with return code 1
[2025-08-11T02:46:05.942+0000] {taskinstance.py:3498} INFO - 0 downstream tasks scheduled from follow-on schedule check
[2025-08-11T02:46:05.944+0000] {local_task_job_runner.py:222} INFO - ::endgroup::
